2017-12-29 11:10:27,970 - LogUtils.py[line:112] - INFO: ................99999999999999wqeqweqweqwe999
2017-12-29 11:41:34,776 - LogUtils.py[line:112] - INFO:  [x] Received "INSERT INTO fs_call_replay(who, text, record_fpath,  call_id,resp_param)VALUES ('45', '454', '454', '454', '4545')"


2017-12-29 11:42:05,999 - LogUtils.py[line:112] - INFO:  [x] Received "INSERT INTO fs_call_replay(who, text, record_fpath,  call_id,resp_param)VALUES ('45', '454', '454', '454', '4545')"


2017-12-29 11:42:23,053 - LogUtils.py[line:112] - INFO:  [x] Received "INSERT INTO fs_call_replay(who, text, record_fpath,  call_id,resp_param)VALUES ('45', '454', '454', '454', '4545')"


2017-12-29 11:42:40,399 - LogUtils.py[line:112] - INFO:  [x] Received "INSERT INTO fs_call_replay(who, text, record_fpath,  call_id,resp_param)VALUES ('45', '454', '454', '454', '4545')"


2017-12-29 11:42:57,730 - LogUtils.py[line:112] - INFO:  [x] Received "INSERT INTO fs_call_replay(who, text, record_fpath,  call_id,resp_param)VALUES ('45', '454', '454', '454', '4545')"


2017-12-29 11:43:25,055 - LogUtils.py[line:112] - INFO:  [x] Received "INSERT INTO fs_call_replay(who, text, record_fpath,  call_id,resp_param)VALUES ('45', '454', '454', '454', '4545')"


2017-12-29 11:43:25,057 - LogUtils.py[line:112] - INFO:  [x] Received "INSERT INTO fs_call_replay(who, text, record_fpath,  call_id,resp_param)VALUES ('45', '454', '454', '454', '4545')"


2017-12-29 11:43:25,058 - LogUtils.py[line:112] - INFO:  [x] Received "INSERT INTO fs_call_replay(who, text, record_fpath,  call_id,resp_param)VALUES ('45', '454', '454', '454', '4545')"


2017-12-29 11:43:25,058 - LogUtils.py[line:112] - INFO:  [x] Received "INSERT INTO fs_call_replay(who, text, record_fpath,  call_id,resp_param)VALUES ('45', '454', '454', '454', '4545')"


2017-12-29 11:43:25,058 - LogUtils.py[line:112] - INFO:  [x] Received "INSERT INTO fs_call_replay(who, text, record_fpath,  call_id,resp_param)VALUES ('45', '454', '454', '454', '4545')"


2017-12-29 11:43:25,059 - LogUtils.py[line:112] - INFO:  [x] Received "INSERT INTO fs_call_replay(who, text, record_fpath,  call_id,resp_param)VALUES ('45', '454', '454', '454', '4545')"


2017-12-29 11:43:25,059 - LogUtils.py[line:112] - INFO:  [x] Received "INSERT INTO fs_call_replay(who, text, record_fpath,  call_id,resp_param)VALUES ('45', '454', '454', '454', '4545')"


2017-12-29 11:43:25,059 - LogUtils.py[line:112] - INFO:  [x] Received "INSERT INTO fs_call_replay(who, text, record_fpath,  call_id,resp_param)VALUES ('45', '454', '454', '454', '4545')"


2017-12-29 11:43:25,059 - LogUtils.py[line:112] - INFO:  [x] Received "INSERT INTO fs_call_replay(who, text, record_fpath,  call_id,resp_param)VALUES ('45', '454', '454', '454', '4545')"


2017-12-29 11:43:25,060 - LogUtils.py[line:112] - INFO:  [x] Received "INSERT INTO fs_call_replay(who, text, record_fpath,  call_id,resp_param)VALUES ('45', '454', '454', '454', '4545')"


2017-12-29 11:43:25,060 - LogUtils.py[line:112] - INFO:  [x] Received "INSERT INTO fs_call_replay(who, text, record_fpath,  call_id,resp_param)VALUES ('45', '454', '454', '454', '4545')"


2017-12-29 11:43:25,060 - LogUtils.py[line:112] - INFO:  [x] Received "INSERT INTO fs_call_replay(who, text, record_fpath,  call_id,resp_param)VALUES ('45', '454', '454', '454', '4545')"


2017-12-29 11:43:45,198 - LogUtils.py[line:112] - INFO: postgresql connect host .....   118.190.166.165
2017-12-29 11:44:07,773 - LogUtils.py[line:112] - INFO: postgresql connect host .....   118.190.166.165
2017-12-29 11:44:46,619 - LogUtils.py[line:112] - INFO: postgresql connect host .....   118.190.166.165
2017-12-29 11:45:05,290 - LogUtils.py[line:112] - INFO: postgresql connect host .....   118.190.166.165
2017-12-29 11:46:17,834 - LogUtils.py[line:112] - INFO: postgresql connect host .....   118.190.166.165
2017-12-29 11:46:18,178 - LogUtils.py[line:112] - INFO: postgresql connect.....closed!!!
2017-12-29 11:46:47,331 - LogUtils.py[line:112] - INFO: postgresql connect host .....   118.190.166.165
2017-12-29 11:46:47,588 - LogUtils.py[line:112] - INFO: postgresql connect.....closed!!!
2017-12-29 11:47:24,977 - LogUtils.py[line:112] - INFO: postgresql connect host .....   118.190.166.165
2017-12-29 11:47:25,251 - LogUtils.py[line:112] - INFO: postgresql connect.....closed!!!
2017-12-29 11:47:48,084 - LogUtils.py[line:112] - INFO: postgresql connect host .....   118.190.166.165
2017-12-29 11:47:48,416 - LogUtils.py[line:112] - INFO: postgresql connect.....closed!!!
2017-12-29 11:48:34,049 - LogUtils.py[line:112] - INFO: postgresql connect host .....   118.190.166.165
2017-12-29 11:48:34,299 - LogUtils.py[line:112] - INFO: postgresql connect.....closed!!!
2017-12-29 11:48:43,318 - LogUtils.py[line:112] - INFO: postgresql connect host .....   118.190.166.165
2017-12-29 11:48:43,559 - LogUtils.py[line:112] - INFO: postgresql connect.....closed!!!
2017-12-29 11:51:28,402 - LogUtils.py[line:112] - INFO: postgresql connect host .....   118.190.166.165
2017-12-29 11:51:28,917 - LogUtils.py[line:112] - INFO: postgresql connect.....closed!!!
2017-12-29 11:51:29,149 - LogUtils.py[line:112] - INFO: Flow return ----------{u'successful': False, u'message': u'\u6ca1\u6709\u63d0\u4f9buser_id'}
2017-12-29 11:52:49,140 - LogUtils.py[line:112] - INFO: postgresql connect host .....   118.190.166.165
2017-12-29 11:52:49,404 - LogUtils.py[line:112] - INFO: postgresql connect.....closed!!!
2017-12-29 11:52:49,433 - LogUtils.py[line:112] - INFO: Flow return ----------{u'successful': True, u'message': u'ok', u'data': []}
2017-12-29 11:53:16,295 - LogUtils.py[line:112] - INFO: postgresql connect host .....   118.190.166.165
2017-12-29 11:53:17,054 - LogUtils.py[line:112] - INFO: postgresql connect.....closed!!!
2017-12-29 11:53:17,095 - LogUtils.py[line:112] - INFO: Flow return ----------{u'successful': True, u'message': u'ok', u'data': []}
2017-12-29 11:54:01,667 - LogUtils.py[line:112] - INFO: postgresql connect host .....   118.190.166.165
2017-12-29 11:54:01,929 - LogUtils.py[line:112] - INFO: postgresql connect.....closed!!!
2017-12-29 11:54:01,969 - LogUtils.py[line:112] - INFO: Flow return ----------{u'successful': True, u'message': u'ok', u'data': [{u'key_word': u'\u533b\u7597', u'similarity': 0.6340351531652823, u'sentence': u'\u9644\u8fd1\u6709\u533b\u9662\u5417', u'word': u'\u533b\u9662', u'label': u'\u5173\u6ce8\u533b\u7597'}, {u'key_word': u'\u5b66\u6821', u'similarity': 1.0, u'sentence': u'\u9644\u8fd1\u6709\u5b66\u6821\u5417', u'word': u'\u5b66\u6821', u'label': u'\u5173\u6ce8\u6559\u80b2'}]}
2017-12-29 11:56:10,372 - LogUtils.py[line:112] - INFO: postgresql connect host .....   118.190.166.165
2017-12-29 11:56:10,610 - LogUtils.py[line:112] - INFO: postgresql connect.....closed!!!
2017-12-29 13:03:22,725 - LogUtils.py[line:112] - INFO: postgresql connect host .....   118.190.166.165
2017-12-29 13:03:23,050 - LogUtils.py[line:112] - INFO: postgresql connect.....closed!!!
2017-12-29 14:24:06,276 - LogUtils.py[line:112] - INFO: postgresql connect host .....   118.190.166.165
2017-12-29 14:24:06,619 - LogUtils.py[line:112] - INFO: postgresql connect.....closed!!!
2017-12-29 14:24:06,620 - LogUtils.py[line:112] - INFO: postgresql connect host .....   118.190.166.165
2017-12-29 14:24:06,672 - LogUtils.py[line:120] - ERROR: runsql exception error insert or update on table "fs_customer_label" violates foreign key constraint "fs_customer_label_user_id_c890eae4_fk_fs_user_id"
DETAIL:  Key (user_id)=(55655656) is not present in table "fs_user".
 
2017-12-29 14:25:13,087 - LogUtils.py[line:112] - INFO: postgresql connect host .....   118.190.166.165
2017-12-29 14:25:13,370 - LogUtils.py[line:112] - INFO: postgresql connect.....closed!!!
2017-12-29 14:25:13,371 - LogUtils.py[line:112] - INFO: postgresql connect host .....   118.190.166.165
2017-12-29 14:25:13,429 - LogUtils.py[line:112] - INFO: postgresql connect.....closed!!!
2017-12-29 14:26:36,697 - LogUtils.py[line:112] - INFO: postgresql connect host .....   118.190.166.165
2017-12-29 14:26:37,006 - LogUtils.py[line:112] - INFO: postgresql connect.....closed!!!
2017-12-29 14:26:37,007 - LogUtils.py[line:112] - INFO: postgresql connect host .....   118.190.166.165
2017-12-29 14:26:37,041 - LogUtils.py[line:120] - ERROR: runsql exception error duplicate key value violates unique constraint "fs_customer_label_user_id_number_label_b61f2da0_uniq"
DETAIL:  Key (user_id, number, label)=(1, 15900282168, ceshi_label) already exists.
 
2017-12-29 14:26:58,245 - LogUtils.py[line:112] - INFO: postgresql connect host .....   118.190.166.165
2017-12-29 14:26:58,529 - LogUtils.py[line:112] - INFO: postgresql connect.....closed!!!
2017-12-29 14:26:58,529 - LogUtils.py[line:112] - INFO: postgresql connect host .....   118.190.166.165
2017-12-29 14:26:58,595 - LogUtils.py[line:112] - INFO: postgresql connect.....closed!!!
2017-12-29 14:27:37,467 - LogUtils.py[line:112] - INFO: postgresql connect host .....   118.190.166.165
2017-12-29 14:27:37,769 - LogUtils.py[line:112] - INFO: postgresql connect.....closed!!!
2017-12-29 14:27:37,769 - LogUtils.py[line:112] - INFO: postgresql connect host .....   118.190.166.165
2017-12-29 14:27:37,814 - LogUtils.py[line:120] - ERROR: runsql exception error duplicate key value violates unique constraint "fs_customer_label_user_id_number_label_b61f2da0_uniq"
DETAIL:  Key (user_id, number, label)=(1, 15900282168, 666) already exists.
 
2017-12-29 14:30:54,217 - LogUtils.py[line:112] - INFO: postgresql connect host .....   118.190.166.165
2017-12-29 14:30:54,520 - LogUtils.py[line:112] - INFO: postgresql connect.....closed!!!
2017-12-29 14:30:54,520 - LogUtils.py[line:112] - INFO: postgresql connect host .....   118.190.166.165
2017-12-29 14:30:54,571 - LogUtils.py[line:112] - INFO: postgresql connect.....closed!!!
2017-12-29 14:30:59,829 - LogUtils.py[line:112] - INFO: postgresql connect host .....   118.190.166.165
2017-12-29 14:31:00,080 - LogUtils.py[line:112] - INFO: postgresql connect.....closed!!!
2017-12-29 14:31:00,081 - LogUtils.py[line:112] - INFO: postgresql connect host .....   118.190.166.165
2017-12-29 14:31:00,113 - LogUtils.py[line:120] - ERROR: runsql exception error duplicate key value violates unique constraint "fs_customer_label_user_id_number_label_b61f2da0_uniq"
DETAIL:  Key (user_id, number, label)=(1, 15900282168, 111) already exists.
 
2017-12-29 14:36:22,025 - LogUtils.py[line:112] - INFO: postgresql connect host .....   118.190.166.165
2017-12-29 14:36:22,309 - LogUtils.py[line:112] - INFO: postgresql connect.....closed!!!
2017-12-29 14:36:22,309 - LogUtils.py[line:112] - INFO: postgresql connect host .....   118.190.166.165
2017-12-29 14:36:22,343 - LogUtils.py[line:120] - ERROR: runsql exception error duplicate key value violates unique constraint "fs_customer_label_user_id_number_label_b61f2da0_uniq"
DETAIL:  Key (user_id, number, label)=(1, 15900282168, 111) already exists.
 
2017-12-29 14:36:27,585 - LogUtils.py[line:112] - INFO: postgresql connect host .....   118.190.166.165
2017-12-29 14:36:27,892 - LogUtils.py[line:112] - INFO: postgresql connect.....closed!!!
2017-12-29 14:36:27,893 - LogUtils.py[line:112] - INFO: postgresql connect host .....   118.190.166.165
2017-12-29 14:36:27,968 - LogUtils.py[line:112] - INFO: postgresql connect.....closed!!!
2017-12-29 14:39:01,755 - LogUtils.py[line:112] - INFO: postgresql connect host .....   118.190.166.165
2017-12-29 14:39:02,057 - LogUtils.py[line:112] - INFO: postgresql connect.....closed!!!
2017-12-29 14:39:02,058 - LogUtils.py[line:112] - INFO: postgresql connect host .....   118.190.166.165
2017-12-29 14:39:02,105 - LogUtils.py[line:112] - INFO: postgresql connect.....closed!!!
2017-12-29 14:39:02,105 - LogUtils.py[line:120] - ERROR: runsql exception error cursor already closed 
2017-12-29 14:39:11,355 - LogUtils.py[line:112] - INFO: postgresql connect host .....   118.190.166.165
2017-12-29 14:39:11,620 - LogUtils.py[line:112] - INFO: postgresql connect.....closed!!!
2017-12-29 14:39:11,621 - LogUtils.py[line:112] - INFO: postgresql connect host .....   118.190.166.165
2017-12-29 14:39:11,655 - LogUtils.py[line:120] - ERROR: runsql exception error duplicate key value violates unique constraint "fs_customer_label_user_id_number_label_b61f2da0_uniq"
DETAIL:  Key (user_id, number, label)=(1, 15900282168, qwqw) already exists.
 
2017-12-29 14:44:02,291 - LogUtils.py[line:112] - INFO: postgresql connect host .....   118.190.166.165
2017-12-29 14:44:02,618 - LogUtils.py[line:112] - INFO: postgresql connect.....closed!!!
2017-12-29 14:44:02,619 - LogUtils.py[line:112] - INFO: postgresql connect host .....   118.190.166.165
2017-12-29 14:44:02,655 - LogUtils.py[line:120] - ERROR: runsql exception error int() argument must be a string or a number, not 'tuple' 
2017-12-29 14:45:04,500 - LogUtils.py[line:112] - INFO: postgresql connect host .....   118.190.166.165
2017-12-29 14:45:04,744 - LogUtils.py[line:112] - INFO: postgresql connect.....closed!!!
2017-12-29 14:45:04,745 - LogUtils.py[line:112] - INFO: postgresql connect host .....   118.190.166.165
2017-12-29 14:45:04,791 - LogUtils.py[line:112] - INFO: postgresql connect.....closed!!!
2017-12-29 14:45:04,792 - LogUtils.py[line:120] - ERROR: runsql exception error cursor already closed 
2017-12-29 14:45:27,626 - LogUtils.py[line:112] - INFO: postgresql connect host .....   118.190.166.165
2017-12-29 14:45:27,901 - LogUtils.py[line:112] - INFO: postgresql connect.....closed!!!
2017-12-29 14:45:27,901 - LogUtils.py[line:112] - INFO: postgresql connect host .....   118.190.166.165
2017-12-29 14:45:27,933 - LogUtils.py[line:120] - ERROR: runsql exception error duplicate key value violates unique constraint "fs_customer_label_user_id_number_label_b61f2da0_uniq"
DETAIL:  Key (user_id, number, label)=(1, 15900282168, 12121) already exists.
 
2017-12-29 14:45:33,099 - LogUtils.py[line:112] - INFO: postgresql connect host .....   118.190.166.165
2017-12-29 14:45:33,357 - LogUtils.py[line:112] - INFO: postgresql connect.....closed!!!
2017-12-29 14:45:33,357 - LogUtils.py[line:112] - INFO: postgresql connect host .....   118.190.166.165
2017-12-29 14:45:33,417 - LogUtils.py[line:112] - INFO: postgresql connect.....closed!!!
2017-12-29 14:45:33,417 - LogUtils.py[line:120] - ERROR: runsql exception error cursor already closed 
2017-12-29 14:45:51,671 - LogUtils.py[line:112] - INFO: postgresql connect host .....   118.190.166.165
2017-12-29 14:45:51,929 - LogUtils.py[line:112] - INFO: postgresql connect.....closed!!!
2017-12-29 14:45:51,929 - LogUtils.py[line:112] - INFO: postgresql connect host .....   118.190.166.165
2017-12-29 14:45:51,976 - LogUtils.py[line:112] - INFO: postgresql connect.....closed!!!
2017-12-29 14:45:51,977 - LogUtils.py[line:120] - ERROR: runsql exception error cursor already closed 
2017-12-29 14:47:19,693 - LogUtils.py[line:112] - INFO: postgresql connect host .....   118.190.166.165
2017-12-29 14:47:20,005 - LogUtils.py[line:112] - INFO: postgresql connect.....closed!!!
2017-12-29 14:47:20,005 - LogUtils.py[line:112] - INFO: postgresql connect host .....   118.190.166.165
2017-12-29 14:47:20,073 - LogUtils.py[line:112] - INFO: postgresql connect.....closed!!!
2017-12-29 14:47:20,073 - LogUtils.py[line:120] - ERROR: runsql exception error cursor already closed 
2017-12-29 14:47:50,509 - LogUtils.py[line:112] - INFO: postgresql connect host .....   118.190.166.165
2017-12-29 14:47:50,801 - LogUtils.py[line:112] - INFO: postgresql connect.....closed!!!
2017-12-29 14:47:50,802 - LogUtils.py[line:112] - INFO: postgresql connect host .....   118.190.166.165
2017-12-29 14:47:50,833 - LogUtils.py[line:120] - ERROR: runsql exception error 'NoneType' object has no attribute '__getitem__' 
2017-12-29 14:48:44,643 - LogUtils.py[line:112] - INFO: postgresql connect host .....   118.190.166.165
2017-12-29 14:48:44,965 - LogUtils.py[line:112] - INFO: postgresql connect.....closed!!!
2017-12-29 14:48:46,933 - LogUtils.py[line:112] - INFO: postgresql connect host .....   118.190.166.165
2017-12-29 14:48:58,913 - LogUtils.py[line:120] - ERROR: runsql exception error 'NoneType' object has no attribute '__getitem__' 
2017-12-29 14:49:32,211 - LogUtils.py[line:112] - INFO: postgresql connect host .....   118.190.166.165
2017-12-29 14:49:32,456 - LogUtils.py[line:112] - INFO: postgresql connect.....closed!!!
2017-12-29 14:49:33,380 - LogUtils.py[line:112] - INFO: postgresql connect host .....   118.190.166.165
2017-12-29 14:49:40,505 - LogUtils.py[line:112] - INFO: postgresql connect.....closed!!!
2017-12-29 14:50:09,221 - LogUtils.py[line:112] - INFO: postgresql connect host .....   118.190.166.165
2017-12-29 14:50:09,485 - LogUtils.py[line:112] - INFO: postgresql connect.....closed!!!
2017-12-29 14:50:09,486 - LogUtils.py[line:112] - INFO: postgresql connect host .....   118.190.166.165
2017-12-29 14:50:09,518 - LogUtils.py[line:120] - ERROR: runsql exception error duplicate key value violates unique constraint "fs_customer_label_user_id_number_label_b61f2da0_uniq"
DETAIL:  Key (user_id, number, label)=(1, 15900282168, 111) already exists.
 
2017-12-29 14:50:19,954 - LogUtils.py[line:112] - INFO: postgresql connect host .....   118.190.166.165
2017-12-29 14:50:20,272 - LogUtils.py[line:112] - INFO: postgresql connect.....closed!!!
2017-12-29 14:50:20,273 - LogUtils.py[line:112] - INFO: postgresql connect host .....   118.190.166.165
2017-12-29 14:50:20,327 - LogUtils.py[line:112] - INFO: postgresql connect.....closed!!!
2017-12-29 14:53:47,026 - LogUtils.py[line:112] - INFO: postgresql connect host .....   118.190.166.165
2017-12-29 14:53:47,325 - LogUtils.py[line:112] - INFO: postgresql connect.....closed!!!
2017-12-29 14:53:47,372 - LogUtils.py[line:112] - INFO: .......httpClient exception error  : 'label'
2017-12-29 14:54:04,397 - LogUtils.py[line:112] - INFO: postgresql connect host .....   118.190.166.165
2017-12-29 14:54:04,658 - LogUtils.py[line:112] - INFO: postgresql connect.....closed!!!
2017-12-29 14:54:54,490 - LogUtils.py[line:112] - INFO: .......httpClient exception error  : 'label'
2017-12-29 14:55:09,710 - LogUtils.py[line:112] - INFO: postgresql connect host .....   118.190.166.165
2017-12-29 14:55:09,995 - LogUtils.py[line:112] - INFO: postgresql connect.....closed!!!
2017-12-29 14:55:12,536 - LogUtils.py[line:112] - INFO: .......httpClient exception error  : 'label'
2017-12-29 14:55:35,393 - LogUtils.py[line:112] - INFO: postgresql connect host .....   118.190.166.165
2017-12-29 14:55:35,650 - LogUtils.py[line:112] - INFO: postgresql connect.....closed!!!
2017-12-29 14:55:35,696 - LogUtils.py[line:112] - INFO: postgresql connect host .....   118.190.166.165
2017-12-29 14:55:35,743 - LogUtils.py[line:112] - INFO: postgresql connect.....closed!!!
2017-12-29 14:55:35,743 - LogUtils.py[line:112] - INFO: postgresql connect host .....   118.190.166.165
2017-12-29 14:55:35,794 - LogUtils.py[line:112] - INFO: postgresql connect.....closed!!!
2017-12-29 15:24:00,141 - LogUtils.py[line:112] - INFO: postgresql connect host .....   118.190.166.165
2017-12-29 15:24:00,412 - LogUtils.py[line:112] - INFO: postgresql connect.....closed!!!
2017-12-29 15:24:13,668 - LogUtils.py[line:112] - INFO: postgresql connect host .....   118.190.166.165
2017-12-29 15:24:19,688 - LogUtils.py[line:112] - INFO: postgresql connect.....closed!!!
2017-12-29 15:24:24,448 - LogUtils.py[line:112] - INFO: postgresql connect host .....   118.190.166.165
2017-12-29 15:24:24,485 - LogUtils.py[line:120] - ERROR: runsql exception error syntax error at or near "'医疗'"
LINE 1: ...吗', '0.634035153165', '2017-12-29 15:24:00', '25' '医疗', '...
                                                              ^
 
2017-12-29 15:24:31,756 - LogUtils.py[line:112] - INFO: postgresql connect host .....   118.190.166.165
2017-12-29 15:24:31,803 - LogUtils.py[line:112] - INFO: postgresql connect.....closed!!!
2017-12-29 15:24:33,033 - LogUtils.py[line:112] - INFO: postgresql connect host .....   118.190.166.165
2017-12-29 15:24:33,069 - LogUtils.py[line:120] - ERROR: runsql exception error syntax error at or near "'学校'"
LINE 1: ...'附近有学校吗', '1.0', '2017-12-29 15:24:00', '26' '学校', '...
                                                              ^
 
2017-12-29 15:25:00,787 - LogUtils.py[line:112] - INFO: postgresql connect host .....   118.190.166.165
2017-12-29 15:25:02,105 - LogUtils.py[line:112] - INFO: postgresql connect.....closed!!!
2017-12-29 15:25:02,153 - LogUtils.py[line:112] - INFO: postgresql connect host .....   118.190.166.165
2017-12-29 15:25:02,187 - LogUtils.py[line:120] - ERROR: runsql exception error duplicate key value violates unique constraint "fs_customer_label_user_id_number_label_b61f2da0_uniq"
DETAIL:  Key (user_id, number, label)=(1, 15900282168, 关注医疗) already exists.
 
2017-12-29 15:25:02,204 - LogUtils.py[line:112] - INFO: postgresql connect host .....   118.190.166.165
2017-12-29 15:25:02,244 - LogUtils.py[line:120] - ERROR: runsql exception error invalid input syntax for integer: "None"
LINE 1: ...医院吗', '0.634035153165', '2017-12-29 15:25:02', 'None', '...
                                                             ^
 
2017-12-29 15:25:02,264 - LogUtils.py[line:112] - INFO: postgresql connect host .....   118.190.166.165
2017-12-29 15:25:02,298 - LogUtils.py[line:120] - ERROR: runsql exception error duplicate key value violates unique constraint "fs_customer_label_user_id_number_label_b61f2da0_uniq"
DETAIL:  Key (user_id, number, label)=(1, 15900282168, 关注教育) already exists.
 
2017-12-29 15:25:02,316 - LogUtils.py[line:112] - INFO: postgresql connect host .....   118.190.166.165
2017-12-29 15:25:02,354 - LogUtils.py[line:120] - ERROR: runsql exception error invalid input syntax for integer: "None"
LINE 1: ...ues ('附近有学校吗', '1.0', '2017-12-29 15:25:02', 'None', '...
                                                              ^
 
2017-12-29 15:25:38,351 - LogUtils.py[line:112] - INFO: postgresql connect host .....   118.190.166.165
2017-12-29 15:25:38,648 - LogUtils.py[line:112] - INFO: postgresql connect.....closed!!!
2017-12-29 15:25:38,690 - LogUtils.py[line:112] - INFO: postgresql connect host .....   118.190.166.165
2017-12-29 15:25:38,724 - LogUtils.py[line:120] - ERROR: runsql exception error duplicate key value violates unique constraint "fs_customer_label_user_id_number_label_b61f2da0_uniq"
DETAIL:  Key (user_id, number, label)=(1, 15900282168, 关注医疗) already exists.
 
2017-12-29 15:25:38,743 - LogUtils.py[line:112] - INFO: postgresql connect host .....   118.190.166.165
2017-12-29 15:25:38,778 - LogUtils.py[line:120] - ERROR: runsql exception error invalid input syntax for integer: ""
LINE 1: ...医院吗', '0.634035153165', '2017-12-29 15:25:38', '', '医疗'...
                                                             ^
 
2017-12-29 15:25:38,795 - LogUtils.py[line:112] - INFO: postgresql connect host .....   118.190.166.165
2017-12-29 15:25:38,829 - LogUtils.py[line:120] - ERROR: runsql exception error duplicate key value violates unique constraint "fs_customer_label_user_id_number_label_b61f2da0_uniq"
DETAIL:  Key (user_id, number, label)=(1, 15900282168, 关注教育) already exists.
 
2017-12-29 15:25:38,846 - LogUtils.py[line:112] - INFO: postgresql connect host .....   118.190.166.165
2017-12-29 15:25:38,881 - LogUtils.py[line:120] - ERROR: runsql exception error invalid input syntax for integer: ""
LINE 1: ...es ('附近有学校吗', '1.0', '2017-12-29 15:25:38', '', '学校'...
                                                             ^
 
2017-12-29 15:27:35,300 - LogUtils.py[line:112] - INFO: postgresql connect host .....   118.190.166.165
2017-12-29 15:27:35,616 - LogUtils.py[line:112] - INFO: postgresql connect.....closed!!!
2017-12-29 15:27:35,657 - LogUtils.py[line:112] - INFO: postgresql connect host .....   118.190.166.165
2017-12-29 15:27:35,697 - LogUtils.py[line:120] - ERROR: runsql exception error duplicate key value violates unique constraint "fs_customer_label_user_id_number_label_b61f2da0_uniq"
DETAIL:  Key (user_id, number, label)=(1, 15900282168, 关注医疗) already exists.
 
2017-12-29 15:27:35,717 - LogUtils.py[line:112] - INFO: postgresql connect host .....   118.190.166.165
2017-12-29 15:27:35,755 - LogUtils.py[line:120] - ERROR: runsql exception error invalid input syntax for integer: "asdasdasdasdasd"
LINE 1: ...疗', '医院', '23e566219595a9cb92bc3e5a175dbd63', 'asdasdasd...
                                                            ^
 
2017-12-29 15:27:35,776 - LogUtils.py[line:112] - INFO: postgresql connect host .....   118.190.166.165
2017-12-29 15:27:35,815 - LogUtils.py[line:120] - ERROR: runsql exception error duplicate key value violates unique constraint "fs_customer_label_user_id_number_label_b61f2da0_uniq"
DETAIL:  Key (user_id, number, label)=(1, 15900282168, 关注教育) already exists.
 
2017-12-29 15:27:35,834 - LogUtils.py[line:112] - INFO: postgresql connect host .....   118.190.166.165
2017-12-29 15:27:35,871 - LogUtils.py[line:120] - ERROR: runsql exception error invalid input syntax for integer: "asdasdasdasdasd"
LINE 1: ...育', '学校', '23e566219595a9cb92bc3e5a175dbd63', 'asdasdasd...
                                                            ^
 
2017-12-29 15:28:08,531 - LogUtils.py[line:112] - INFO: postgresql connect host .....   118.190.166.165
2017-12-29 15:28:08,847 - LogUtils.py[line:112] - INFO: postgresql connect.....closed!!!
2017-12-29 15:28:08,896 - LogUtils.py[line:112] - INFO: postgresql connect host .....   118.190.166.165
2017-12-29 15:28:08,929 - LogUtils.py[line:120] - ERROR: runsql exception error duplicate key value violates unique constraint "fs_customer_label_user_id_number_label_b61f2da0_uniq"
DETAIL:  Key (user_id, number, label)=(1, 15900282168, 关注医疗) already exists.
 
2017-12-29 15:28:08,946 - LogUtils.py[line:112] - INFO: postgresql connect host .....   118.190.166.165
2017-12-29 15:28:08,977 - LogUtils.py[line:120] - ERROR: runsql exception error no results to fetch 
2017-12-29 15:28:08,993 - LogUtils.py[line:112] - INFO: postgresql connect host .....   118.190.166.165
2017-12-29 15:28:09,026 - LogUtils.py[line:120] - ERROR: runsql exception error duplicate key value violates unique constraint "fs_customer_label_user_id_number_label_b61f2da0_uniq"
DETAIL:  Key (user_id, number, label)=(1, 15900282168, 关注教育) already exists.
 
2017-12-29 15:28:09,042 - LogUtils.py[line:112] - INFO: postgresql connect host .....   118.190.166.165
2017-12-29 15:28:09,074 - LogUtils.py[line:120] - ERROR: runsql exception error no results to fetch 
2017-12-29 15:28:32,293 - LogUtils.py[line:112] - INFO: postgresql connect host .....   118.190.166.165
2017-12-29 15:28:32,606 - LogUtils.py[line:112] - INFO: postgresql connect.....closed!!!
2017-12-29 15:28:34,864 - LogUtils.py[line:112] - INFO: postgresql connect host .....   118.190.166.165
2017-12-29 15:28:34,898 - LogUtils.py[line:120] - ERROR: runsql exception error duplicate key value violates unique constraint "fs_customer_label_user_id_number_label_b61f2da0_uniq"
DETAIL:  Key (user_id, number, label)=(1, 15900282168, 关注医疗) already exists.
 
2017-12-29 15:28:35,552 - LogUtils.py[line:112] - INFO: postgresql connect host .....   118.190.166.165
2017-12-29 15:28:35,597 - LogUtils.py[line:120] - ERROR: runsql exception error no results to fetch 
2017-12-29 15:28:35,620 - LogUtils.py[line:112] - INFO: postgresql connect host .....   118.190.166.165
2017-12-29 15:28:35,652 - LogUtils.py[line:120] - ERROR: runsql exception error duplicate key value violates unique constraint "fs_customer_label_user_id_number_label_b61f2da0_uniq"
DETAIL:  Key (user_id, number, label)=(1, 15900282168, 关注教育) already exists.
 
2017-12-29 15:28:36,192 - LogUtils.py[line:112] - INFO: postgresql connect host .....   118.190.166.165
2017-12-29 15:28:36,235 - LogUtils.py[line:120] - ERROR: runsql exception error no results to fetch 
2017-12-29 15:28:55,367 - LogUtils.py[line:112] - INFO: postgresql connect host .....   118.190.166.165
2017-12-29 15:28:55,655 - LogUtils.py[line:112] - INFO: postgresql connect.....closed!!!
2017-12-29 15:29:02,457 - LogUtils.py[line:112] - INFO: postgresql connect host .....   118.190.166.165
2017-12-29 15:29:02,502 - LogUtils.py[line:120] - ERROR: runsql exception error duplicate key value violates unique constraint "fs_customer_label_user_id_number_label_b61f2da0_uniq"
DETAIL:  Key (user_id, number, label)=(1, 15900282168, 关注医疗) already exists.
 
2017-12-29 15:29:06,860 - LogUtils.py[line:112] - INFO: postgresql connect host .....   118.190.166.165
2017-12-29 15:29:06,909 - LogUtils.py[line:112] - INFO: postgresql connect.....closed!!!
2017-12-29 15:29:14,501 - LogUtils.py[line:112] - INFO: postgresql connect host .....   118.190.166.165
2017-12-29 15:29:14,548 - LogUtils.py[line:120] - ERROR: runsql exception error duplicate key value violates unique constraint "fs_customer_label_user_id_number_label_b61f2da0_uniq"
DETAIL:  Key (user_id, number, label)=(1, 15900282168, 关注教育) already exists.
 
2017-12-29 15:29:16,126 - LogUtils.py[line:112] - INFO: postgresql connect host .....   118.190.166.165
2017-12-29 15:29:16,172 - LogUtils.py[line:112] - INFO: postgresql connect.....closed!!!
2017-12-29 15:29:43,466 - LogUtils.py[line:112] - INFO: postgresql connect host .....   118.190.166.165
2017-12-29 15:29:43,775 - LogUtils.py[line:112] - INFO: postgresql connect.....closed!!!
2017-12-29 15:29:43,818 - LogUtils.py[line:112] - INFO: postgresql connect host .....   118.190.166.165
2017-12-29 15:29:43,851 - LogUtils.py[line:120] - ERROR: runsql exception error duplicate key value violates unique constraint "fs_customer_label_user_id_number_label_b61f2da0_uniq"
DETAIL:  Key (user_id, number, label)=(1, 15900282168, 关注医疗) already exists.
 
2017-12-29 15:29:43,868 - LogUtils.py[line:112] - INFO: postgresql connect host .....   118.190.166.165
2017-12-29 15:29:43,936 - LogUtils.py[line:112] - INFO: postgresql connect.....closed!!!
2017-12-29 15:29:43,936 - LogUtils.py[line:112] - INFO: postgresql connect host .....   118.190.166.165
2017-12-29 15:29:43,966 - LogUtils.py[line:120] - ERROR: runsql exception error duplicate key value violates unique constraint "fs_customer_label_user_id_number_label_b61f2da0_uniq"
DETAIL:  Key (user_id, number, label)=(1, 15900282168, 关注教育) already exists.
 
2017-12-29 15:29:43,982 - LogUtils.py[line:112] - INFO: postgresql connect host .....   118.190.166.165
2017-12-29 15:29:44,048 - LogUtils.py[line:112] - INFO: postgresql connect.....closed!!!
2017-12-29 15:34:49,493 - LogUtils.py[line:112] - INFO: postgresql connect host .....   118.190.166.165
2017-12-29 15:34:49,813 - LogUtils.py[line:112] - INFO: postgresql connect.....closed!!!
2017-12-29 15:34:49,855 - LogUtils.py[line:112] - INFO: postgresql connect host .....   118.190.166.165
2017-12-29 15:34:49,904 - LogUtils.py[line:112] - INFO: postgresql connect.....closed!!!
2017-12-29 15:34:49,905 - LogUtils.py[line:112] - INFO: postgresql connect host .....   118.190.166.165
2017-12-29 15:34:49,977 - LogUtils.py[line:112] - INFO: postgresql connect.....closed!!!
2017-12-29 15:34:49,977 - LogUtils.py[line:112] - INFO: postgresql connect host .....   118.190.166.165
2017-12-29 15:34:50,026 - LogUtils.py[line:112] - INFO: postgresql connect.....closed!!!
2017-12-29 15:34:50,027 - LogUtils.py[line:112] - INFO: postgresql connect host .....   118.190.166.165
2017-12-29 15:34:50,099 - LogUtils.py[line:112] - INFO: postgresql connect.....closed!!!
