2018-01-06 13:18:34,532 - LogUtils.py[line:112] - INFO:  [x] Received '{"record_fpath": "/8a9fc0df0e56058d56e8a0323f5ed08f/all_audio/13132229287_full_20180106131834_.wav", "channal_uuid": "9d5fe208-5fb2-44ac-96e8-4c8441384a69", "mark": "update"}'


2018-01-06 13:18:34,532 - LogUtils.py[line:112] - INFO: postgresql connect host .....   118.190.166.165
2018-01-06 13:18:34,827 - LogUtils.py[line:112] - INFO: postgresql connect.....closed!!!
2018-01-06 13:18:34,827 - LogUtils.py[line:112] - INFO: run_update_sql.....update fs_call set full_record_fpath ='/8a9fc0df0e56058d56e8a0323f5ed08f/all_audio/13132229287_full_20180106131834_.wav' where channal_uuid ='9d5fe208-5fb2-44ac-96e8-4c8441384a69'
2018-01-06 13:18:35,750 - LogUtils.py[line:112] - INFO:  [x] Received '{"record_fpath": "/8a9fc0df0e56058d56e8a0323f5ed08f/all_audio/15900282168_full_20180106131835_.wav", "channal_uuid": "4458dc3f-f980-4a85-a771-c3ab67376871", "mark": "update"}'


2018-01-06 13:18:35,751 - LogUtils.py[line:112] - INFO: postgresql connect host .....   118.190.166.165
2018-01-06 13:18:35,794 - LogUtils.py[line:112] - INFO: postgresql connect.....closed!!!
2018-01-06 13:18:35,794 - LogUtils.py[line:112] - INFO: run_update_sql.....update fs_call set full_record_fpath ='/8a9fc0df0e56058d56e8a0323f5ed08f/all_audio/15900282168_full_20180106131835_.wav' where channal_uuid ='4458dc3f-f980-4a85-a771-c3ab67376871'
2018-01-06 13:18:35,857 - LogUtils.py[line:112] - INFO:  [x] Received '{"user_label": "\\u672a\\u77e5", "channal_uuid": "4458dc3f-f980-4a85-a771-c3ab67376871", "mark": "user_label"}'


2018-01-06 13:18:35,858 - LogUtils.py[line:112] - INFO: postgresql connect host .....   118.190.166.165
2018-01-06 13:18:35,923 - LogUtils.py[line:112] - INFO: postgresql connect.....closed!!!
2018-01-06 13:18:35,923 - LogUtils.py[line:112] - INFO:  run_update_sql.........user_label... update fs_call set cust_tag = '未知' where channal_uuid ='4458dc3f-f980-4a85-a771-c3ab67376871' 
2018-01-06 13:18:39,715 - LogUtils.py[line:112] - INFO:  [x] Received '{"jsonStr": "{\\"result\\": \\"\\\\u54ce\\\\u4f60\\\\u597d\\", \\"ret\\": 0}", "text": "\\u54ce\\u4f60\\u597d", "who": "human", "create_at": "2018-01-06 13:18:36", "call_id": "16", "record_fpath": "/8a9fc0df0e56058d56e8a0323f5ed08f/human_audio/15900282168_in_0_20180106131835.wav", "mark": "insert"}'


2018-01-06 13:18:39,715 - LogUtils.py[line:112] - INFO: postgresql connect host .....   118.190.166.165
2018-01-06 13:18:39,760 - LogUtils.py[line:120] - ERROR: runsql exception error insert or update on table "fs_call_replay" violates foreign key constraint "fs_call_replay_call_id_a2c15655_fk_fs_call_id"
DETAIL:  Key (call_id)=(16) is not present in table "fs_call".
 
2018-01-06 13:18:39,760 - LogUtils.py[line:112] - INFO: ******** run_insert_sql..*********...INSERT INTO fs_call_replay(who, text, record_fpath, create_at, call_id,resp_param)VALUES ('human', '哎你好', '/8a9fc0df0e56058d56e8a0323f5ed08f/human_audio/15900282168_in_0_20180106131835.wav', '2018-01-06 13:18:36', '16','{"result": "\u54ce\u4f60\u597d", "ret": 0}') RETURNING id
2018-01-06 13:18:40,782 - LogUtils.py[line:112] - INFO:  [x] Received '{"jsonStr": "vad \\u6ca1\\u6709\\u68c0\\u6d4b\\u5230\\u58f0\\u97f3", "text": "", "who": "human", "create_at": "2018-01-06 13:18:35", "call_id": "19", "record_fpath": "", "mark": "insert"}'


2018-01-06 13:18:40,782 - LogUtils.py[line:112] - INFO: postgresql connect host .....   118.190.166.165
2018-01-06 13:18:40,848 - LogUtils.py[line:120] - ERROR: runsql exception error insert or update on table "fs_call_replay" violates foreign key constraint "fs_call_replay_call_id_a2c15655_fk_fs_call_id"
DETAIL:  Key (call_id)=(19) is not present in table "fs_call".
 
2018-01-06 13:18:40,848 - LogUtils.py[line:112] - INFO: ******** run_insert_sql..*********...INSERT INTO fs_call_replay(who, text, record_fpath, create_at, call_id,resp_param)VALUES ('human', '', '', '2018-01-06 13:18:35', '19','vad 没有检测到声音') RETURNING id
2018-01-06 13:18:41,262 - LogUtils.py[line:112] - INFO:  [x] Received '{"jsonStr": "{\\"info\\": [{\\"is_flow_output\\": true, \\"output\\": \\"\\\\u5582\\\\uff1f\\", \\"node_text\\": \\"\\\\u8bed\\\\u6599\\\\u8282\\\\u70b9\\", \\"flow_id\\": \\"8a9fc0df0e56058d56e8a0323f5ed08f\\", \\"label\\": \\"\\", \\"session_end\\": false, \\"state\\": \\"\\", \\"node_id\\": -11, \\"output_resource\\": \\"t0.wav\\", \\"flow_end\\": false, \\"input\\": \\"\\", \\"similarity\\": 1, \\"flow_title\\": \\"\\\\u91d1\\\\u878d\\\\u884c\\\\u4e1a\\\\uff08\\\\u8d37\\\\u6b3e\\\\uff09\\", \\"output_type\\": \\"path\\", \\"user_label\\": \\"\\\\u672a\\\\u77e5\\", \\"id\\": \\"8a9fc0df0e56058d56e8a0323f5ed08f_-11\\"}], \\"successful\\": true, \\"message\\": \\"ok\\"}", "text": "\\u5582\\uff1f", "who": "bot", "create_at": "2018-01-06 13:18:40", "call_id": "19", "record_fpath": "/8a9fc0df0e56058d56e8a0323f5ed08f/bot_audio/t0.wav", "mark": "insert"}'


2018-01-06 13:18:41,262 - LogUtils.py[line:112] - INFO: postgresql connect host .....   118.190.166.165
2018-01-06 13:18:41,306 - LogUtils.py[line:120] - ERROR: runsql exception error insert or update on table "fs_call_replay" violates foreign key constraint "fs_call_replay_call_id_a2c15655_fk_fs_call_id"
DETAIL:  Key (call_id)=(19) is not present in table "fs_call".
 
2018-01-06 13:18:41,307 - LogUtils.py[line:112] - INFO: ******** run_insert_sql..*********...INSERT INTO fs_call_replay(who, text, record_fpath, create_at, call_id,resp_param)VALUES ('bot', '喂？', '/8a9fc0df0e56058d56e8a0323f5ed08f/bot_audio/t0.wav', '2018-01-06 13:18:40', '19','{"info": [{"is_flow_output": true, "output": "\u5582\uff1f", "node_text": "\u8bed\u6599\u8282\u70b9", "flow_id": "8a9fc0df0e56058d56e8a0323f5ed08f", "label": "", "session_end": false, "state": "", "node_id": -11, "output_resource": "t0.wav", "flow_end": false, "input": "", "similarity": 1, "flow_title": "\u91d1\u878d\u884c\u4e1a\uff08\u8d37\u6b3e\uff09", "output_type": "path", "user_label": "\u672a\u77e5", "id": "8a9fc0df0e56058d56e8a0323f5ed08f_-11"}], "successful": true, "message": "ok"}') RETURNING id
2018-01-06 13:18:43,648 - LogUtils.py[line:112] - INFO:  [x] Received '{"user_label": "\\u5f00\\u573a\\u6302\\u65ad", "channal_uuid": "9d5fe208-5fb2-44ac-96e8-4c8441384a69", "mark": "user_label"}'


2018-01-06 13:18:43,649 - LogUtils.py[line:112] - INFO: postgresql connect host .....   118.190.166.165
2018-01-06 13:18:43,714 - LogUtils.py[line:112] - INFO: postgresql connect.....closed!!!
2018-01-06 13:18:43,714 - LogUtils.py[line:112] - INFO:  run_update_sql.........user_label... update fs_call set cust_tag = '开场挂断' where channal_uuid ='9d5fe208-5fb2-44ac-96e8-4c8441384a69' 
2018-01-06 13:18:46,952 - LogUtils.py[line:112] - INFO:  [x] Received '{"jsonStr": "{\\"result\\": \\"\\\\u6ca1\\\\u6709\\\\u6ca1\\\\u6709\\", \\"ret\\": 0}", "text": "\\u6ca1\\u6709\\u6ca1\\u6709", "who": "human", "create_at": "2018-01-06 13:18:43", "call_id": "16", "record_fpath": "/8a9fc0df0e56058d56e8a0323f5ed08f/human_audio/15900282168_in_1_20180106131835.wav", "mark": "insert"}'


2018-01-06 13:18:46,952 - LogUtils.py[line:112] - INFO: postgresql connect host .....   118.190.166.165
2018-01-06 13:18:46,996 - LogUtils.py[line:120] - ERROR: runsql exception error insert or update on table "fs_call_replay" violates foreign key constraint "fs_call_replay_call_id_a2c15655_fk_fs_call_id"
DETAIL:  Key (call_id)=(16) is not present in table "fs_call".
 
2018-01-06 13:18:46,996 - LogUtils.py[line:112] - INFO: ******** run_insert_sql..*********...INSERT INTO fs_call_replay(who, text, record_fpath, create_at, call_id,resp_param)VALUES ('human', '没有没有', '/8a9fc0df0e56058d56e8a0323f5ed08f/human_audio/15900282168_in_1_20180106131835.wav', '2018-01-06 13:18:43', '16','{"result": "\u6ca1\u6709\u6ca1\u6709", "ret": 0}') RETURNING id
2018-01-06 13:18:47,601 - LogUtils.py[line:112] - INFO:  [x] Received '{"jsonStr": "{\\"info\\": [{\\"is_flow_output\\": true, \\"output\\": \\"\\\\u60a8\\\\u597d\\\\uff0c\\\\u6211\\\\u4eec\\\\u662f\\\\u529e\\\\u7406\\\\u8d37\\\\u6b3e\\\\u7684\\\\uff0c\\\\u8bf7\\\\u95ee\\\\u60a8\\\\u6709\\\\u8d44\\\\u91d1\\\\u4e0a\\\\u7684\\\\u9700\\\\u6c42\\\\u5417\\\\uff1f\\", \\"node_text\\": \\"\\\\u8bed\\\\u6599\\\\u8282\\\\u70b9\\", \\"flow_id\\": \\"505c426d2b8fbe8f8f5f18250c2f568f\\", \\"label\\": \\"\\\\u5f00\\\\u573a\\\\u767d\\", \\"session_end\\": false, \\"state\\": \\"\\", \\"node_id\\": -3, \\"output_resource\\": \\"7.wav\\", \\"flow_end\\": false, \\"input\\": \\"\\\\u4f60\\\\u597d\\", \\"similarity\\": 1, \\"flow_title\\": \\"\\\\u5f00\\\\u573a\\\\u767d\\", \\"output_type\\": \\"path\\", \\"user_label\\": \\"\\\\u5f00\\\\u573a\\\\u6302\\\\u65ad\\", \\"id\\": \\"505c426d2b8fbe8f8f5f18250c2f568f_-3\\"}], \\"successful\\": true, \\"message\\": \\"ok\\"}", "text": "\\u60a8\\u597d\\uff0c\\u6211\\u4eec\\u662f\\u529e\\u7406\\u8d37\\u6b3e\\u7684\\uff0c\\u8bf7\\u95ee\\u60a8\\u6709\\u8d44\\u91d1\\u4e0a\\u7684\\u9700\\u6c42\\u5417\\uff1f", "who": "bot", "create_at": "2018-01-06 13:18:43", "call_id": "19", "record_fpath": "/8a9fc0df0e56058d56e8a0323f5ed08f/bot_audio/7.wav", "mark": "insert"}'


2018-01-06 13:18:47,602 - LogUtils.py[line:112] - INFO: postgresql connect host .....   118.190.166.165
2018-01-06 13:18:47,668 - LogUtils.py[line:120] - ERROR: runsql exception error insert or update on table "fs_call_replay" violates foreign key constraint "fs_call_replay_call_id_a2c15655_fk_fs_call_id"
DETAIL:  Key (call_id)=(19) is not present in table "fs_call".
 
2018-01-06 13:18:47,669 - LogUtils.py[line:112] - INFO: ******** run_insert_sql..*********...INSERT INTO fs_call_replay(who, text, record_fpath, create_at, call_id,resp_param)VALUES ('bot', '您好，我们是办理贷款的，请问您有资金上的需求吗？', '/8a9fc0df0e56058d56e8a0323f5ed08f/bot_audio/7.wav', '2018-01-06 13:18:43', '19','{"info": [{"is_flow_output": true, "output": "\u60a8\u597d\uff0c\u6211\u4eec\u662f\u529e\u7406\u8d37\u6b3e\u7684\uff0c\u8bf7\u95ee\u60a8\u6709\u8d44\u91d1\u4e0a\u7684\u9700\u6c42\u5417\uff1f", "node_text": "\u8bed\u6599\u8282\u70b9", "flow_id": "505c426d2b8fbe8f8f5f18250c2f568f", "label": "\u5f00\u573a\u767d", "session_end": false, "state": "", "node_id": -3, "output_resource": "7.wav", "flow_end": false, "input": "\u4f60\u597d", "similarity": 1, "flow_title": "\u5f00\u573a\u767d", "output_type": "path", "user_label": "\u5f00\u573a\u6302\u65ad", "id": "505c426d2b8fbe8f8f5f18250c2f568f_-3"}], "successful": true, "message": "ok"}') RETURNING id
2018-01-06 13:18:51,233 - LogUtils.py[line:112] - INFO:  [x] Received '{"user_label": "\\u5f00\\u573a\\u6302\\u65ad", "channal_uuid": "9d5fe208-5fb2-44ac-96e8-4c8441384a69", "mark": "user_label"}'


2018-01-06 13:18:51,233 - LogUtils.py[line:112] - INFO: postgresql connect host .....   118.190.166.165
2018-01-06 13:18:51,276 - LogUtils.py[line:112] - INFO: postgresql connect.....closed!!!
2018-01-06 13:18:51,276 - LogUtils.py[line:112] - INFO:  run_update_sql.........user_label... update fs_call set cust_tag = '开场挂断' where channal_uuid ='9d5fe208-5fb2-44ac-96e8-4c8441384a69' 
2018-01-06 13:18:56,562 - LogUtils.py[line:112] - INFO:  [x] Received '{"jsonStr": "{\\"info\\": [{\\"is_flow_output\\": true, \\"output\\": \\"\\\\u6211\\\\u4eec\\\\u662f\\\\u4e2d\\\\u5b89\\\\u4fe1\\\\u6210\\\\uff0c\\\\u4e13\\\\u4e1a\\\\u529e\\\\u7406\\\\u94f6\\\\u884c\\\\u8d37\\\\u6b3e\\\\u7684\\\\uff0c\\\\u8bf7\\\\u95ee\\\\u60a8\\\\u5927\\\\u6982\\\\u9700\\\\u8981\\\\u591a\\\\u5c11\\\\u91d1\\\\u989d\\\\u5462\\", \\"node_text\\": \\"\\\\u4f01\\\\u4e1a\\\\u4ecb\\\\u7ecd\\", \\"flow_id\\": \\"81f445b5cc3c92c5cdf3a1488a7c2eb7\\", \\"label\\": \\"\\\\u4f01\\\\u4e1a\\\\u4ecb\\\\u7ecd\\", \\"session_end\\": false, \\"state\\": \\"\\", \\"node_id\\": -11, \\"output_resource\\": \\"2.wav\\", \\"flow_end\\": false, \\"input\\": \\"\\\\u55ef\\\\u60f3\\\\u4e70\\\\u4e2a\\\\u8f66\\", \\"similarity\\": 1, \\"flow_title\\": \\"\\\\u516c\\\\u53f8\\\\u4ecb\\\\u7ecd\\", \\"output_type\\": \\"path\\", \\"user_label\\": \\"\\\\u5f00\\\\u573a\\\\u6302\\\\u65ad\\", \\"id\\": \\"81f445b5cc3c92c5cdf3a1488a7c2eb7_-11\\"}], \\"successful\\": true, \\"message\\": \\"ok\\"}", "text": "\\u6211\\u4eec\\u662f\\u4e2d\\u5b89\\u4fe1\\u6210\\uff0c\\u4e13\\u4e1a\\u529e\\u7406\\u94f6\\u884c\\u8d37\\u6b3e\\u7684\\uff0c\\u8bf7\\u95ee\\u60a8\\u5927\\u6982\\u9700\\u8981\\u591a\\u5c11\\u91d1\\u989d\\u5462", "who": "bot", "create_at": "2018-01-06 13:18:51", "call_id": "19", "record_fpath": "/8a9fc0df0e56058d56e8a0323f5ed08f/bot_audio/2.wav", "mark": "insert"}'


2018-01-06 13:18:56,563 - LogUtils.py[line:112] - INFO: postgresql connect host .....   118.190.166.165
2018-01-06 13:18:56,628 - LogUtils.py[line:120] - ERROR: runsql exception error insert or update on table "fs_call_replay" violates foreign key constraint "fs_call_replay_call_id_a2c15655_fk_fs_call_id"
DETAIL:  Key (call_id)=(19) is not present in table "fs_call".
 
2018-01-06 13:18:56,629 - LogUtils.py[line:112] - INFO: ******** run_insert_sql..*********...INSERT INTO fs_call_replay(who, text, record_fpath, create_at, call_id,resp_param)VALUES ('bot', '我们是中安信成，专业办理银行贷款的，请问您大概需要多少金额呢', '/8a9fc0df0e56058d56e8a0323f5ed08f/bot_audio/2.wav', '2018-01-06 13:18:51', '19','{"info": [{"is_flow_output": true, "output": "\u6211\u4eec\u662f\u4e2d\u5b89\u4fe1\u6210\uff0c\u4e13\u4e1a\u529e\u7406\u94f6\u884c\u8d37\u6b3e\u7684\uff0c\u8bf7\u95ee\u60a8\u5927\u6982\u9700\u8981\u591a\u5c11\u91d1\u989d\u5462", "node_text": "\u4f01\u4e1a\u4ecb\u7ecd", "flow_id": "81f445b5cc3c92c5cdf3a1488a7c2eb7", "label": "\u4f01\u4e1a\u4ecb\u7ecd", "session_end": false, "state": "", "node_id": -11, "output_resource": "2.wav", "flow_end": false, "input": "\u55ef\u60f3\u4e70\u4e2a\u8f66", "similarity": 1, "flow_title": "\u516c\u53f8\u4ecb\u7ecd", "output_type": "path", "user_label": "\u5f00\u573a\u6302\u65ad", "id": "81f445b5cc3c92c5cdf3a1488a7c2eb7_-11"}], "successful": true, "message": "ok"}') RETURNING id
2018-01-06 13:18:57,796 - LogUtils.py[line:112] - INFO:  [x] Received '{"user_label": "\\u5f00\\u573a\\u6302\\u65ad", "channal_uuid": "4458dc3f-f980-4a85-a771-c3ab67376871", "mark": "user_label"}'


2018-01-06 13:18:57,796 - LogUtils.py[line:112] - INFO: postgresql connect host .....   118.190.166.165
2018-01-06 13:18:57,839 - LogUtils.py[line:112] - INFO: postgresql connect.....closed!!!
2018-01-06 13:18:57,839 - LogUtils.py[line:112] - INFO:  run_update_sql.........user_label... update fs_call set cust_tag = '开场挂断' where channal_uuid ='4458dc3f-f980-4a85-a771-c3ab67376871' 
2018-01-06 13:18:58,708 - LogUtils.py[line:112] - INFO:  [x] Received '{"user_label": "\\u5f00\\u573a\\u6302\\u65ad", "channal_uuid": "9d5fe208-5fb2-44ac-96e8-4c8441384a69", "mark": "user_label"}'


2018-01-06 13:18:58,708 - LogUtils.py[line:112] - INFO: postgresql connect host .....   118.190.166.165
2018-01-06 13:18:58,774 - LogUtils.py[line:112] - INFO: postgresql connect.....closed!!!
2018-01-06 13:18:58,774 - LogUtils.py[line:112] - INFO:  run_update_sql.........user_label... update fs_call set cust_tag = '开场挂断' where channal_uuid ='9d5fe208-5fb2-44ac-96e8-4c8441384a69' 
2018-01-06 13:19:02,407 - LogUtils.py[line:112] - INFO:  [x] Received '{"jsonStr": "{\\"result\\": \\"\\\\u6ca1\\\\u6709\\", \\"ret\\": 0}", "text": "\\u6ca1\\u6709", "who": "human", "create_at": "2018-01-06 13:19:00", "call_id": "19", "record_fpath": "/8a9fc0df0e56058d56e8a0323f5ed08f/human_audio/13132229287_in_4_20180106131834.wav", "mark": "insert"}'


2018-01-06 13:19:02,407 - LogUtils.py[line:112] - INFO: postgresql connect host .....   118.190.166.165
2018-01-06 13:19:02,451 - LogUtils.py[line:120] - ERROR: runsql exception error insert or update on table "fs_call_replay" violates foreign key constraint "fs_call_replay_call_id_a2c15655_fk_fs_call_id"
DETAIL:  Key (call_id)=(19) is not present in table "fs_call".
 
2018-01-06 13:19:02,451 - LogUtils.py[line:112] - INFO: ******** run_insert_sql..*********...INSERT INTO fs_call_replay(who, text, record_fpath, create_at, call_id,resp_param)VALUES ('human', '没有', '/8a9fc0df0e56058d56e8a0323f5ed08f/human_audio/13132229287_in_4_20180106131834.wav', '2018-01-06 13:19:00', '19','{"result": "\u6ca1\u6709", "ret": 0}') RETURNING id
2018-01-06 13:19:03,117 - LogUtils.py[line:112] - INFO:  [x] Received '{"jsonStr": "{\\"info\\": [{\\"is_flow_output\\": true, \\"output\\": \\"\\\\u6211\\\\u4eec\\\\u662f\\\\u4e2d\\\\u5b89\\\\u4fe1\\\\u6210\\\\uff0c\\\\u4e13\\\\u4e1a\\\\u529e\\\\u7406\\\\u94f6\\\\u884c\\\\u8d37\\\\u6b3e\\\\u7684\\\\uff0c\\\\u8bf7\\\\u95ee\\\\u60a8\\\\u5927\\\\u6982\\\\u9700\\\\u8981\\\\u591a\\\\u5c11\\\\u91d1\\\\u989d\\\\u5462\\", \\"node_text\\": \\"\\\\u4f01\\\\u4e1a\\\\u4ecb\\\\u7ecd\\", \\"flow_id\\": \\"81f445b5cc3c92c5cdf3a1488a7c2eb7\\", \\"label\\": \\"\\\\u4f01\\\\u4e1a\\\\u4ecb\\\\u7ecd\\", \\"session_end\\": false, \\"state\\": \\"\\", \\"node_id\\": -11, \\"output_resource\\": \\"2.wav\\", \\"flow_end\\": false, \\"input\\": \\"\\\\u6211\\\\u60f3\\\\u4e70\\\\u4e2a\\\\u8f66\\", \\"similarity\\": 1, \\"flow_title\\": \\"\\\\u516c\\\\u53f8\\\\u4ecb\\\\u7ecd\\", \\"output_type\\": \\"path\\", \\"user_label\\": \\"\\\\u5f00\\\\u573a\\\\u6302\\\\u65ad\\", \\"id\\": \\"81f445b5cc3c92c5cdf3a1488a7c2eb7_-11\\"}], \\"successful\\": true, \\"message\\": \\"ok\\"}", "text": "\\u6211\\u4eec\\u662f\\u4e2d\\u5b89\\u4fe1\\u6210\\uff0c\\u4e13\\u4e1a\\u529e\\u7406\\u94f6\\u884c\\u8d37\\u6b3e\\u7684\\uff0c\\u8bf7\\u95ee\\u60a8\\u5927\\u6982\\u9700\\u8981\\u591a\\u5c11\\u91d1\\u989d\\u5462", "who": "bot", "create_at": "2018-01-06 13:18:57", "call_id": "16", "record_fpath": "/8a9fc0df0e56058d56e8a0323f5ed08f/bot_audio/2.wav", "mark": "insert"}'


2018-01-06 13:19:03,117 - LogUtils.py[line:112] - INFO: postgresql connect host .....   118.190.166.165
2018-01-06 13:19:03,184 - LogUtils.py[line:120] - ERROR: runsql exception error insert or update on table "fs_call_replay" violates foreign key constraint "fs_call_replay_call_id_a2c15655_fk_fs_call_id"
DETAIL:  Key (call_id)=(16) is not present in table "fs_call".
 
2018-01-06 13:19:03,184 - LogUtils.py[line:112] - INFO: ******** run_insert_sql..*********...INSERT INTO fs_call_replay(who, text, record_fpath, create_at, call_id,resp_param)VALUES ('bot', '我们是中安信成，专业办理银行贷款的，请问您大概需要多少金额呢', '/8a9fc0df0e56058d56e8a0323f5ed08f/bot_audio/2.wav', '2018-01-06 13:18:57', '16','{"info": [{"is_flow_output": true, "output": "\u6211\u4eec\u662f\u4e2d\u5b89\u4fe1\u6210\uff0c\u4e13\u4e1a\u529e\u7406\u94f6\u884c\u8d37\u6b3e\u7684\uff0c\u8bf7\u95ee\u60a8\u5927\u6982\u9700\u8981\u591a\u5c11\u91d1\u989d\u5462", "node_text": "\u4f01\u4e1a\u4ecb\u7ecd", "flow_id": "81f445b5cc3c92c5cdf3a1488a7c2eb7", "label": "\u4f01\u4e1a\u4ecb\u7ecd", "session_end": false, "state": "", "node_id": -11, "output_resource": "2.wav", "flow_end": false, "input": "\u6211\u60f3\u4e70\u4e2a\u8f66", "similarity": 1, "flow_title": "\u516c\u53f8\u4ecb\u7ecd", "output_type": "path", "user_label": "\u5f00\u573a\u6302\u65ad", "id": "81f445b5cc3c92c5cdf3a1488a7c2eb7_-11"}], "successful": true, "message": "ok"}') RETURNING id
2018-01-06 13:19:06,173 - LogUtils.py[line:112] - INFO:  [x] Received '{"jsonStr": "{\\"result\\": \\"\\\\u6211\\\\u60f3\\\\u4e70\\\\u623f\\", \\"ret\\": 0}", "text": "\\u6211\\u60f3\\u4e70\\u623f", "who": "human", "create_at": "2018-01-06 13:19:03", "call_id": "16", "record_fpath": "/8a9fc0df0e56058d56e8a0323f5ed08f/human_audio/15900282168_in_3_20180106131835.wav", "mark": "insert"}'


2018-01-06 13:19:06,173 - LogUtils.py[line:112] - INFO: postgresql connect host .....   118.190.166.165
2018-01-06 13:19:06,216 - LogUtils.py[line:120] - ERROR: runsql exception error insert or update on table "fs_call_replay" violates foreign key constraint "fs_call_replay_call_id_a2c15655_fk_fs_call_id"
DETAIL:  Key (call_id)=(16) is not present in table "fs_call".
 
2018-01-06 13:19:06,216 - LogUtils.py[line:112] - INFO: ******** run_insert_sql..*********...INSERT INTO fs_call_replay(who, text, record_fpath, create_at, call_id,resp_param)VALUES ('human', '我想买房', '/8a9fc0df0e56058d56e8a0323f5ed08f/human_audio/15900282168_in_3_20180106131835.wav', '2018-01-06 13:19:03', '16','{"result": "\u6211\u60f3\u4e70\u623f", "ret": 0}') RETURNING id
2018-01-06 13:19:06,998 - LogUtils.py[line:112] - INFO:  [x] Received '{"jsonStr": "{\\"result\\": \\"\\\\u4e0a\\\\u73ed\\\\u5462\\", \\"ret\\": 0}", "text": "\\u4e0a\\u73ed\\u5462", "who": "human", "create_at": "2018-01-06 13:19:04", "call_id": "19", "record_fpath": "/8a9fc0df0e56058d56e8a0323f5ed08f/human_audio/13132229287_in_5_20180106131834.wav", "mark": "insert"}'


2018-01-06 13:19:06,998 - LogUtils.py[line:112] - INFO: postgresql connect host .....   118.190.166.165
2018-01-06 13:19:07,064 - LogUtils.py[line:120] - ERROR: runsql exception error insert or update on table "fs_call_replay" violates foreign key constraint "fs_call_replay_call_id_a2c15655_fk_fs_call_id"
DETAIL:  Key (call_id)=(19) is not present in table "fs_call".
 
2018-01-06 13:19:07,064 - LogUtils.py[line:112] - INFO: ******** run_insert_sql..*********...INSERT INTO fs_call_replay(who, text, record_fpath, create_at, call_id,resp_param)VALUES ('human', '上班呢', '/8a9fc0df0e56058d56e8a0323f5ed08f/human_audio/13132229287_in_5_20180106131834.wav', '2018-01-06 13:19:04', '19','{"result": "\u4e0a\u73ed\u5462", "ret": 0}') RETURNING id
2018-01-06 13:19:11,741 - LogUtils.py[line:112] - INFO:  [x] Received '{"jsonStr": "{\\"info\\": [{\\"is_flow_output\\": true, \\"output\\": \\"\\\\u90a3\\\\u60a8\\\\u7684\\\\u5de5\\\\u8d44\\\\u73b0\\\\u5728\\\\u662f\\\\u6253\\\\u5361\\\\u8fd8\\\\u662f\\\\u53d1\\\\u73b0\\\\u91d1\\\\u7684\\\\uff0c\\\\u793e\\\\u4fdd\\\\u6216\\\\u516c\\\\u79ef\\\\u91d1\\\\u6709\\\\u4ea4\\\\u5417\\\\uff1f\\", \\"node_text\\": \\"\\\\u95ee\\\\u98983\\", \\"flow_id\\": \\"ba8d69e98f71243574ab338537a7a1bd\\", \\"label\\": \\"\\\\u95ee\\\\u98983\\", \\"session_end\\": false, \\"state\\": \\"\\", \\"node_id\\": -5, \\"output_resource\\": \\"t12.wav\\", \\"flow_end\\": false, \\"input\\": \\"\\\\u4e0a\\\\u73ed\\\\u5462\\", \\"similarity\\": 0.9892436482176099, \\"flow_title\\": \\"\\\\u4e86\\\\u89e3\\\\u60c5\\\\u51b5\\", \\"output_type\\": \\"path\\", \\"user_label\\": \\"\\\\u5f00\\\\u573a\\\\u6302\\\\u65ad\\", \\"id\\": \\"ba8d69e98f71243574ab338537a7a1bd_-5\\"}], \\"successful\\": true, \\"message\\": \\"ok\\"}", "text": "\\u90a3\\u60a8\\u7684\\u5de5\\u8d44\\u73b0\\u5728\\u662f\\u6253\\u5361\\u8fd8\\u662f\\u53d1\\u73b0\\u91d1\\u7684\\uff0c\\u793e\\u4fdd\\u6216\\u516c\\u79ef\\u91d1\\u6709\\u4ea4\\u5417\\uff1f", "who": "bot", "create_at": "2018-01-06 13:19:07", "call_id": "19", "record_fpath": "/8a9fc0df0e56058d56e8a0323f5ed08f/bot_audio/t12.wav", "mark": "insert"}'


2018-01-06 13:19:11,742 - LogUtils.py[line:112] - INFO: postgresql connect host .....   118.190.166.165
2018-01-06 13:19:11,785 - LogUtils.py[line:120] - ERROR: runsql exception error insert or update on table "fs_call_replay" violates foreign key constraint "fs_call_replay_call_id_a2c15655_fk_fs_call_id"
DETAIL:  Key (call_id)=(19) is not present in table "fs_call".
 
2018-01-06 13:19:11,786 - LogUtils.py[line:112] - INFO: ******** run_insert_sql..*********...INSERT INTO fs_call_replay(who, text, record_fpath, create_at, call_id,resp_param)VALUES ('bot', '那您的工资现在是打卡还是发现金的，社保或公积金有交吗？', '/8a9fc0df0e56058d56e8a0323f5ed08f/bot_audio/t12.wav', '2018-01-06 13:19:07', '19','{"info": [{"is_flow_output": true, "output": "\u90a3\u60a8\u7684\u5de5\u8d44\u73b0\u5728\u662f\u6253\u5361\u8fd8\u662f\u53d1\u73b0\u91d1\u7684\uff0c\u793e\u4fdd\u6216\u516c\u79ef\u91d1\u6709\u4ea4\u5417\uff1f", "node_text": "\u95ee\u98983", "flow_id": "ba8d69e98f71243574ab338537a7a1bd", "label": "\u95ee\u98983", "session_end": false, "state": "", "node_id": -5, "output_resource": "t12.wav", "flow_end": false, "input": "\u4e0a\u73ed\u5462", "similarity": 0.9892436482176099, "flow_title": "\u4e86\u89e3\u60c5\u51b5", "output_type": "path", "user_label": "\u5f00\u573a\u6302\u65ad", "id": "ba8d69e98f71243574ab338537a7a1bd_-5"}], "successful": true, "message": "ok"}') RETURNING id
2018-01-06 13:19:13,756 - LogUtils.py[line:112] - INFO:  [x] Received '{"jsonStr": "{\\"result\\": \\"\\\\u6709\\\\u554a\\", \\"ret\\": 0}", "text": "\\u6709\\u554a", "who": "human", "create_at": "2018-01-06 13:19:11", "call_id": "19", "record_fpath": "/8a9fc0df0e56058d56e8a0323f5ed08f/human_audio/13132229287_in_6_20180106131834.wav", "mark": "insert"}'


2018-01-06 13:19:13,757 - LogUtils.py[line:112] - INFO: postgresql connect host .....   118.190.166.165
2018-01-06 13:19:13,823 - LogUtils.py[line:120] - ERROR: runsql exception error insert or update on table "fs_call_replay" violates foreign key constraint "fs_call_replay_call_id_a2c15655_fk_fs_call_id"
DETAIL:  Key (call_id)=(19) is not present in table "fs_call".
 
2018-01-06 13:19:13,824 - LogUtils.py[line:112] - INFO: ******** run_insert_sql..*********...INSERT INTO fs_call_replay(who, text, record_fpath, create_at, call_id,resp_param)VALUES ('human', '有啊', '/8a9fc0df0e56058d56e8a0323f5ed08f/human_audio/13132229287_in_6_20180106131834.wav', '2018-01-06 13:19:11', '19','{"result": "\u6709\u554a", "ret": 0}') RETURNING id
2018-01-06 13:19:15,423 - LogUtils.py[line:112] - INFO:  [x] Received '{"jsonStr": "{\\"result\\": \\"\\\\u8981\\\\u4e70\\\\u8f66\\", \\"ret\\": 0}", "text": "\\u8981\\u4e70\\u8f66", "who": "human", "create_at": "2018-01-06 13:19:12", "call_id": "16", "record_fpath": "/8a9fc0df0e56058d56e8a0323f5ed08f/human_audio/15900282168_in_4_20180106131835.wav", "mark": "insert"}'


2018-01-06 13:19:15,423 - LogUtils.py[line:112] - INFO: postgresql connect host .....   118.190.166.165
2018-01-06 13:19:15,468 - LogUtils.py[line:120] - ERROR: runsql exception error insert or update on table "fs_call_replay" violates foreign key constraint "fs_call_replay_call_id_a2c15655_fk_fs_call_id"
DETAIL:  Key (call_id)=(16) is not present in table "fs_call".
 
2018-01-06 13:19:15,468 - LogUtils.py[line:112] - INFO: ******** run_insert_sql..*********...INSERT INTO fs_call_replay(who, text, record_fpath, create_at, call_id,resp_param)VALUES ('human', '要买车', '/8a9fc0df0e56058d56e8a0323f5ed08f/human_audio/15900282168_in_4_20180106131835.wav', '2018-01-06 13:19:12', '16','{"result": "\u8981\u4e70\u8f66", "ret": 0}') RETURNING id
2018-01-06 13:19:17,256 - LogUtils.py[line:112] - INFO:  [x] Received '{"jsonStr": "{\\"info\\": [{\\"is_flow_output\\": true, \\"output\\": \\"\\\\u8bf7\\\\u95ee\\\\u60a8\\\\u5728\\\\u5317\\\\u4eac\\\\u6709\\\\u623f\\\\u5417\\\\uff1f\\", \\"node_text\\": \\"\\\\u95ee\\\\u98987\\", \\"flow_id\\": \\"ba8d69e98f71243574ab338537a7a1bd\\", \\"label\\": \\"\\\\u95ee\\\\u98987\\", \\"session_end\\": false, \\"state\\": \\"\\", \\"node_id\\": -23, \\"output_resource\\": \\"3.wav\\", \\"flow_end\\": false, \\"input\\": \\"\\\\u8981\\\\u4e70\\\\u8f66\\", \\"similarity\\": 1, \\"flow_title\\": \\"\\\\u4e86\\\\u89e3\\\\u60c5\\\\u51b5\\", \\"output_type\\": \\"path\\", \\"user_label\\": \\"\\\\u5f00\\\\u573a\\\\u6302\\\\u65ad\\", \\"id\\": \\"ba8d69e98f71243574ab338537a7a1bd_-23\\"}], \\"successful\\": true, \\"message\\": \\"ok\\"}", "text": "\\u8bf7\\u95ee\\u60a8\\u5728\\u5317\\u4eac\\u6709\\u623f\\u5417\\uff1f", "who": "bot", "create_at": "2018-01-06 13:19:15", "call_id": "16", "record_fpath": "/8a9fc0df0e56058d56e8a0323f5ed08f/bot_audio/3.wav", "mark": "insert"}'


2018-01-06 13:19:17,257 - LogUtils.py[line:112] - INFO: postgresql connect host .....   118.190.166.165
2018-01-06 13:19:17,323 - LogUtils.py[line:120] - ERROR: runsql exception error insert or update on table "fs_call_replay" violates foreign key constraint "fs_call_replay_call_id_a2c15655_fk_fs_call_id"
DETAIL:  Key (call_id)=(16) is not present in table "fs_call".
 
2018-01-06 13:19:17,323 - LogUtils.py[line:112] - INFO: ******** run_insert_sql..*********...INSERT INTO fs_call_replay(who, text, record_fpath, create_at, call_id,resp_param)VALUES ('bot', '请问您在北京有房吗？', '/8a9fc0df0e56058d56e8a0323f5ed08f/bot_audio/3.wav', '2018-01-06 13:19:15', '16','{"info": [{"is_flow_output": true, "output": "\u8bf7\u95ee\u60a8\u5728\u5317\u4eac\u6709\u623f\u5417\uff1f", "node_text": "\u95ee\u98987", "flow_id": "ba8d69e98f71243574ab338537a7a1bd", "label": "\u95ee\u98987", "session_end": false, "state": "", "node_id": -23, "output_resource": "3.wav", "flow_end": false, "input": "\u8981\u4e70\u8f66", "similarity": 1, "flow_title": "\u4e86\u89e3\u60c5\u51b5", "output_type": "path", "user_label": "\u5f00\u573a\u6302\u65ad", "id": "ba8d69e98f71243574ab338537a7a1bd_-23"}], "successful": true, "message": "ok"}') RETURNING id
2018-01-06 13:19:20,481 - LogUtils.py[line:112] - INFO:  [x] Received '{"jsonStr": "{\\"result\\": \\"\\\\u7b97\\\\u4e86\\", \\"ret\\": 0}", "text": "\\u7b97\\u4e86", "who": "human", "create_at": "2018-01-06 13:19:17", "call_id": "16", "record_fpath": "/8a9fc0df0e56058d56e8a0323f5ed08f/human_audio/15900282168_in_5_20180106131835.wav", "mark": "insert"}'


2018-01-06 13:19:20,481 - LogUtils.py[line:112] - INFO: postgresql connect host .....   118.190.166.165
2018-01-06 13:19:20,525 - LogUtils.py[line:120] - ERROR: runsql exception error insert or update on table "fs_call_replay" violates foreign key constraint "fs_call_replay_call_id_a2c15655_fk_fs_call_id"
DETAIL:  Key (call_id)=(16) is not present in table "fs_call".
 
2018-01-06 13:19:20,525 - LogUtils.py[line:112] - INFO: ******** run_insert_sql..*********...INSERT INTO fs_call_replay(who, text, record_fpath, create_at, call_id,resp_param)VALUES ('human', '算了', '/8a9fc0df0e56058d56e8a0323f5ed08f/human_audio/15900282168_in_5_20180106131835.wav', '2018-01-06 13:19:17', '16','{"result": "\u7b97\u4e86", "ret": 0}') RETURNING id
2018-01-06 13:19:23,348 - LogUtils.py[line:112] - INFO:  [x] Received '{"jsonStr": "{\\"result\\": \\"\\\\u80fd\\\\u5e26\\\\u7ed9\\\\u6211\\\\u5417\\", \\"ret\\": 0}", "text": "\\u80fd\\u5e26\\u7ed9\\u6211\\u5417", "who": "human", "create_at": "2018-01-06 13:19:19", "call_id": "19", "record_fpath": "/8a9fc0df0e56058d56e8a0323f5ed08f/human_audio/13132229287_in_7_20180106131834.wav", "mark": "insert"}'


2018-01-06 13:19:23,348 - LogUtils.py[line:112] - INFO: postgresql connect host .....   118.190.166.165
2018-01-06 13:19:23,414 - LogUtils.py[line:120] - ERROR: runsql exception error insert or update on table "fs_call_replay" violates foreign key constraint "fs_call_replay_call_id_a2c15655_fk_fs_call_id"
DETAIL:  Key (call_id)=(19) is not present in table "fs_call".
 
2018-01-06 13:19:23,414 - LogUtils.py[line:112] - INFO: ******** run_insert_sql..*********...INSERT INTO fs_call_replay(who, text, record_fpath, create_at, call_id,resp_param)VALUES ('human', '能带给我吗', '/8a9fc0df0e56058d56e8a0323f5ed08f/human_audio/13132229287_in_7_20180106131834.wav', '2018-01-06 13:19:19', '19','{"result": "\u80fd\u5e26\u7ed9\u6211\u5417", "ret": 0}') RETURNING id
2018-01-06 13:19:24,076 - LogUtils.py[line:112] - INFO:  [x] Received '{"jsonStr": "{\\"info\\": [{\\"is_flow_output\\": true, \\"output\\": \\"\\\\u8bf7\\\\u95ee\\\\u60a8\\\\u623f\\\\u5b50\\\\u662f\\\\u54ea\\\\u4e2a\\\\u5c0f\\\\u533a\\\\uff0c\\\\u591a\\\\u5927\\\\u9762\\\\u79ef\\\\u7684\\\\u5462\\\\uff1f\\", \\"node_text\\": \\"\\\\u95ee\\\\u98988\\", \\"flow_id\\": \\"ba8d69e98f71243574ab338537a7a1bd\\", \\"label\\": \\"\\\\u95ee\\\\u98988\\", \\"session_end\\": false, \\"state\\": \\"\\", \\"node_id\\": -26, \\"output_resource\\": \\"6.wav\\", \\"flow_end\\": false, \\"input\\": \\"\\\\u7b97\\\\u4e86\\", \\"similarity\\": 1, \\"flow_title\\": \\"\\\\u4e86\\\\u89e3\\\\u60c5\\\\u51b5\\", \\"output_type\\": \\"path\\", \\"user_label\\": \\"\\\\u4e2a\\\\u4eba\\\\u62b5\\\\u62bc\\\\u8d37\\\\u6b3e\\", \\"id\\": \\"ba8d69e98f71243574ab338537a7a1bd_-26\\"}], \\"successful\\": true, \\"message\\": \\"ok\\"}", "text": "\\u8bf7\\u95ee\\u60a8\\u623f\\u5b50\\u662f\\u54ea\\u4e2a\\u5c0f\\u533a\\uff0c\\u591a\\u5927\\u9762\\u79ef\\u7684\\u5462\\uff1f", "who": "bot", "create_at": "2018-01-06 13:19:20", "call_id": "16", "record_fpath": "/8a9fc0df0e56058d56e8a0323f5ed08f/bot_audio/6.wav", "mark": "insert"}'


2018-01-06 13:19:24,077 - LogUtils.py[line:112] - INFO: postgresql connect host .....   118.190.166.165
2018-01-06 13:19:24,121 - LogUtils.py[line:120] - ERROR: runsql exception error insert or update on table "fs_call_replay" violates foreign key constraint "fs_call_replay_call_id_a2c15655_fk_fs_call_id"
DETAIL:  Key (call_id)=(16) is not present in table "fs_call".
 
2018-01-06 13:19:24,121 - LogUtils.py[line:112] - INFO: ******** run_insert_sql..*********...INSERT INTO fs_call_replay(who, text, record_fpath, create_at, call_id,resp_param)VALUES ('bot', '请问您房子是哪个小区，多大面积的呢？', '/8a9fc0df0e56058d56e8a0323f5ed08f/bot_audio/6.wav', '2018-01-06 13:19:20', '16','{"info": [{"is_flow_output": true, "output": "\u8bf7\u95ee\u60a8\u623f\u5b50\u662f\u54ea\u4e2a\u5c0f\u533a\uff0c\u591a\u5927\u9762\u79ef\u7684\u5462\uff1f", "node_text": "\u95ee\u98988", "flow_id": "ba8d69e98f71243574ab338537a7a1bd", "label": "\u95ee\u98988", "session_end": false, "state": "", "node_id": -26, "output_resource": "6.wav", "flow_end": false, "input": "\u7b97\u4e86", "similarity": 1, "flow_title": "\u4e86\u89e3\u60c5\u51b5", "output_type": "path", "user_label": "\u4e2a\u4eba\u62b5\u62bc\u8d37\u6b3e", "id": "ba8d69e98f71243574ab338537a7a1bd_-26"}], "successful": true, "message": "ok"}') RETURNING id
2018-01-06 13:19:27,789 - LogUtils.py[line:112] - INFO:  [x] Received '{"user_id": "3", "task_id": "5", "number": "13132229287", "call_id": "19", "flow_id": "8a9fc0df0e56058d56e8a0323f5ed08f", "mark": "statistical"}'


2018-01-06 13:19:27,789 - LogUtils.py[line:112] - INFO: postgresql connect host .....   118.190.166.165
2018-01-06 13:19:27,857 - LogUtils.py[line:112] - INFO: postgresql connect.....closed!!!
2018-01-06 13:19:29,518 - LogUtils.py[line:112] - INFO:  [x] Received '{"user_label": "\\u4e2a\\u4eba\\u62b5\\u62bc\\u8d37\\u6b3e", "channal_uuid": "4458dc3f-f980-4a85-a771-c3ab67376871", "mark": "user_label"}'


2018-01-06 13:19:29,519 - LogUtils.py[line:112] - INFO: postgresql connect host .....   118.190.166.165
2018-01-06 13:19:29,562 - LogUtils.py[line:112] - INFO: postgresql connect.....closed!!!
2018-01-06 13:19:29,562 - LogUtils.py[line:112] - INFO:  run_update_sql.........user_label... update fs_call set cust_tag = '个人抵押贷款' where channal_uuid ='4458dc3f-f980-4a85-a771-c3ab67376871' 
2018-01-06 13:19:37,409 - LogUtils.py[line:112] - INFO:  [x] Received '{"jsonStr": "{\\"result\\": \\"\\\\u597d\\\\u7684\\\\u597d\\\\u7684\\", \\"ret\\": 0}", "text": "\\u597d\\u7684\\u597d\\u7684", "who": "human", "create_at": "2018-01-06 13:19:34", "call_id": "16", "record_fpath": "/8a9fc0df0e56058d56e8a0323f5ed08f/human_audio/15900282168_in_7_20180106131835.wav", "mark": "insert"}'


2018-01-06 13:19:37,409 - LogUtils.py[line:112] - INFO: postgresql connect host .....   118.190.166.165
2018-01-06 13:19:37,475 - LogUtils.py[line:120] - ERROR: runsql exception error insert or update on table "fs_call_replay" violates foreign key constraint "fs_call_replay_call_id_a2c15655_fk_fs_call_id"
DETAIL:  Key (call_id)=(16) is not present in table "fs_call".
 
2018-01-06 13:19:37,475 - LogUtils.py[line:112] - INFO: ******** run_insert_sql..*********...INSERT INTO fs_call_replay(who, text, record_fpath, create_at, call_id,resp_param)VALUES ('human', '好的好的', '/8a9fc0df0e56058d56e8a0323f5ed08f/human_audio/15900282168_in_7_20180106131835.wav', '2018-01-06 13:19:34', '16','{"result": "\u597d\u7684\u597d\u7684", "ret": 0}') RETURNING id
2018-01-06 13:19:41,777 - LogUtils.py[line:112] - INFO:  [x] Received '{"jsonStr": "{\\"info\\": [{\\"is_flow_output\\": true, \\"output\\": \\"\\\\u90a3\\\\u597d\\\\uff0c\\\\u7a0d\\\\u540e\\\\u4f1a\\\\u6709\\\\u5de5\\\\u4f5c\\\\u4eba\\\\u5458\\\\u4e0e\\\\u60a8\\\\u8054\\\\u7cfb\\\\uff0c\\\\u795d\\\\u60a8\\\\u751f\\\\u6d3b\\\\u6109\\\\u5feb\\\\uff0c\\\\u518d\\\\u89c1\\\\u3002\\", \\"node_text\\": \\"\\\\u7ed3\\\\u675f\\\\u8bed4\\", \\"flow_id\\": \\"bfbbb0cfab4aac3dba462ac2d805fca1\\", \\"label\\": \\"\\\\u7ed3\\\\u675f\\\\u8bed4\\", \\"session_end\\": false, \\"state\\": \\"\\", \\"node_id\\": -7, \\"output_resource\\": \\"13.wav\\", \\"flow_end\\": true, \\"input\\": \\"\\\\u597d\\\\u7684\\\\u597d\\\\u7684\\", \\"similarity\\": 0.8, \\"flow_title\\": \\"\\\\u9080\\\\u7ea6\\", \\"output_type\\": \\"path\\", \\"user_label\\": \\"\\\\u4e2a\\\\u4eba\\\\u62b5\\\\u62bc\\\\u8d37\\\\u6b3e\\", \\"id\\": \\"bfbbb0cfab4aac3dba462ac2d805fca1_-7\\"}], \\"successful\\": true, \\"message\\": \\"ok\\"}", "text": "\\u90a3\\u597d\\uff0c\\u7a0d\\u540e\\u4f1a\\u6709\\u5de5\\u4f5c\\u4eba\\u5458\\u4e0e\\u60a8\\u8054\\u7cfb\\uff0c\\u795d\\u60a8\\u751f\\u6d3b\\u6109\\u5feb\\uff0c\\u518d\\u89c1\\u3002", "who": "bot", "create_at": "2018-01-06 13:19:37", "call_id": "16", "record_fpath": "/8a9fc0df0e56058d56e8a0323f5ed08f/bot_audio/13.wav", "mark": "insert"}'


2018-01-06 13:19:41,777 - LogUtils.py[line:112] - INFO: postgresql connect host .....   118.190.166.165
2018-01-06 13:19:41,822 - LogUtils.py[line:120] - ERROR: runsql exception error insert or update on table "fs_call_replay" violates foreign key constraint "fs_call_replay_call_id_a2c15655_fk_fs_call_id"
DETAIL:  Key (call_id)=(16) is not present in table "fs_call".
 
2018-01-06 13:19:41,822 - LogUtils.py[line:112] - INFO: ******** run_insert_sql..*********...INSERT INTO fs_call_replay(who, text, record_fpath, create_at, call_id,resp_param)VALUES ('bot', '那好，稍后会有工作人员与您联系，祝您生活愉快，再见。', '/8a9fc0df0e56058d56e8a0323f5ed08f/bot_audio/13.wav', '2018-01-06 13:19:37', '16','{"info": [{"is_flow_output": true, "output": "\u90a3\u597d\uff0c\u7a0d\u540e\u4f1a\u6709\u5de5\u4f5c\u4eba\u5458\u4e0e\u60a8\u8054\u7cfb\uff0c\u795d\u60a8\u751f\u6d3b\u6109\u5feb\uff0c\u518d\u89c1\u3002", "node_text": "\u7ed3\u675f\u8bed4", "flow_id": "bfbbb0cfab4aac3dba462ac2d805fca1", "label": "\u7ed3\u675f\u8bed4", "session_end": false, "state": "", "node_id": -7, "output_resource": "13.wav", "flow_end": true, "input": "\u597d\u7684\u597d\u7684", "similarity": 0.8, "flow_title": "\u9080\u7ea6", "output_type": "path", "user_label": "\u4e2a\u4eba\u62b5\u62bc\u8d37\u6b3e", "id": "bfbbb0cfab4aac3dba462ac2d805fca1_-7"}], "successful": true, "message": "ok"}') RETURNING id
2018-01-06 13:20:09,606 - LogUtils.py[line:112] - INFO:  [x] Received '{"record_fpath": "/8a9fc0df0e56058d56e8a0323f5ed08f/all_audio/13662106371_full_20180106132009_.wav", "channal_uuid": "d904fe8a-39d3-4955-962f-f4bb9da5f22d", "mark": "update"}'


2018-01-06 13:20:09,607 - LogUtils.py[line:112] - INFO: postgresql connect host .....   118.190.166.165
2018-01-06 13:20:09,670 - LogUtils.py[line:112] - INFO: postgresql connect.....closed!!!
2018-01-06 13:20:09,670 - LogUtils.py[line:112] - INFO: run_update_sql.....update fs_call set full_record_fpath ='/8a9fc0df0e56058d56e8a0323f5ed08f/all_audio/13662106371_full_20180106132009_.wav' where channal_uuid ='d904fe8a-39d3-4955-962f-f4bb9da5f22d'
2018-01-06 13:20:10,531 - LogUtils.py[line:112] - INFO:  [x] Received '{"jsonStr": "{\\"info\\": [{\\"is_flow_output\\": true, \\"output\\": \\"\\\\u5582\\\\uff0c\\\\u60a8\\\\u597d\\\\u3002\\", \\"node_text\\": \\"\\\\u95ee\\\\u5019\\\\u8bed\\", \\"flow_id\\": \\"505c426d2b8fbe8f8f5f18250c2f568f\\", \\"label\\": \\"\\", \\"session_end\\": false, \\"state\\": \\"\\", \\"node_id\\": -11, \\"output_resource\\": \\"t13.wav\\", \\"flow_end\\": false, \\"input\\": \\"\\\\u4f60\\\\u597d\\", \\"similarity\\": 1, \\"flow_title\\": \\"\\\\u5f00\\\\u573a\\\\u767d\\", \\"output_type\\": \\"path\\", \\"user_label\\": \\"\\\\u672a\\\\u77e5\\", \\"id\\": \\"505c426d2b8fbe8f8f5f18250c2f568f_-11\\"}], \\"successful\\": true, \\"message\\": \\"ok\\"}", "text": "\\u5582\\uff0c\\u60a8\\u597d\\u3002", "who": "bot", "create_at": "2018-01-06 13:20:09", "call_id": "17", "record_fpath": "/8a9fc0df0e56058d56e8a0323f5ed08f/bot_audio/t13.wav", "mark": "insert"}'


2018-01-06 13:20:10,531 - LogUtils.py[line:112] - INFO: postgresql connect host .....   118.190.166.165
2018-01-06 13:20:10,574 - LogUtils.py[line:120] - ERROR: runsql exception error insert or update on table "fs_call_replay" violates foreign key constraint "fs_call_replay_call_id_a2c15655_fk_fs_call_id"
DETAIL:  Key (call_id)=(17) is not present in table "fs_call".
 
2018-01-06 13:20:10,574 - LogUtils.py[line:112] - INFO: ******** run_insert_sql..*********...INSERT INTO fs_call_replay(who, text, record_fpath, create_at, call_id,resp_param)VALUES ('bot', '喂，您好。', '/8a9fc0df0e56058d56e8a0323f5ed08f/bot_audio/t13.wav', '2018-01-06 13:20:09', '17','{"info": [{"is_flow_output": true, "output": "\u5582\uff0c\u60a8\u597d\u3002", "node_text": "\u95ee\u5019\u8bed", "flow_id": "505c426d2b8fbe8f8f5f18250c2f568f", "label": "", "session_end": false, "state": "", "node_id": -11, "output_resource": "t13.wav", "flow_end": false, "input": "\u4f60\u597d", "similarity": 1, "flow_title": "\u5f00\u573a\u767d", "output_type": "path", "user_label": "\u672a\u77e5", "id": "505c426d2b8fbe8f8f5f18250c2f568f_-11"}], "successful": true, "message": "ok"}') RETURNING id
2018-01-06 13:20:12,441 - LogUtils.py[line:112] - INFO:  [x] Received '{"user_label": "\\u672a\\u77e5", "channal_uuid": "28d3a2e7-7891-42c3-9172-49e66dd55827", "mark": "user_label"}'


2018-01-06 13:20:12,442 - LogUtils.py[line:112] - INFO: postgresql connect host .....   118.190.166.165
2018-01-06 13:20:12,507 - LogUtils.py[line:112] - INFO: postgresql connect.....closed!!!
2018-01-06 13:20:12,507 - LogUtils.py[line:112] - INFO:  run_update_sql.........user_label... update fs_call set cust_tag = '未知' where channal_uuid ='28d3a2e7-7891-42c3-9172-49e66dd55827' 
2018-01-06 13:20:15,710 - LogUtils.py[line:112] - INFO:  [x] Received '{"jsonStr": "{\\"result\\": \\"\\\\u5582\\\\u4f60\\\\u597d\\", \\"ret\\": 0}", "text": "\\u5582\\u4f60\\u597d", "who": "human", "create_at": "2018-01-06 13:20:13", "call_id": "20", "record_fpath": "/8a9fc0df0e56058d56e8a0323f5ed08f/human_audio/13512239772_in_0_20180106132012.wav", "mark": "insert"}'


2018-01-06 13:20:15,710 - LogUtils.py[line:112] - INFO: postgresql connect host .....   118.190.166.165
2018-01-06 13:20:15,754 - LogUtils.py[line:120] - ERROR: runsql exception error insert or update on table "fs_call_replay" violates foreign key constraint "fs_call_replay_call_id_a2c15655_fk_fs_call_id"
DETAIL:  Key (call_id)=(20) is not present in table "fs_call".
 
2018-01-06 13:20:15,754 - LogUtils.py[line:112] - INFO: ******** run_insert_sql..*********...INSERT INTO fs_call_replay(who, text, record_fpath, create_at, call_id,resp_param)VALUES ('human', '喂你好', '/8a9fc0df0e56058d56e8a0323f5ed08f/human_audio/13512239772_in_0_20180106132012.wav', '2018-01-06 13:20:13', '20','{"result": "\u5582\u4f60\u597d", "ret": 0}') RETURNING id
2018-01-06 13:20:16,279 - LogUtils.py[line:112] - INFO:  [x] Received '{"jsonStr": "{\\"result\\": \\"\\\\u4f60\\\\u597d\\", \\"ret\\": 0}", "text": "\\u4f60\\u597d", "who": "human", "create_at": "2018-01-06 13:20:10", "call_id": "17", "record_fpath": "/8a9fc0df0e56058d56e8a0323f5ed08f/human_audio/13662106371_in_0_20180106132009.wav", "mark": "insert"}'


2018-01-06 13:20:16,279 - LogUtils.py[line:112] - INFO: postgresql connect host .....   118.190.166.165
2018-01-06 13:20:16,345 - LogUtils.py[line:120] - ERROR: runsql exception error insert or update on table "fs_call_replay" violates foreign key constraint "fs_call_replay_call_id_a2c15655_fk_fs_call_id"
DETAIL:  Key (call_id)=(17) is not present in table "fs_call".
 
2018-01-06 13:20:16,346 - LogUtils.py[line:112] - INFO: ******** run_insert_sql..*********...INSERT INTO fs_call_replay(who, text, record_fpath, create_at, call_id,resp_param)VALUES ('human', '你好', '/8a9fc0df0e56058d56e8a0323f5ed08f/human_audio/13662106371_in_0_20180106132009.wav', '2018-01-06 13:20:10', '17','{"result": "\u4f60\u597d", "ret": 0}') RETURNING id
2018-01-06 13:20:19,763 - LogUtils.py[line:112] - INFO:  [x] Received '{"jsonStr": "{\\"info\\": [{\\"is_flow_output\\": true, \\"output\\": \\"\\\\u60a8\\\\u597d\\\\uff0c\\\\u6211\\\\u4eec\\\\u662f\\\\u529e\\\\u7406\\\\u8d37\\\\u6b3e\\\\u7684\\\\uff0c\\\\u8bf7\\\\u95ee\\\\u60a8\\\\u6709\\\\u8d44\\\\u91d1\\\\u4e0a\\\\u7684\\\\u9700\\\\u6c42\\\\u5417\\\\uff1f\\", \\"node_text\\": \\"\\\\u8bed\\\\u6599\\\\u8282\\\\u70b9\\", \\"flow_id\\": \\"505c426d2b8fbe8f8f5f18250c2f568f\\", \\"label\\": \\"\\\\u5f00\\\\u573a\\\\u767d\\", \\"session_end\\": false, \\"state\\": \\"\\", \\"node_id\\": -3, \\"output_resource\\": \\"7.wav\\", \\"flow_end\\": false, \\"input\\": \\"\\\\u5582\\\\u4f60\\\\u597d\\", \\"similarity\\": 1, \\"flow_title\\": \\"\\\\u5f00\\\\u573a\\\\u767d\\", \\"output_type\\": \\"path\\", \\"user_label\\": \\"\\\\u5f00\\\\u573a\\\\u6302\\\\u65ad\\", \\"id\\": \\"505c426d2b8fbe8f8f5f18250c2f568f_-3\\"}], \\"successful\\": true, \\"message\\": \\"ok\\"}", "text": "\\u60a8\\u597d\\uff0c\\u6211\\u4eec\\u662f\\u529e\\u7406\\u8d37\\u6b3e\\u7684\\uff0c\\u8bf7\\u95ee\\u60a8\\u6709\\u8d44\\u91d1\\u4e0a\\u7684\\u9700\\u6c42\\u5417\\uff1f", "who": "bot", "create_at": "2018-01-06 13:20:15", "call_id": "20", "record_fpath": "/8a9fc0df0e56058d56e8a0323f5ed08f/bot_audio/7.wav", "mark": "insert"}'


2018-01-06 13:20:19,764 - LogUtils.py[line:112] - INFO: postgresql connect host .....   118.190.166.165
2018-01-06 13:20:19,807 - LogUtils.py[line:120] - ERROR: runsql exception error insert or update on table "fs_call_replay" violates foreign key constraint "fs_call_replay_call_id_a2c15655_fk_fs_call_id"
DETAIL:  Key (call_id)=(20) is not present in table "fs_call".
 
2018-01-06 13:20:19,807 - LogUtils.py[line:112] - INFO: ******** run_insert_sql..*********...INSERT INTO fs_call_replay(who, text, record_fpath, create_at, call_id,resp_param)VALUES ('bot', '您好，我们是办理贷款的，请问您有资金上的需求吗？', '/8a9fc0df0e56058d56e8a0323f5ed08f/bot_audio/7.wav', '2018-01-06 13:20:15', '20','{"info": [{"is_flow_output": true, "output": "\u60a8\u597d\uff0c\u6211\u4eec\u662f\u529e\u7406\u8d37\u6b3e\u7684\uff0c\u8bf7\u95ee\u60a8\u6709\u8d44\u91d1\u4e0a\u7684\u9700\u6c42\u5417\uff1f", "node_text": "\u8bed\u6599\u8282\u70b9", "flow_id": "505c426d2b8fbe8f8f5f18250c2f568f", "label": "\u5f00\u573a\u767d", "session_end": false, "state": "", "node_id": -3, "output_resource": "7.wav", "flow_end": false, "input": "\u5582\u4f60\u597d", "similarity": 1, "flow_title": "\u5f00\u573a\u767d", "output_type": "path", "user_label": "\u5f00\u573a\u6302\u65ad", "id": "505c426d2b8fbe8f8f5f18250c2f568f_-3"}], "successful": true, "message": "ok"}') RETURNING id
2018-01-06 13:20:25,738 - LogUtils.py[line:112] - INFO:  [x] Received '{"jsonStr": "{\\"result\\": \\"\\\\u5c31\\\\u4ec0\\\\u4e48\\\\u94f6\\\\u884c\\\\u7684\\", \\"ret\\": 0}", "text": "\\u5c31\\u4ec0\\u4e48\\u94f6\\u884c\\u7684", "who": "human", "create_at": "2018-01-06 13:20:19", "call_id": "20", "record_fpath": "/8a9fc0df0e56058d56e8a0323f5ed08f/human_audio/13512239772_in_1_20180106132012.wav", "mark": "insert"}'


2018-01-06 13:20:25,739 - LogUtils.py[line:112] - INFO: postgresql connect host .....   118.190.166.165
2018-01-06 13:20:25,805 - LogUtils.py[line:120] - ERROR: runsql exception error insert or update on table "fs_call_replay" violates foreign key constraint "fs_call_replay_call_id_a2c15655_fk_fs_call_id"
DETAIL:  Key (call_id)=(20) is not present in table "fs_call".
 
2018-01-06 13:20:25,805 - LogUtils.py[line:112] - INFO: ******** run_insert_sql..*********...INSERT INTO fs_call_replay(who, text, record_fpath, create_at, call_id,resp_param)VALUES ('human', '就什么银行的', '/8a9fc0df0e56058d56e8a0323f5ed08f/human_audio/13512239772_in_1_20180106132012.wav', '2018-01-06 13:20:19', '20','{"result": "\u5c31\u4ec0\u4e48\u94f6\u884c\u7684", "ret": 0}') RETURNING id
2018-01-06 13:20:25,846 - LogUtils.py[line:112] - INFO:  [x] Received '{"user_label": "\\u672a\\u77e5", "channal_uuid": "28d3a2e7-7891-42c3-9172-49e66dd55827", "mark": "user_label"}'


2018-01-06 13:20:25,847 - LogUtils.py[line:112] - INFO: postgresql connect host .....   118.190.166.165
2018-01-06 13:20:25,890 - LogUtils.py[line:112] - INFO: postgresql connect.....closed!!!
2018-01-06 13:20:25,890 - LogUtils.py[line:112] - INFO:  run_update_sql.........user_label... update fs_call set cust_tag = '未知' where channal_uuid ='28d3a2e7-7891-42c3-9172-49e66dd55827' 
2018-01-06 13:20:30,671 - LogUtils.py[line:112] - INFO:  [x] Received '{"jsonStr": "{\\"info\\": [{\\"is_flow_output\\": false, \\"output\\": \\"\\\\u60a8\\\\u542c\\\\u51fa\\\\u6765\\\\u4e86\\\\u554a\\\\uff1f\\\\u6211\\\\u662f\\\\u4e0d\\\\u662f\\\\u5f88\\\\u53ef\\\\u7231\\\\u554a\\\\u54c8\\\\u54c8\\", \\"node_text\\": \\"\\\\u8bed\\\\u6599\\\\u8282\\\\u70b9\\", \\"flow_id\\": \\"505c426d2b8fbe8f8f5f18250c2f568f\\", \\"label\\": \\"\\\\u5f00\\\\u573a\\\\u767d\\", \\"session_end\\": false, \\"state\\": \\"\\", \\"node_id\\": -3, \\"output_resource\\": \\"t56.wav\\", \\"flow_end\\": false, \\"input\\": \\"\\\\u4f60\\\\u662f\\\\u673a\\\\u5668\\\\u4eba\\\\u5417\\", \\"similarity\\": 0.0, \\"flow_title\\": \\"\\\\u5f00\\\\u573a\\\\u767d\\", \\"output_type\\": \\"path\\", \\"user_label\\": \\"\\\\u672a\\\\u77e5\\", \\"id\\": \\"505c426d2b8fbe8f8f5f18250c2f568f_-3\\"}], \\"successful\\": true, \\"message\\": \\"ok\\"}", "text": "\\u60a8\\u542c\\u51fa\\u6765\\u4e86\\u554a\\uff1f\\u6211\\u662f\\u4e0d\\u662f\\u5f88\\u53ef\\u7231\\u554a\\u54c8\\u54c8", "who": "bot", "create_at": "2018-01-06 13:20:25", "call_id": "17", "record_fpath": "/8a9fc0df0e56058d56e8a0323f5ed08f/bot_audio/t56.wav", "mark": "insert"}'


2018-01-06 13:20:30,672 - LogUtils.py[line:112] - INFO: postgresql connect host .....   118.190.166.165
2018-01-06 13:20:30,738 - LogUtils.py[line:120] - ERROR: runsql exception error insert or update on table "fs_call_replay" violates foreign key constraint "fs_call_replay_call_id_a2c15655_fk_fs_call_id"
DETAIL:  Key (call_id)=(17) is not present in table "fs_call".
 
2018-01-06 13:20:30,739 - LogUtils.py[line:112] - INFO: ******** run_insert_sql..*********...INSERT INTO fs_call_replay(who, text, record_fpath, create_at, call_id,resp_param)VALUES ('bot', '您听出来了啊？我是不是很可爱啊哈哈', '/8a9fc0df0e56058d56e8a0323f5ed08f/bot_audio/t56.wav', '2018-01-06 13:20:25', '17','{"info": [{"is_flow_output": false, "output": "\u60a8\u542c\u51fa\u6765\u4e86\u554a\uff1f\u6211\u662f\u4e0d\u662f\u5f88\u53ef\u7231\u554a\u54c8\u54c8", "node_text": "\u8bed\u6599\u8282\u70b9", "flow_id": "505c426d2b8fbe8f8f5f18250c2f568f", "label": "\u5f00\u573a\u767d", "session_end": false, "state": "", "node_id": -3, "output_resource": "t56.wav", "flow_end": false, "input": "\u4f60\u662f\u673a\u5668\u4eba\u5417", "similarity": 0.0, "flow_title": "\u5f00\u573a\u767d", "output_type": "path", "user_label": "\u672a\u77e5", "id": "505c426d2b8fbe8f8f5f18250c2f568f_-3"}], "successful": true, "message": "ok"}') RETURNING id
2018-01-06 13:20:32,571 - LogUtils.py[line:112] - INFO:  [x] Received '{"jsonStr": "{\\"result\\": \\"\\\\u591f\\\\u4e0d\\\\u591f\\", \\"ret\\": 0}", "text": "\\u591f\\u4e0d\\u591f", "who": "human", "create_at": "2018-01-06 13:20:30", "call_id": "17", "record_fpath": "/8a9fc0df0e56058d56e8a0323f5ed08f/human_audio/13662106371_in_2_20180106132009.wav", "mark": "insert"}'


2018-01-06 13:20:32,571 - LogUtils.py[line:112] - INFO: postgresql connect host .....   118.190.166.165
2018-01-06 13:20:32,615 - LogUtils.py[line:120] - ERROR: runsql exception error insert or update on table "fs_call_replay" violates foreign key constraint "fs_call_replay_call_id_a2c15655_fk_fs_call_id"
DETAIL:  Key (call_id)=(17) is not present in table "fs_call".
 
2018-01-06 13:20:32,615 - LogUtils.py[line:112] - INFO: ******** run_insert_sql..*********...INSERT INTO fs_call_replay(who, text, record_fpath, create_at, call_id,resp_param)VALUES ('human', '够不够', '/8a9fc0df0e56058d56e8a0323f5ed08f/human_audio/13662106371_in_2_20180106132009.wav', '2018-01-06 13:20:30', '17','{"result": "\u591f\u4e0d\u591f", "ret": 0}') RETURNING id
2018-01-06 13:20:34,277 - LogUtils.py[line:112] - INFO:  [x] Received '{"user_label": "\\u5f00\\u573a\\u6302\\u65ad", "channal_uuid": "d904fe8a-39d3-4955-962f-f4bb9da5f22d", "mark": "user_label"}'


2018-01-06 13:20:34,277 - LogUtils.py[line:112] - INFO: postgresql connect host .....   118.190.166.165
2018-01-06 13:20:34,343 - LogUtils.py[line:112] - INFO: postgresql connect.....closed!!!
2018-01-06 13:20:34,343 - LogUtils.py[line:112] - INFO:  run_update_sql.........user_label... update fs_call set cust_tag = '开场挂断' where channal_uuid ='d904fe8a-39d3-4955-962f-f4bb9da5f22d' 
2018-01-06 13:20:38,457 - LogUtils.py[line:112] - INFO:  [x] Received '{"jsonStr": "{\\"result\\": \\"\\\\u4f60\\\\u600e\\\\u4e48\\\\u77e5\\\\u9053\\\\u624b\\\\u673a\\\\u53f7\\\\u7801\\", \\"ret\\": 0}", "text": "\\u4f60\\u600e\\u4e48\\u77e5\\u9053\\u624b\\u673a\\u53f7\\u7801", "who": "human", "create_at": "2018-01-06 13:20:33", "call_id": "20", "record_fpath": "/8a9fc0df0e56058d56e8a0323f5ed08f/human_audio/13512239772_in_2_20180106132012.wav", "mark": "insert"}'


2018-01-06 13:20:38,457 - LogUtils.py[line:112] - INFO: postgresql connect host .....   118.190.166.165
2018-01-06 13:20:38,500 - LogUtils.py[line:120] - ERROR: runsql exception error insert or update on table "fs_call_replay" violates foreign key constraint "fs_call_replay_call_id_a2c15655_fk_fs_call_id"
DETAIL:  Key (call_id)=(20) is not present in table "fs_call".
 
2018-01-06 13:20:38,501 - LogUtils.py[line:112] - INFO: ******** run_insert_sql..*********...INSERT INTO fs_call_replay(who, text, record_fpath, create_at, call_id,resp_param)VALUES ('human', '你怎么知道手机号码', '/8a9fc0df0e56058d56e8a0323f5ed08f/human_audio/13512239772_in_2_20180106132012.wav', '2018-01-06 13:20:33', '20','{"result": "\u4f60\u600e\u4e48\u77e5\u9053\u624b\u673a\u53f7\u7801", "ret": 0}') RETURNING id
2018-01-06 13:20:40,642 - LogUtils.py[line:112] - INFO:  [x] Received '{"jsonStr": "{\\"info\\": [{\\"is_flow_output\\": false, \\"output\\": \\"\\\\u8fd9\\\\u4e2a\\\\u6211\\\\u4eec\\\\u90fd\\\\u662f\\\\u7535\\\\u8111\\\\u968f\\\\u673a\\\\u62e8\\\\u53f7\\", \\"node_text\\": \\"\\\\u8bed\\\\u6599\\\\u8282\\\\u70b9\\", \\"flow_id\\": \\"505c426d2b8fbe8f8f5f18250c2f568f\\", \\"label\\": \\"\\\\u5f00\\\\u573a\\\\u767d\\", \\"session_end\\": false, \\"state\\": \\"\\", \\"node_id\\": -3, \\"output_resource\\": \\"32.wav\\", \\"flow_end\\": false, \\"input\\": \\"\\\\u4f60\\\\u600e\\\\u4e48\\\\u77e5\\\\u9053\\\\u624b\\\\u673a\\\\u53f7\\\\u7801\\", \\"similarity\\": 0.7615416646003723, \\"flow_title\\": \\"\\\\u5f00\\\\u573a\\\\u767d\\", \\"output_type\\": \\"path\\", \\"user_label\\": \\"\\\\u672a\\\\u77e5\\", \\"id\\": \\"505c426d2b8fbe8f8f5f18250c2f568f_-3\\"}], \\"successful\\": true, \\"message\\": \\"ok\\"}", "text": "\\u8fd9\\u4e2a\\u6211\\u4eec\\u90fd\\u662f\\u7535\\u8111\\u968f\\u673a\\u62e8\\u53f7", "who": "bot", "create_at": "2018-01-06 13:20:38", "call_id": "20", "record_fpath": "/8a9fc0df0e56058d56e8a0323f5ed08f/bot_audio/32.wav", "mark": "insert"}'


2018-01-06 13:20:40,642 - LogUtils.py[line:112] - INFO: postgresql connect host .....   118.190.166.165
2018-01-06 13:20:40,709 - LogUtils.py[line:120] - ERROR: runsql exception error insert or update on table "fs_call_replay" violates foreign key constraint "fs_call_replay_call_id_a2c15655_fk_fs_call_id"
DETAIL:  Key (call_id)=(20) is not present in table "fs_call".
 
2018-01-06 13:20:40,709 - LogUtils.py[line:112] - INFO: ******** run_insert_sql..*********...INSERT INTO fs_call_replay(who, text, record_fpath, create_at, call_id,resp_param)VALUES ('bot', '这个我们都是电脑随机拨号', '/8a9fc0df0e56058d56e8a0323f5ed08f/bot_audio/32.wav', '2018-01-06 13:20:38', '20','{"info": [{"is_flow_output": false, "output": "\u8fd9\u4e2a\u6211\u4eec\u90fd\u662f\u7535\u8111\u968f\u673a\u62e8\u53f7", "node_text": "\u8bed\u6599\u8282\u70b9", "flow_id": "505c426d2b8fbe8f8f5f18250c2f568f", "label": "\u5f00\u573a\u767d", "session_end": false, "state": "", "node_id": -3, "output_resource": "32.wav", "flow_end": false, "input": "\u4f60\u600e\u4e48\u77e5\u9053\u624b\u673a\u53f7\u7801", "similarity": 0.7615416646003723, "flow_title": "\u5f00\u573a\u767d", "output_type": "path", "user_label": "\u672a\u77e5", "id": "505c426d2b8fbe8f8f5f18250c2f568f_-3"}], "successful": true, "message": "ok"}') RETURNING id
2018-01-06 13:20:43,801 - LogUtils.py[line:112] - INFO:  [x] Received '{"user_label": "\\u5f00\\u573a\\u6302\\u65ad", "channal_uuid": "28d3a2e7-7891-42c3-9172-49e66dd55827", "mark": "user_label"}'


2018-01-06 13:20:43,802 - LogUtils.py[line:112] - INFO: postgresql connect host .....   118.190.166.165
2018-01-06 13:20:43,845 - LogUtils.py[line:112] - INFO: postgresql connect.....closed!!!
2018-01-06 13:20:43,845 - LogUtils.py[line:112] - INFO:  run_update_sql.........user_label... update fs_call set cust_tag = '开场挂断' where channal_uuid ='28d3a2e7-7891-42c3-9172-49e66dd55827' 
2018-01-06 13:20:49,137 - LogUtils.py[line:112] - INFO:  [x] Received '{"record_fpath": "/8a9fc0df0e56058d56e8a0323f5ed08f/all_audio/18522611368_full_20180106132049_.wav", "channal_uuid": "09aad566-a233-4275-9f91-c1a828a99b10", "mark": "update"}'


2018-01-06 13:20:49,137 - LogUtils.py[line:112] - INFO: postgresql connect host .....   118.190.166.165
2018-01-06 13:20:49,202 - LogUtils.py[line:112] - INFO: postgresql connect.....closed!!!
2018-01-06 13:20:49,203 - LogUtils.py[line:112] - INFO: run_update_sql.....update fs_call set full_record_fpath ='/8a9fc0df0e56058d56e8a0323f5ed08f/all_audio/18522611368_full_20180106132049_.wav' where channal_uuid ='09aad566-a233-4275-9f91-c1a828a99b10'
2018-01-06 13:20:50,073 - LogUtils.py[line:112] - INFO:  [x] Received '{"jsonStr": "{\\"info\\": [{\\"is_flow_output\\": true, \\"output\\": \\"\\\\u5582\\\\uff0c\\\\u60a8\\\\u597d\\\\u3002\\", \\"node_text\\": \\"\\\\u95ee\\\\u5019\\\\u8bed\\", \\"flow_id\\": \\"505c426d2b8fbe8f8f5f18250c2f568f\\", \\"label\\": \\"\\", \\"session_end\\": false, \\"state\\": \\"\\", \\"node_id\\": -11, \\"output_resource\\": \\"t13.wav\\", \\"flow_end\\": false, \\"input\\": \\"\\\\u4f60\\\\u597d\\", \\"similarity\\": 1, \\"flow_title\\": \\"\\\\u5f00\\\\u573a\\\\u767d\\", \\"output_type\\": \\"path\\", \\"user_label\\": \\"\\\\u672a\\\\u77e5\\", \\"id\\": \\"505c426d2b8fbe8f8f5f18250c2f568f_-11\\"}], \\"successful\\": true, \\"message\\": \\"ok\\"}", "text": "\\u5582\\uff0c\\u60a8\\u597d\\u3002", "who": "bot", "create_at": "2018-01-06 13:20:49", "call_id": "18", "record_fpath": "/8a9fc0df0e56058d56e8a0323f5ed08f/bot_audio/t13.wav", "mark": "insert"}'


2018-01-06 13:20:50,074 - LogUtils.py[line:112] - INFO: postgresql connect host .....   118.190.166.165
2018-01-06 13:20:50,117 - LogUtils.py[line:120] - ERROR: runsql exception error insert or update on table "fs_call_replay" violates foreign key constraint "fs_call_replay_call_id_a2c15655_fk_fs_call_id"
DETAIL:  Key (call_id)=(18) is not present in table "fs_call".
 
2018-01-06 13:20:50,118 - LogUtils.py[line:112] - INFO: ******** run_insert_sql..*********...INSERT INTO fs_call_replay(who, text, record_fpath, create_at, call_id,resp_param)VALUES ('bot', '喂，您好。', '/8a9fc0df0e56058d56e8a0323f5ed08f/bot_audio/t13.wav', '2018-01-06 13:20:49', '18','{"info": [{"is_flow_output": true, "output": "\u5582\uff0c\u60a8\u597d\u3002", "node_text": "\u95ee\u5019\u8bed", "flow_id": "505c426d2b8fbe8f8f5f18250c2f568f", "label": "", "session_end": false, "state": "", "node_id": -11, "output_resource": "t13.wav", "flow_end": false, "input": "\u4f60\u597d", "similarity": 1, "flow_title": "\u5f00\u573a\u767d", "output_type": "path", "user_label": "\u672a\u77e5", "id": "505c426d2b8fbe8f8f5f18250c2f568f_-11"}], "successful": true, "message": "ok"}') RETURNING id
2018-01-06 13:20:52,565 - LogUtils.py[line:112] - INFO:  [x] Received '{"user_label": "\\u5f00\\u573a\\u6302\\u65ad", "channal_uuid": "28d3a2e7-7891-42c3-9172-49e66dd55827", "mark": "user_label"}'


2018-01-06 13:20:52,566 - LogUtils.py[line:112] - INFO: postgresql connect host .....   118.190.166.165
2018-01-06 13:20:52,631 - LogUtils.py[line:112] - INFO: postgresql connect.....closed!!!
2018-01-06 13:20:52,631 - LogUtils.py[line:112] - INFO:  run_update_sql.........user_label... update fs_call set cust_tag = '开场挂断' where channal_uuid ='28d3a2e7-7891-42c3-9172-49e66dd55827' 
2018-01-06 13:20:52,748 - LogUtils.py[line:112] - INFO:  [x] Received '{"user_label": "\\u5f00\\u573a\\u6302\\u65ad", "channal_uuid": "09aad566-a233-4275-9f91-c1a828a99b10", "mark": "user_label"}'


2018-01-06 13:20:52,748 - LogUtils.py[line:112] - INFO: postgresql connect host .....   118.190.166.165
2018-01-06 13:20:52,817 - LogUtils.py[line:112] - INFO: postgresql connect.....closed!!!
2018-01-06 13:20:52,818 - LogUtils.py[line:112] - INFO:  run_update_sql.........user_label... update fs_call set cust_tag = '开场挂断' where channal_uuid ='09aad566-a233-4275-9f91-c1a828a99b10' 
2018-01-06 13:20:59,122 - LogUtils.py[line:112] - INFO:  [x] Received '{"jsonStr": "{\\"result\\": \\"\\\\u554a\\\\u6ca1\\\\u6709\\", \\"ret\\": 0}", "text": "\\u554a\\u6ca1\\u6709", "who": "human", "create_at": "2018-01-06 13:20:56", "call_id": "18", "record_fpath": "/8a9fc0df0e56058d56e8a0323f5ed08f/human_audio/18522611368_in_1_20180106132049.wav", "mark": "insert"}'


2018-01-06 13:20:59,123 - LogUtils.py[line:112] - INFO: postgresql connect host .....   118.190.166.165
2018-01-06 13:20:59,189 - LogUtils.py[line:120] - ERROR: runsql exception error insert or update on table "fs_call_replay" violates foreign key constraint "fs_call_replay_call_id_a2c15655_fk_fs_call_id"
DETAIL:  Key (call_id)=(18) is not present in table "fs_call".
 
2018-01-06 13:20:59,189 - LogUtils.py[line:112] - INFO: ******** run_insert_sql..*********...INSERT INTO fs_call_replay(who, text, record_fpath, create_at, call_id,resp_param)VALUES ('human', '啊没有', '/8a9fc0df0e56058d56e8a0323f5ed08f/human_audio/18522611368_in_1_20180106132049.wav', '2018-01-06 13:20:56', '18','{"result": "\u554a\u6ca1\u6709", "ret": 0}') RETURNING id
2018-01-06 13:21:00,886 - LogUtils.py[line:112] - INFO:  [x] Received '{"user_label": "\\u5f00\\u573a\\u6302\\u65ad", "channal_uuid": "09aad566-a233-4275-9f91-c1a828a99b10", "mark": "user_label"}'


2018-01-06 13:21:00,886 - LogUtils.py[line:112] - INFO: postgresql connect host .....   118.190.166.165
2018-01-06 13:21:00,930 - LogUtils.py[line:112] - INFO: postgresql connect.....closed!!!
2018-01-06 13:21:00,930 - LogUtils.py[line:112] - INFO:  run_update_sql.........user_label... update fs_call set cust_tag = '开场挂断' where channal_uuid ='09aad566-a233-4275-9f91-c1a828a99b10' 
2018-01-06 13:21:04,355 - LogUtils.py[line:112] - INFO:  [x] Received '{"user_label": "\\u5f00\\u573a\\u6302\\u65ad", "channal_uuid": "28d3a2e7-7891-42c3-9172-49e66dd55827", "mark": "user_label"}'


2018-01-06 13:21:04,356 - LogUtils.py[line:112] - INFO: postgresql connect host .....   118.190.166.165
2018-01-06 13:21:04,422 - LogUtils.py[line:112] - INFO: postgresql connect.....closed!!!
2018-01-06 13:21:04,423 - LogUtils.py[line:112] - INFO:  run_update_sql.........user_label... update fs_call set cust_tag = '开场挂断' where channal_uuid ='28d3a2e7-7891-42c3-9172-49e66dd55827' 
2018-01-06 13:21:08,574 - LogUtils.py[line:112] - INFO:  [x] Received '{"jsonStr": "{\\"info\\": [{\\"is_flow_output\\": true, \\"output\\": \\"\\\\u60a8\\\\u53ef\\\\u4ee5\\\\u7a0d\\\\u5fae\\\\u4e86\\\\u89e3\\\\u4e00\\\\u4e0b\\\\u5417\\\\uff0c\\\\u6211\\\\u4eec\\\\u8fd9\\\\u8fb9\\\\u90fd\\\\u662f\\\\u548c\\\\u94f6\\\\u884c\\\\u6b63\\\\u89c4\\\\u5408\\\\u4f5c\\\\u7684\\\\uff0c\\\\u653e\\\\u6b3e\\\\u5feb\\\\u5229\\\\u606f\\\\u4f4e\\\\uff0c\\\\u4fe1\\\\u7528\\\\u8d37\\\\u6b3e\\\\u6700\\\\u9ad8\\\\u53ef\\\\u4ee5\\\\u6279\\\\u5230200\\\\u4e07\\\\u7684\\\\u3002\\", \\"node_text\\": \\"\\\\u633d\\\\u56de\\", \\"flow_id\\": \\"dcb1952dac09ebf6996e56d050c9a7f5\\", \\"label\\": \\"\\\\u633d\\\\u56de\\", \\"session_end\\": false, \\"state\\": \\"\\", \\"node_id\\": -11, \\"output_resource\\": \\"8.wav\\", \\"flow_end\\": false, \\"input\\": \\"\\\\u554a\\\\u6ca1\\\\u6709\\", \\"similarity\\": 1, \\"flow_title\\": \\"\\\\u633d\\\\u56de\\", \\"output_type\\": \\"path\\", \\"user_label\\": \\"\\\\u5f00\\\\u573a\\\\u6302\\\\u65ad\\", \\"id\\": \\"dcb1952dac09ebf6996e56d050c9a7f5_-11\\"}], \\"successful\\": true, \\"message\\": \\"ok\\"}", "text": "\\u60a8\\u53ef\\u4ee5\\u7a0d\\u5fae\\u4e86\\u89e3\\u4e00\\u4e0b\\u5417\\uff0c\\u6211\\u4eec\\u8fd9\\u8fb9\\u90fd\\u662f\\u548c\\u94f6\\u884c\\u6b63\\u89c4\\u5408\\u4f5c\\u7684\\uff0c\\u653e\\u6b3e\\u5feb\\u5229\\u606f\\u4f4e\\uff0c\\u4fe1\\u7528\\u8d37\\u6b3e\\u6700\\u9ad8\\u53ef\\u4ee5\\u6279\\u5230200\\u4e07\\u7684\\u3002", "who": "bot", "create_at": "2018-01-06 13:20:59", "call_id": "18", "record_fpath": "/8a9fc0df0e56058d56e8a0323f5ed08f/bot_audio/8.wav", "mark": "insert"}'


2018-01-06 13:21:08,575 - LogUtils.py[line:112] - INFO: postgresql connect host .....   118.190.166.165
2018-01-06 13:21:08,619 - LogUtils.py[line:120] - ERROR: runsql exception error insert or update on table "fs_call_replay" violates foreign key constraint "fs_call_replay_call_id_a2c15655_fk_fs_call_id"
DETAIL:  Key (call_id)=(18) is not present in table "fs_call".
 
2018-01-06 13:21:08,619 - LogUtils.py[line:112] - INFO: ******** run_insert_sql..*********...INSERT INTO fs_call_replay(who, text, record_fpath, create_at, call_id,resp_param)VALUES ('bot', '您可以稍微了解一下吗，我们这边都是和银行正规合作的，放款快利息低，信用贷款最高可以批到200万的。', '/8a9fc0df0e56058d56e8a0323f5ed08f/bot_audio/8.wav', '2018-01-06 13:20:59', '18','{"info": [{"is_flow_output": true, "output": "\u60a8\u53ef\u4ee5\u7a0d\u5fae\u4e86\u89e3\u4e00\u4e0b\u5417\uff0c\u6211\u4eec\u8fd9\u8fb9\u90fd\u662f\u548c\u94f6\u884c\u6b63\u89c4\u5408\u4f5c\u7684\uff0c\u653e\u6b3e\u5feb\u5229\u606f\u4f4e\uff0c\u4fe1\u7528\u8d37\u6b3e\u6700\u9ad8\u53ef\u4ee5\u6279\u5230200\u4e07\u7684\u3002", "node_text": "\u633d\u56de", "flow_id": "dcb1952dac09ebf6996e56d050c9a7f5", "label": "\u633d\u56de", "session_end": false, "state": "", "node_id": -11, "output_resource": "8.wav", "flow_end": false, "input": "\u554a\u6ca1\u6709", "similarity": 1, "flow_title": "\u633d\u56de", "output_type": "path", "user_label": "\u5f00\u573a\u6302\u65ad", "id": "dcb1952dac09ebf6996e56d050c9a7f5_-11"}], "successful": true, "message": "ok"}') RETURNING id
2018-01-06 13:21:10,550 - LogUtils.py[line:112] - INFO:  [x] Received '{"user_label": "\\u5f00\\u573a\\u6302\\u65ad", "channal_uuid": "28d3a2e7-7891-42c3-9172-49e66dd55827", "mark": "user_label"}'


2018-01-06 13:21:10,550 - LogUtils.py[line:112] - INFO: postgresql connect host .....   118.190.166.165
2018-01-06 13:21:10,615 - LogUtils.py[line:112] - INFO: postgresql connect.....closed!!!
2018-01-06 13:21:10,616 - LogUtils.py[line:112] - INFO:  run_update_sql.........user_label... update fs_call set cust_tag = '开场挂断' where channal_uuid ='28d3a2e7-7891-42c3-9172-49e66dd55827' 
2018-01-06 13:21:12,923 - LogUtils.py[line:112] - INFO:  [x] Received '{"jsonStr": "{\\"info\\": [{\\"is_flow_output\\": true, \\"output\\": \\"\\\\u90a3\\\\u60a8\\\\u76ee\\\\u524d\\\\u662f\\\\u81ea\\\\u5df1\\\\u5f00\\\\u516c\\\\u53f8\\\\u8fd8\\\\u662f\\\\u4e0a\\\\u73ed\\\\u7684\\\\uff1f\\", \\"node_text\\": \\"\\\\u95ee\\\\u98981\\", \\"flow_id\\": \\"ba8d69e98f71243574ab338537a7a1bd\\", \\"label\\": \\"\\\\u95ee\\\\u98981\\", \\"session_end\\": false, \\"state\\": \\"\\", \\"node_id\\": -25, \\"output_resource\\": \\"t6.wav\\", \\"flow_end\\": false, \\"input\\": \\"\\\\u6ca1\\\\u6709\\", \\"similarity\\": 0.8, \\"flow_title\\": \\"\\\\u4e86\\\\u89e3\\\\u60c5\\\\u51b5\\", \\"output_type\\": \\"path\\", \\"user_label\\": \\"\\\\u5f00\\\\u573a\\\\u6302\\\\u65ad\\", \\"id\\": \\"ba8d69e98f71243574ab338537a7a1bd_-25\\"}], \\"successful\\": true, \\"message\\": \\"ok\\"}", "text": "\\u90a3\\u60a8\\u76ee\\u524d\\u662f\\u81ea\\u5df1\\u5f00\\u516c\\u53f8\\u8fd8\\u662f\\u4e0a\\u73ed\\u7684\\uff1f", "who": "bot", "create_at": "2018-01-06 13:21:08", "call_id": "20", "record_fpath": "/8a9fc0df0e56058d56e8a0323f5ed08f/bot_audio/t6.wav", "mark": "insert"}'


2018-01-06 13:21:12,923 - LogUtils.py[line:112] - INFO: postgresql connect host .....   118.190.166.165
2018-01-06 13:21:12,967 - LogUtils.py[line:120] - ERROR: runsql exception error insert or update on table "fs_call_replay" violates foreign key constraint "fs_call_replay_call_id_a2c15655_fk_fs_call_id"
DETAIL:  Key (call_id)=(20) is not present in table "fs_call".
 
2018-01-06 13:21:12,968 - LogUtils.py[line:112] - INFO: ******** run_insert_sql..*********...INSERT INTO fs_call_replay(who, text, record_fpath, create_at, call_id,resp_param)VALUES ('bot', '那您目前是自己开公司还是上班的？', '/8a9fc0df0e56058d56e8a0323f5ed08f/bot_audio/t6.wav', '2018-01-06 13:21:08', '20','{"info": [{"is_flow_output": true, "output": "\u90a3\u60a8\u76ee\u524d\u662f\u81ea\u5df1\u5f00\u516c\u53f8\u8fd8\u662f\u4e0a\u73ed\u7684\uff1f", "node_text": "\u95ee\u98981", "flow_id": "ba8d69e98f71243574ab338537a7a1bd", "label": "\u95ee\u98981", "session_end": false, "state": "", "node_id": -25, "output_resource": "t6.wav", "flow_end": false, "input": "\u6ca1\u6709", "similarity": 0.8, "flow_title": "\u4e86\u89e3\u60c5\u51b5", "output_type": "path", "user_label": "\u5f00\u573a\u6302\u65ad", "id": "ba8d69e98f71243574ab338537a7a1bd_-25"}], "successful": true, "message": "ok"}') RETURNING id
2018-01-06 13:21:14,293 - LogUtils.py[line:112] - INFO:  [x] Received '{"jsonStr": "{\\"info\\": [{\\"is_flow_output\\": false, \\"output\\": \\"\\\\u4e0d\\\\u5ba2\\\\u6c14\\", \\"node_text\\": \\"\\\\u633d\\\\u56de\\", \\"flow_id\\": \\"dcb1952dac09ebf6996e56d050c9a7f5\\", \\"label\\": \\"\\\\u633d\\\\u56de\\", \\"session_end\\": false, \\"state\\": \\"\\", \\"node_id\\": -11, \\"output_resource\\": \\"t50.wav\\", \\"flow_end\\": false, \\"input\\": \\"\\\\u554a\\\\u4e0d\\\\u7528\\\\u4e86\\\\u8c22\\\\u8c22\\\\u554a\\", \\"similarity\\": 0.0, \\"flow_title\\": \\"\\\\u633d\\\\u56de\\", \\"output_type\\": \\"path\\", \\"user_label\\": \\"\\\\u672a\\\\u77e5\\", \\"id\\": \\"dcb1952dac09ebf6996e56d050c9a7f5_-11\\"}], \\"successful\\": true, \\"message\\": \\"ok\\"}", "text": "\\u4e0d\\u5ba2\\u6c14", "who": "bot", "create_at": "2018-01-06 13:21:11", "call_id": "18", "record_fpath": "/8a9fc0df0e56058d56e8a0323f5ed08f/bot_audio/t50.wav", "mark": "insert"}'


2018-01-06 13:21:14,293 - LogUtils.py[line:112] - INFO: postgresql connect host .....   118.190.166.165
2018-01-06 13:21:14,359 - LogUtils.py[line:120] - ERROR: runsql exception error insert or update on table "fs_call_replay" violates foreign key constraint "fs_call_replay_call_id_a2c15655_fk_fs_call_id"
DETAIL:  Key (call_id)=(18) is not present in table "fs_call".
 
2018-01-06 13:21:14,360 - LogUtils.py[line:112] - INFO: ******** run_insert_sql..*********...INSERT INTO fs_call_replay(who, text, record_fpath, create_at, call_id,resp_param)VALUES ('bot', '不客气', '/8a9fc0df0e56058d56e8a0323f5ed08f/bot_audio/t50.wav', '2018-01-06 13:21:11', '18','{"info": [{"is_flow_output": false, "output": "\u4e0d\u5ba2\u6c14", "node_text": "\u633d\u56de", "flow_id": "dcb1952dac09ebf6996e56d050c9a7f5", "label": "\u633d\u56de", "session_end": false, "state": "", "node_id": -11, "output_resource": "t50.wav", "flow_end": false, "input": "\u554a\u4e0d\u7528\u4e86\u8c22\u8c22\u554a", "similarity": 0.0, "flow_title": "\u633d\u56de", "output_type": "path", "user_label": "\u672a\u77e5", "id": "dcb1952dac09ebf6996e56d050c9a7f5_-11"}], "successful": true, "message": "ok"}') RETURNING id
2018-01-06 13:21:17,773 - LogUtils.py[line:112] - INFO:  [x] Received '{"user_label": "\\u672a\\u77e5", "channal_uuid": "09aad566-a233-4275-9f91-c1a828a99b10", "mark": "user_label"}'


2018-01-06 13:21:17,773 - LogUtils.py[line:112] - INFO: postgresql connect host .....   118.190.166.165
2018-01-06 13:21:17,816 - LogUtils.py[line:112] - INFO: postgresql connect.....closed!!!
2018-01-06 13:21:17,817 - LogUtils.py[line:112] - INFO:  run_update_sql.........user_label... update fs_call set cust_tag = '未知' where channal_uuid ='09aad566-a233-4275-9f91-c1a828a99b10' 
2018-01-06 13:21:18,896 - LogUtils.py[line:112] - INFO:  [x] Received '{"jsonStr": "{\\"result\\": \\"\\\\u7ef5\\\\u9633\\\\u660e\\", \\"ret\\": 0}", "text": "\\u7ef5\\u9633\\u660e", "who": "human", "create_at": "2018-01-06 13:21:12", "call_id": "20", "record_fpath": "/8a9fc0df0e56058d56e8a0323f5ed08f/human_audio/13512239772_in_7_20180106132012.wav", "mark": "insert"}'


2018-01-06 13:21:18,896 - LogUtils.py[line:112] - INFO: postgresql connect host .....   118.190.166.165
2018-01-06 13:21:18,962 - LogUtils.py[line:120] - ERROR: runsql exception error insert or update on table "fs_call_replay" violates foreign key constraint "fs_call_replay_call_id_a2c15655_fk_fs_call_id"
DETAIL:  Key (call_id)=(20) is not present in table "fs_call".
 
2018-01-06 13:21:18,963 - LogUtils.py[line:112] - INFO: ******** run_insert_sql..*********...INSERT INTO fs_call_replay(who, text, record_fpath, create_at, call_id,resp_param)VALUES ('human', '绵阳明', '/8a9fc0df0e56058d56e8a0323f5ed08f/human_audio/13512239772_in_7_20180106132012.wav', '2018-01-06 13:21:12', '20','{"result": "\u7ef5\u9633\u660e", "ret": 0}') RETURNING id
2018-01-06 13:21:23,337 - LogUtils.py[line:112] - INFO:  [x] Received '{"jsonStr": "{\\"result\\": \\"\\\\u5ba2\\", \\"ret\\": 0}", "text": "\\u5ba2", "who": "human", "create_at": "2018-01-06 13:21:18", "call_id": "18", "record_fpath": "/8a9fc0df0e56058d56e8a0323f5ed08f/human_audio/18522611368_in_4_20180106132049.wav", "mark": "insert"}'


2018-01-06 13:21:23,338 - LogUtils.py[line:112] - INFO: postgresql connect host .....   118.190.166.165
2018-01-06 13:21:23,382 - LogUtils.py[line:120] - ERROR: runsql exception error insert or update on table "fs_call_replay" violates foreign key constraint "fs_call_replay_call_id_a2c15655_fk_fs_call_id"
DETAIL:  Key (call_id)=(18) is not present in table "fs_call".
 
2018-01-06 13:21:23,382 - LogUtils.py[line:112] - INFO: ******** run_insert_sql..*********...INSERT INTO fs_call_replay(who, text, record_fpath, create_at, call_id,resp_param)VALUES ('human', '客', '/8a9fc0df0e56058d56e8a0323f5ed08f/human_audio/18522611368_in_4_20180106132049.wav', '2018-01-06 13:21:18', '18','{"result": "\u5ba2", "ret": 0}') RETURNING id
2018-01-06 13:21:25,044 - LogUtils.py[line:112] - INFO:  [x] Received '{"user_label": "\\u5f00\\u573a\\u6302\\u65ad", "channal_uuid": "09aad566-a233-4275-9f91-c1a828a99b10", "mark": "user_label"}'


2018-01-06 13:21:25,045 - LogUtils.py[line:112] - INFO: postgresql connect host .....   118.190.166.165
2018-01-06 13:21:25,109 - LogUtils.py[line:112] - INFO: postgresql connect.....closed!!!
2018-01-06 13:21:25,110 - LogUtils.py[line:112] - INFO:  run_update_sql.........user_label... update fs_call set cust_tag = '开场挂断' where channal_uuid ='09aad566-a233-4275-9f91-c1a828a99b10' 
2018-01-06 13:21:28,064 - LogUtils.py[line:112] - INFO:  [x] Received '{"jsonStr": "{\\"info\\": [{\\"is_flow_output\\": true, \\"output\\": \\"\\\\u6211\\\\u4eec\\\\u662f\\\\u4e2d\\\\u5b89\\\\u4fe1\\\\u6210\\\\uff0c\\\\u4e13\\\\u4e1a\\\\u529e\\\\u7406\\\\u94f6\\\\u884c\\\\u8d37\\\\u6b3e\\\\u7684\\\\uff0c\\\\u8bf7\\\\u95ee\\\\u60a8\\\\u5927\\\\u6982\\\\u9700\\\\u8981\\\\u591a\\\\u5c11\\\\u91d1\\\\u989d\\\\u5462\\", \\"node_text\\": \\"\\\\u4f01\\\\u4e1a\\\\u4ecb\\\\u7ecd\\", \\"flow_id\\": \\"81f445b5cc3c92c5cdf3a1488a7c2eb7\\", \\"label\\": \\"\\\\u4f01\\\\u4e1a\\\\u4ecb\\\\u7ecd\\", \\"session_end\\": false, \\"state\\": \\"\\", \\"node_id\\": -11, \\"output_resource\\": \\"2.wav\\", \\"flow_end\\": false, \\"input\\": \\"\\\\u5ba2\\", \\"similarity\\": 1, \\"flow_title\\": \\"\\\\u516c\\\\u53f8\\\\u4ecb\\\\u7ecd\\", \\"output_type\\": \\"path\\", \\"user_label\\": \\"\\\\u5f00\\\\u573a\\\\u6302\\\\u65ad\\", \\"id\\": \\"81f445b5cc3c92c5cdf3a1488a7c2eb7_-11\\"}], \\"successful\\": true, \\"message\\": \\"ok\\"}", "text": "\\u6211\\u4eec\\u662f\\u4e2d\\u5b89\\u4fe1\\u6210\\uff0c\\u4e13\\u4e1a\\u529e\\u7406\\u94f6\\u884c\\u8d37\\u6b3e\\u7684\\uff0c\\u8bf7\\u95ee\\u60a8\\u5927\\u6982\\u9700\\u8981\\u591a\\u5c11\\u91d1\\u989d\\u5462", "who": "bot", "create_at": "2018-01-06 13:21:23", "call_id": "18", "record_fpath": "/8a9fc0df0e56058d56e8a0323f5ed08f/bot_audio/2.wav", "mark": "insert"}'


2018-01-06 13:21:28,064 - LogUtils.py[line:112] - INFO: postgresql connect host .....   118.190.166.165
2018-01-06 13:21:28,107 - LogUtils.py[line:120] - ERROR: runsql exception error insert or update on table "fs_call_replay" violates foreign key constraint "fs_call_replay_call_id_a2c15655_fk_fs_call_id"
DETAIL:  Key (call_id)=(18) is not present in table "fs_call".
 
2018-01-06 13:21:28,107 - LogUtils.py[line:112] - INFO: ******** run_insert_sql..*********...INSERT INTO fs_call_replay(who, text, record_fpath, create_at, call_id,resp_param)VALUES ('bot', '我们是中安信成，专业办理银行贷款的，请问您大概需要多少金额呢', '/8a9fc0df0e56058d56e8a0323f5ed08f/bot_audio/2.wav', '2018-01-06 13:21:23', '18','{"info": [{"is_flow_output": true, "output": "\u6211\u4eec\u662f\u4e2d\u5b89\u4fe1\u6210\uff0c\u4e13\u4e1a\u529e\u7406\u94f6\u884c\u8d37\u6b3e\u7684\uff0c\u8bf7\u95ee\u60a8\u5927\u6982\u9700\u8981\u591a\u5c11\u91d1\u989d\u5462", "node_text": "\u4f01\u4e1a\u4ecb\u7ecd", "flow_id": "81f445b5cc3c92c5cdf3a1488a7c2eb7", "label": "\u4f01\u4e1a\u4ecb\u7ecd", "session_end": false, "state": "", "node_id": -11, "output_resource": "2.wav", "flow_end": false, "input": "\u5ba2", "similarity": 1, "flow_title": "\u516c\u53f8\u4ecb\u7ecd", "output_type": "path", "user_label": "\u5f00\u573a\u6302\u65ad", "id": "81f445b5cc3c92c5cdf3a1488a7c2eb7_-11"}], "successful": true, "message": "ok"}') RETURNING id
2018-01-06 13:21:28,422 - LogUtils.py[line:112] - INFO:  [x] Received '{"user_label": "\\u5f00\\u573a\\u6302\\u65ad", "channal_uuid": "28d3a2e7-7891-42c3-9172-49e66dd55827", "mark": "user_label"}'


2018-01-06 13:21:28,423 - LogUtils.py[line:112] - INFO: postgresql connect host .....   118.190.166.165
2018-01-06 13:21:28,488 - LogUtils.py[line:112] - INFO: postgresql connect.....closed!!!
2018-01-06 13:21:28,488 - LogUtils.py[line:112] - INFO:  run_update_sql.........user_label... update fs_call set cust_tag = '开场挂断' where channal_uuid ='28d3a2e7-7891-42c3-9172-49e66dd55827' 
2018-01-06 13:21:31,032 - LogUtils.py[line:112] - INFO:  [x] Received '{"user_id": "3", "task_id": "5", "number": "13512239772", "call_id": "20", "flow_id": "8a9fc0df0e56058d56e8a0323f5ed08f", "mark": "statistical"}'


2018-01-06 13:21:31,033 - LogUtils.py[line:112] - INFO: postgresql connect host .....   118.190.166.165
2018-01-06 13:21:31,078 - LogUtils.py[line:112] - INFO: postgresql connect.....closed!!!
2018-01-06 13:21:49,881 - LogUtils.py[line:112] - INFO:  [x] Received '{"user_label": "\\u672a\\u77e5", "channal_uuid": "5a9d79a2-6e11-4022-b18f-a2ea6a7b6efa", "mark": "user_label"}'


2018-01-06 13:21:49,882 - LogUtils.py[line:112] - INFO: postgresql connect host .....   118.190.166.165
2018-01-06 13:21:49,947 - LogUtils.py[line:112] - INFO: postgresql connect.....closed!!!
2018-01-06 13:21:49,947 - LogUtils.py[line:112] - INFO:  run_update_sql.........user_label... update fs_call set cust_tag = '未知' where channal_uuid ='5a9d79a2-6e11-4022-b18f-a2ea6a7b6efa' 
2018-01-06 13:21:53,356 - LogUtils.py[line:112] - INFO:  [x] Received '{"jsonStr": "{\\"result\\": \\"\\\\u54ce\\\\u4f60\\\\u597d\\", \\"ret\\": 0}", "text": "\\u54ce\\u4f60\\u597d", "who": "human", "create_at": "2018-01-06 13:21:50", "call_id": "21", "record_fpath": "/8a9fc0df0e56058d56e8a0323f5ed08f/human_audio/15900282168_in_0_20180106132149.wav", "mark": "insert"}'


2018-01-06 13:21:53,356 - LogUtils.py[line:112] - INFO: postgresql connect host .....   118.190.166.165
2018-01-06 13:21:53,400 - LogUtils.py[line:120] - ERROR: runsql exception error insert or update on table "fs_call_replay" violates foreign key constraint "fs_call_replay_call_id_a2c15655_fk_fs_call_id"
DETAIL:  Key (call_id)=(21) is not present in table "fs_call".
 
2018-01-06 13:21:53,401 - LogUtils.py[line:112] - INFO: ******** run_insert_sql..*********...INSERT INTO fs_call_replay(who, text, record_fpath, create_at, call_id,resp_param)VALUES ('human', '哎你好', '/8a9fc0df0e56058d56e8a0323f5ed08f/human_audio/15900282168_in_0_20180106132149.wav', '2018-01-06 13:21:50', '21','{"result": "\u54ce\u4f60\u597d", "ret": 0}') RETURNING id
2018-01-06 13:21:57,403 - LogUtils.py[line:112] - INFO:  [x] Received '{"jsonStr": "{\\"info\\": [{\\"is_flow_output\\": true, \\"output\\": \\"\\\\u60a8\\\\u597d\\\\uff0c\\\\u6211\\\\u4eec\\\\u662f\\\\u529e\\\\u7406\\\\u8d37\\\\u6b3e\\\\u7684\\\\uff0c\\\\u8bf7\\\\u95ee\\\\u60a8\\\\u6709\\\\u8d44\\\\u91d1\\\\u4e0a\\\\u7684\\\\u9700\\\\u6c42\\\\u5417\\\\uff1f\\", \\"node_text\\": \\"\\\\u8bed\\\\u6599\\\\u8282\\\\u70b9\\", \\"flow_id\\": \\"505c426d2b8fbe8f8f5f18250c2f568f\\", \\"label\\": \\"\\\\u5f00\\\\u573a\\\\u767d\\", \\"session_end\\": false, \\"state\\": \\"\\", \\"node_id\\": -3, \\"output_resource\\": \\"7.wav\\", \\"flow_end\\": false, \\"input\\": \\"\\\\u54ce\\\\u4f60\\\\u597d\\", \\"similarity\\": 1, \\"flow_title\\": \\"\\\\u5f00\\\\u573a\\\\u767d\\", \\"output_type\\": \\"path\\", \\"user_label\\": \\"\\\\u5f00\\\\u573a\\\\u6302\\\\u65ad\\", \\"id\\": \\"505c426d2b8fbe8f8f5f18250c2f568f_-3\\"}], \\"successful\\": true, \\"message\\": \\"ok\\"}", "text": "\\u60a8\\u597d\\uff0c\\u6211\\u4eec\\u662f\\u529e\\u7406\\u8d37\\u6b3e\\u7684\\uff0c\\u8bf7\\u95ee\\u60a8\\u6709\\u8d44\\u91d1\\u4e0a\\u7684\\u9700\\u6c42\\u5417\\uff1f", "who": "bot", "create_at": "2018-01-06 13:21:53", "call_id": "21", "record_fpath": "/8a9fc0df0e56058d56e8a0323f5ed08f/bot_audio/7.wav", "mark": "insert"}'


2018-01-06 13:21:57,403 - LogUtils.py[line:112] - INFO: postgresql connect host .....   118.190.166.165
2018-01-06 13:21:57,470 - LogUtils.py[line:120] - ERROR: runsql exception error insert or update on table "fs_call_replay" violates foreign key constraint "fs_call_replay_call_id_a2c15655_fk_fs_call_id"
DETAIL:  Key (call_id)=(21) is not present in table "fs_call".
 
2018-01-06 13:21:57,470 - LogUtils.py[line:112] - INFO: ******** run_insert_sql..*********...INSERT INTO fs_call_replay(who, text, record_fpath, create_at, call_id,resp_param)VALUES ('bot', '您好，我们是办理贷款的，请问您有资金上的需求吗？', '/8a9fc0df0e56058d56e8a0323f5ed08f/bot_audio/7.wav', '2018-01-06 13:21:53', '21','{"info": [{"is_flow_output": true, "output": "\u60a8\u597d\uff0c\u6211\u4eec\u662f\u529e\u7406\u8d37\u6b3e\u7684\uff0c\u8bf7\u95ee\u60a8\u6709\u8d44\u91d1\u4e0a\u7684\u9700\u6c42\u5417\uff1f", "node_text": "\u8bed\u6599\u8282\u70b9", "flow_id": "505c426d2b8fbe8f8f5f18250c2f568f", "label": "\u5f00\u573a\u767d", "session_end": false, "state": "", "node_id": -3, "output_resource": "7.wav", "flow_end": false, "input": "\u54ce\u4f60\u597d", "similarity": 1, "flow_title": "\u5f00\u573a\u767d", "output_type": "path", "user_label": "\u5f00\u573a\u6302\u65ad", "id": "505c426d2b8fbe8f8f5f18250c2f568f_-3"}], "successful": true, "message": "ok"}') RETURNING id
2018-01-06 13:22:01,242 - LogUtils.py[line:112] - INFO:  [x] Received '{"user_label": "\\u5f00\\u573a\\u6302\\u65ad", "channal_uuid": "5a9d79a2-6e11-4022-b18f-a2ea6a7b6efa", "mark": "user_label"}'


2018-01-06 13:22:01,243 - LogUtils.py[line:112] - INFO: postgresql connect host .....   118.190.166.165
2018-01-06 13:22:01,286 - LogUtils.py[line:112] - INFO: postgresql connect.....closed!!!
2018-01-06 13:22:01,286 - LogUtils.py[line:112] - INFO:  run_update_sql.........user_label... update fs_call set cust_tag = '开场挂断' where channal_uuid ='5a9d79a2-6e11-4022-b18f-a2ea6a7b6efa' 
2018-01-06 13:22:13,942 - LogUtils.py[line:112] - INFO:  [x] Received '{"jsonStr": "vad \\u6ca1\\u6709\\u68c0\\u6d4b\\u5230\\u58f0\\u97f3", "text": "", "who": "human", "create_at": "2018-01-06 13:22:08", "call_id": "21", "record_fpath": "", "mark": "insert"}'


2018-01-06 13:22:13,943 - LogUtils.py[line:112] - INFO: postgresql connect host .....   118.190.166.165
2018-01-06 13:22:14,009 - LogUtils.py[line:120] - ERROR: runsql exception error insert or update on table "fs_call_replay" violates foreign key constraint "fs_call_replay_call_id_a2c15655_fk_fs_call_id"
DETAIL:  Key (call_id)=(21) is not present in table "fs_call".
 
2018-01-06 13:22:14,009 - LogUtils.py[line:112] - INFO: ******** run_insert_sql..*********...INSERT INTO fs_call_replay(who, text, record_fpath, create_at, call_id,resp_param)VALUES ('human', '', '', '2018-01-06 13:22:08', '21','vad 没有检测到声音') RETURNING id
2018-01-06 13:22:14,421 - LogUtils.py[line:112] - INFO:  [x] Received '{"jsonStr": "{\\"info\\": [{\\"is_flow_output\\": true, \\"output\\": \\"\\\\u5582\\\\uff1f\\", \\"node_text\\": \\"\\\\u8bed\\\\u6599\\\\u8282\\\\u70b9\\", \\"flow_id\\": \\"8a9fc0df0e56058d56e8a0323f5ed08f\\", \\"label\\": \\"\\", \\"session_end\\": false, \\"state\\": \\"\\", \\"node_id\\": -11, \\"output_resource\\": \\"t0.wav\\", \\"flow_end\\": false, \\"input\\": \\"\\", \\"similarity\\": 1, \\"flow_title\\": \\"\\\\u91d1\\\\u878d\\\\u884c\\\\u4e1a\\\\uff08\\\\u8d37\\\\u6b3e\\\\uff09\\", \\"output_type\\": \\"path\\", \\"user_label\\": \\"\\\\u5f00\\\\u573a\\\\u6302\\\\u65ad\\", \\"id\\": \\"8a9fc0df0e56058d56e8a0323f5ed08f_-11\\"}], \\"successful\\": true, \\"message\\": \\"ok\\"}", "text": "\\u5582\\uff1f", "who": "bot", "create_at": "2018-01-06 13:22:13", "call_id": "21", "record_fpath": "/8a9fc0df0e56058d56e8a0323f5ed08f/bot_audio/t0.wav", "mark": "insert"}'


2018-01-06 13:22:14,422 - LogUtils.py[line:112] - INFO: postgresql connect host .....   118.190.166.165
2018-01-06 13:22:14,465 - LogUtils.py[line:120] - ERROR: runsql exception error insert or update on table "fs_call_replay" violates foreign key constraint "fs_call_replay_call_id_a2c15655_fk_fs_call_id"
DETAIL:  Key (call_id)=(21) is not present in table "fs_call".
 
2018-01-06 13:22:14,466 - LogUtils.py[line:112] - INFO: ******** run_insert_sql..*********...INSERT INTO fs_call_replay(who, text, record_fpath, create_at, call_id,resp_param)VALUES ('bot', '喂？', '/8a9fc0df0e56058d56e8a0323f5ed08f/bot_audio/t0.wav', '2018-01-06 13:22:13', '21','{"info": [{"is_flow_output": true, "output": "\u5582\uff1f", "node_text": "\u8bed\u6599\u8282\u70b9", "flow_id": "8a9fc0df0e56058d56e8a0323f5ed08f", "label": "", "session_end": false, "state": "", "node_id": -11, "output_resource": "t0.wav", "flow_end": false, "input": "", "similarity": 1, "flow_title": "\u91d1\u878d\u884c\u4e1a\uff08\u8d37\u6b3e\uff09", "output_type": "path", "user_label": "\u5f00\u573a\u6302\u65ad", "id": "8a9fc0df0e56058d56e8a0323f5ed08f_-11"}], "successful": true, "message": "ok"}') RETURNING id
2018-01-06 13:22:18,697 - LogUtils.py[line:112] - INFO:  [x] Received '{"user_label": "\\u5f00\\u573a\\u6302\\u65ad", "channal_uuid": "5a9d79a2-6e11-4022-b18f-a2ea6a7b6efa", "mark": "user_label"}'


2018-01-06 13:22:18,697 - LogUtils.py[line:112] - INFO: postgresql connect host .....   118.190.166.165
2018-01-06 13:22:18,762 - LogUtils.py[line:112] - INFO: postgresql connect.....closed!!!
2018-01-06 13:22:18,763 - LogUtils.py[line:112] - INFO:  run_update_sql.........user_label... update fs_call set cust_tag = '开场挂断' where channal_uuid ='5a9d79a2-6e11-4022-b18f-a2ea6a7b6efa' 
2018-01-06 13:22:24,722 - LogUtils.py[line:112] - INFO:  [x] Received '{"user_id": "3", "task_id": "5", "number": "15900282168", "call_id": "21", "flow_id": "8a9fc0df0e56058d56e8a0323f5ed08f", "mark": "statistical"}'


2018-01-06 13:22:24,723 - LogUtils.py[line:112] - INFO: postgresql connect host .....   118.190.166.165
2018-01-06 13:22:24,765 - LogUtils.py[line:112] - INFO: postgresql connect.....closed!!!
2018-01-06 13:24:36,031 - LogUtils.py[line:112] - INFO:  [x] Received '{"record_fpath": "/c5042ccaf08af15443fe177d915e0070/all_audio/15712885451_full_20180106132436_.wav", "channal_uuid": "eb0c2b63-a11b-4f63-a94a-28a8c40349c9", "mark": "update"}'


2018-01-06 13:24:36,032 - LogUtils.py[line:112] - INFO: postgresql connect host .....   118.190.166.165
2018-01-06 13:24:36,097 - LogUtils.py[line:112] - INFO: postgresql connect.....closed!!!
2018-01-06 13:24:36,097 - LogUtils.py[line:112] - INFO: run_update_sql.....update fs_call set full_record_fpath ='/c5042ccaf08af15443fe177d915e0070/all_audio/15712885451_full_20180106132436_.wav' where channal_uuid ='eb0c2b63-a11b-4f63-a94a-28a8c40349c9'
2018-01-06 13:26:42,026 - LogUtils.py[line:112] - INFO:  [x] Received '{"record_fpath": "/c5042ccaf08af15443fe177d915e0070/all_audio/15712885451_full_20180106132642_.wav", "channal_uuid": "5d2e7c97-b528-458e-827a-2faf4f6415d1", "mark": "update"}'


2018-01-06 13:26:42,026 - LogUtils.py[line:112] - INFO: postgresql connect host .....   118.190.166.165
2018-01-06 13:26:42,069 - LogUtils.py[line:112] - INFO: postgresql connect.....closed!!!
2018-01-06 13:26:42,070 - LogUtils.py[line:112] - INFO: run_update_sql.....update fs_call set full_record_fpath ='/c5042ccaf08af15443fe177d915e0070/all_audio/15712885451_full_20180106132642_.wav' where channal_uuid ='5d2e7c97-b528-458e-827a-2faf4f6415d1'
2018-01-06 13:28:30,526 - LogUtils.py[line:112] - INFO:  [x] Received '{"record_fpath": "/8a9fc0df0e56058d56e8a0323f5ed08f/all_audio/15900282168_full_20180106132830_.wav", "channal_uuid": "d263622e-c9b0-4098-b21c-168fb1b6deda", "mark": "update"}'


2018-01-06 13:28:30,527 - LogUtils.py[line:112] - INFO: postgresql connect host .....   118.190.166.165
2018-01-06 13:28:30,592 - LogUtils.py[line:112] - INFO: postgresql connect.....closed!!!
2018-01-06 13:28:30,592 - LogUtils.py[line:112] - INFO: run_update_sql.....update fs_call set full_record_fpath ='/8a9fc0df0e56058d56e8a0323f5ed08f/all_audio/15900282168_full_20180106132830_.wav' where channal_uuid ='d263622e-c9b0-4098-b21c-168fb1b6deda'
2018-01-06 13:28:31,464 - LogUtils.py[line:112] - INFO:  [x] Received '{"jsonStr": "{\\"info\\": [{\\"is_flow_output\\": true, \\"output\\": \\"\\\\u5582\\\\uff0c\\\\u60a8\\\\u597d\\\\u3002\\", \\"node_text\\": \\"\\\\u95ee\\\\u5019\\\\u8bed\\", \\"flow_id\\": \\"505c426d2b8fbe8f8f5f18250c2f568f\\", \\"label\\": \\"\\", \\"session_end\\": false, \\"state\\": \\"\\", \\"node_id\\": -11, \\"output_resource\\": \\"t13.wav\\", \\"flow_end\\": false, \\"input\\": \\"\\\\u4f60\\\\u597d\\", \\"similarity\\": 1, \\"flow_title\\": \\"\\\\u5f00\\\\u573a\\\\u767d\\", \\"output_type\\": \\"path\\", \\"user_label\\": \\"\\\\u672a\\\\u77e5\\", \\"id\\": \\"505c426d2b8fbe8f8f5f18250c2f568f_-11\\"}], \\"successful\\": true, \\"message\\": \\"ok\\"}", "text": "\\u5582\\uff0c\\u60a8\\u597d\\u3002", "who": "bot", "create_at": "2018-01-06 13:28:30", "call_id": "25", "record_fpath": "/8a9fc0df0e56058d56e8a0323f5ed08f/bot_audio/t13.wav", "mark": "insert"}'


2018-01-06 13:28:31,464 - LogUtils.py[line:112] - INFO: postgresql connect host .....   118.190.166.165
2018-01-06 13:28:31,508 - LogUtils.py[line:120] - ERROR: runsql exception error insert or update on table "fs_call_replay" violates foreign key constraint "fs_call_replay_call_id_a2c15655_fk_fs_call_id"
DETAIL:  Key (call_id)=(25) is not present in table "fs_call".
 
2018-01-06 13:28:31,508 - LogUtils.py[line:112] - INFO: ******** run_insert_sql..*********...INSERT INTO fs_call_replay(who, text, record_fpath, create_at, call_id,resp_param)VALUES ('bot', '喂，您好。', '/8a9fc0df0e56058d56e8a0323f5ed08f/bot_audio/t13.wav', '2018-01-06 13:28:30', '25','{"info": [{"is_flow_output": true, "output": "\u5582\uff0c\u60a8\u597d\u3002", "node_text": "\u95ee\u5019\u8bed", "flow_id": "505c426d2b8fbe8f8f5f18250c2f568f", "label": "", "session_end": false, "state": "", "node_id": -11, "output_resource": "t13.wav", "flow_end": false, "input": "\u4f60\u597d", "similarity": 1, "flow_title": "\u5f00\u573a\u767d", "output_type": "path", "user_label": "\u672a\u77e5", "id": "505c426d2b8fbe8f8f5f18250c2f568f_-11"}], "successful": true, "message": "ok"}') RETURNING id
2018-01-06 13:28:34,693 - LogUtils.py[line:112] - INFO:  [x] Received '{"user_label": "\\u5f00\\u573a\\u6302\\u65ad", "channal_uuid": "d263622e-c9b0-4098-b21c-168fb1b6deda", "mark": "user_label"}'


2018-01-06 13:28:34,693 - LogUtils.py[line:112] - INFO: postgresql connect host .....   118.190.166.165
2018-01-06 13:28:34,758 - LogUtils.py[line:112] - INFO: postgresql connect.....closed!!!
2018-01-06 13:28:34,758 - LogUtils.py[line:112] - INFO:  run_update_sql.........user_label... update fs_call set cust_tag = '开场挂断' where channal_uuid ='d263622e-c9b0-4098-b21c-168fb1b6deda' 
2018-01-06 13:28:42,337 - LogUtils.py[line:112] - INFO:  [x] Received '{"jsonStr": "{\\"result\\": \\"\\\\u6ca1\\\\u6709\\\\u6ca1\\\\u6709\\\\u6709\\", \\"ret\\": 0}", "text": "\\u6ca1\\u6709\\u6ca1\\u6709\\u6709", "who": "human", "create_at": "2018-01-06 13:28:38", "call_id": "25", "record_fpath": "/8a9fc0df0e56058d56e8a0323f5ed08f/human_audio/15900282168_in_1_20180106132830.wav", "mark": "insert"}'


2018-01-06 13:28:42,337 - LogUtils.py[line:112] - INFO: postgresql connect host .....   118.190.166.165
2018-01-06 13:28:42,381 - LogUtils.py[line:120] - ERROR: runsql exception error insert or update on table "fs_call_replay" violates foreign key constraint "fs_call_replay_call_id_a2c15655_fk_fs_call_id"
DETAIL:  Key (call_id)=(25) is not present in table "fs_call".
 
2018-01-06 13:28:42,382 - LogUtils.py[line:112] - INFO: ******** run_insert_sql..*********...INSERT INTO fs_call_replay(who, text, record_fpath, create_at, call_id,resp_param)VALUES ('human', '没有没有有', '/8a9fc0df0e56058d56e8a0323f5ed08f/human_audio/15900282168_in_1_20180106132830.wav', '2018-01-06 13:28:38', '25','{"result": "\u6ca1\u6709\u6ca1\u6709\u6709", "ret": 0}') RETURNING id
2018-01-06 13:28:47,804 - LogUtils.py[line:112] - INFO:  [x] Received '{"jsonStr": "{\\"info\\": [{\\"is_flow_output\\": true, \\"output\\": \\"\\\\u6211\\\\u4eec\\\\u662f\\\\u4e2d\\\\u5b89\\\\u4fe1\\\\u6210\\\\uff0c\\\\u4e13\\\\u4e1a\\\\u529e\\\\u7406\\\\u94f6\\\\u884c\\\\u8d37\\\\u6b3e\\\\u7684\\\\uff0c\\\\u8bf7\\\\u95ee\\\\u60a8\\\\u5927\\\\u6982\\\\u9700\\\\u8981\\\\u591a\\\\u5c11\\\\u91d1\\\\u989d\\\\u5462\\", \\"node_text\\": \\"\\\\u4f01\\\\u4e1a\\\\u4ecb\\\\u7ecd\\", \\"flow_id\\": \\"81f445b5cc3c92c5cdf3a1488a7c2eb7\\", \\"label\\": \\"\\\\u4f01\\\\u4e1a\\\\u4ecb\\\\u7ecd\\", \\"session_end\\": false, \\"state\\": \\"\\", \\"node_id\\": -11, \\"output_resource\\": \\"2.wav\\", \\"flow_end\\": false, \\"input\\": \\"\\\\u6ca1\\\\u6709\\\\u6ca1\\\\u6709\\\\u6709\\", \\"similarity\\": 1, \\"flow_title\\": \\"\\\\u516c\\\\u53f8\\\\u4ecb\\\\u7ecd\\", \\"output_type\\": \\"path\\", \\"user_label\\": \\"\\\\u5f00\\\\u573a\\\\u6302\\\\u65ad\\", \\"id\\": \\"81f445b5cc3c92c5cdf3a1488a7c2eb7_-11\\"}], \\"successful\\": true, \\"message\\": \\"ok\\"}", "text": "\\u6211\\u4eec\\u662f\\u4e2d\\u5b89\\u4fe1\\u6210\\uff0c\\u4e13\\u4e1a\\u529e\\u7406\\u94f6\\u884c\\u8d37\\u6b3e\\u7684\\uff0c\\u8bf7\\u95ee\\u60a8\\u5927\\u6982\\u9700\\u8981\\u591a\\u5c11\\u91d1\\u989d\\u5462", "who": "bot", "create_at": "2018-01-06 13:28:42", "call_id": "25", "record_fpath": "/8a9fc0df0e56058d56e8a0323f5ed08f/bot_audio/2.wav", "mark": "insert"}'


2018-01-06 13:28:47,805 - LogUtils.py[line:112] - INFO: postgresql connect host .....   118.190.166.165
2018-01-06 13:28:47,871 - LogUtils.py[line:120] - ERROR: runsql exception error insert or update on table "fs_call_replay" violates foreign key constraint "fs_call_replay_call_id_a2c15655_fk_fs_call_id"
DETAIL:  Key (call_id)=(25) is not present in table "fs_call".
 
2018-01-06 13:28:47,871 - LogUtils.py[line:112] - INFO: ******** run_insert_sql..*********...INSERT INTO fs_call_replay(who, text, record_fpath, create_at, call_id,resp_param)VALUES ('bot', '我们是中安信成，专业办理银行贷款的，请问您大概需要多少金额呢', '/8a9fc0df0e56058d56e8a0323f5ed08f/bot_audio/2.wav', '2018-01-06 13:28:42', '25','{"info": [{"is_flow_output": true, "output": "\u6211\u4eec\u662f\u4e2d\u5b89\u4fe1\u6210\uff0c\u4e13\u4e1a\u529e\u7406\u94f6\u884c\u8d37\u6b3e\u7684\uff0c\u8bf7\u95ee\u60a8\u5927\u6982\u9700\u8981\u591a\u5c11\u91d1\u989d\u5462", "node_text": "\u4f01\u4e1a\u4ecb\u7ecd", "flow_id": "81f445b5cc3c92c5cdf3a1488a7c2eb7", "label": "\u4f01\u4e1a\u4ecb\u7ecd", "session_end": false, "state": "", "node_id": -11, "output_resource": "2.wav", "flow_end": false, "input": "\u6ca1\u6709\u6ca1\u6709\u6709", "similarity": 1, "flow_title": "\u516c\u53f8\u4ecb\u7ecd", "output_type": "path", "user_label": "\u5f00\u573a\u6302\u65ad", "id": "81f445b5cc3c92c5cdf3a1488a7c2eb7_-11"}], "successful": true, "message": "ok"}') RETURNING id
2018-01-06 13:28:51,233 - LogUtils.py[line:112] - INFO:  [x] Received '{"user_label": "\\u5f00\\u573a\\u6302\\u65ad", "channal_uuid": "d263622e-c9b0-4098-b21c-168fb1b6deda", "mark": "user_label"}'


2018-01-06 13:28:51,233 - LogUtils.py[line:112] - INFO: postgresql connect host .....   118.190.166.165
2018-01-06 13:28:51,276 - LogUtils.py[line:112] - INFO: postgresql connect.....closed!!!
2018-01-06 13:28:51,276 - LogUtils.py[line:112] - INFO:  run_update_sql.........user_label... update fs_call set cust_tag = '开场挂断' where channal_uuid ='d263622e-c9b0-4098-b21c-168fb1b6deda' 
2018-01-06 13:28:55,854 - LogUtils.py[line:112] - INFO:  [x] Received '{"jsonStr": "{\\"result\\": \\"\\\\u6211\\\\u8981\\\\u4e70\\\\u4ec0\\\\u4e48\\\\u6837\\", \\"ret\\": 0}", "text": "\\u6211\\u8981\\u4e70\\u4ec0\\u4e48\\u6837", "who": "human", "create_at": "2018-01-06 13:28:52", "call_id": "25", "record_fpath": "/8a9fc0df0e56058d56e8a0323f5ed08f/human_audio/15900282168_in_3_20180106132830.wav", "mark": "insert"}'


2018-01-06 13:28:55,855 - LogUtils.py[line:112] - INFO: postgresql connect host .....   118.190.166.165
2018-01-06 13:28:55,921 - LogUtils.py[line:120] - ERROR: runsql exception error insert or update on table "fs_call_replay" violates foreign key constraint "fs_call_replay_call_id_a2c15655_fk_fs_call_id"
DETAIL:  Key (call_id)=(25) is not present in table "fs_call".
 
2018-01-06 13:28:55,921 - LogUtils.py[line:112] - INFO: ******** run_insert_sql..*********...INSERT INTO fs_call_replay(who, text, record_fpath, create_at, call_id,resp_param)VALUES ('human', '我要买什么样', '/8a9fc0df0e56058d56e8a0323f5ed08f/human_audio/15900282168_in_3_20180106132830.wav', '2018-01-06 13:28:52', '25','{"result": "\u6211\u8981\u4e70\u4ec0\u4e48\u6837", "ret": 0}') RETURNING id
2018-01-06 13:28:59,444 - LogUtils.py[line:112] - INFO:  [x] Received '{"jsonStr": "{\\"info\\": [{\\"is_flow_output\\": true, \\"output\\": \\"\\\\u8bf7\\\\u95ee\\\\u60a8\\\\u623f\\\\u5b50\\\\u662f\\\\u54ea\\\\u4e2a\\\\u5c0f\\\\u533a\\\\uff0c\\\\u591a\\\\u5927\\\\u9762\\\\u79ef\\\\u7684\\\\u5462\\\\uff1f\\", \\"node_text\\": \\"\\\\u95ee\\\\u98988\\", \\"flow_id\\": \\"ba8d69e98f71243574ab338537a7a1bd\\", \\"label\\": \\"\\\\u95ee\\\\u98988\\", \\"session_end\\": false, \\"state\\": \\"\\", \\"node_id\\": -26, \\"output_resource\\": \\"6.wav\\", \\"flow_end\\": false, \\"input\\": \\"\\\\u6211\\\\u8981\\\\u4e70\\\\u4ec0\\\\u4e48\\\\u6837\\", \\"similarity\\": 1, \\"flow_title\\": \\"\\\\u4e86\\\\u89e3\\\\u60c5\\\\u51b5\\", \\"output_type\\": \\"path\\", \\"user_label\\": \\"\\\\u4e2a\\\\u4eba\\\\u62b5\\\\u62bc\\\\u8d37\\\\u6b3e\\", \\"id\\": \\"ba8d69e98f71243574ab338537a7a1bd_-26\\"}], \\"successful\\": true, \\"message\\": \\"ok\\"}", "text": "\\u8bf7\\u95ee\\u60a8\\u623f\\u5b50\\u662f\\u54ea\\u4e2a\\u5c0f\\u533a\\uff0c\\u591a\\u5927\\u9762\\u79ef\\u7684\\u5462\\uff1f", "who": "bot", "create_at": "2018-01-06 13:28:55", "call_id": "25", "record_fpath": "/8a9fc0df0e56058d56e8a0323f5ed08f/bot_audio/6.wav", "mark": "insert"}'


2018-01-06 13:28:59,444 - LogUtils.py[line:112] - INFO: postgresql connect host .....   118.190.166.165
2018-01-06 13:28:59,489 - LogUtils.py[line:120] - ERROR: runsql exception error insert or update on table "fs_call_replay" violates foreign key constraint "fs_call_replay_call_id_a2c15655_fk_fs_call_id"
DETAIL:  Key (call_id)=(25) is not present in table "fs_call".
 
2018-01-06 13:28:59,490 - LogUtils.py[line:112] - INFO: ******** run_insert_sql..*********...INSERT INTO fs_call_replay(who, text, record_fpath, create_at, call_id,resp_param)VALUES ('bot', '请问您房子是哪个小区，多大面积的呢？', '/8a9fc0df0e56058d56e8a0323f5ed08f/bot_audio/6.wav', '2018-01-06 13:28:55', '25','{"info": [{"is_flow_output": true, "output": "\u8bf7\u95ee\u60a8\u623f\u5b50\u662f\u54ea\u4e2a\u5c0f\u533a\uff0c\u591a\u5927\u9762\u79ef\u7684\u5462\uff1f", "node_text": "\u95ee\u98988", "flow_id": "ba8d69e98f71243574ab338537a7a1bd", "label": "\u95ee\u98988", "session_end": false, "state": "", "node_id": -26, "output_resource": "6.wav", "flow_end": false, "input": "\u6211\u8981\u4e70\u4ec0\u4e48\u6837", "similarity": 1, "flow_title": "\u4e86\u89e3\u60c5\u51b5", "output_type": "path", "user_label": "\u4e2a\u4eba\u62b5\u62bc\u8d37\u6b3e", "id": "ba8d69e98f71243574ab338537a7a1bd_-26"}], "successful": true, "message": "ok"}') RETURNING id
2018-01-06 13:29:03,294 - LogUtils.py[line:112] - INFO:  [x] Received '{"user_label": "\\u4e2a\\u4eba\\u62b5\\u62bc\\u8d37\\u6b3e", "channal_uuid": "d263622e-c9b0-4098-b21c-168fb1b6deda", "mark": "user_label"}'


2018-01-06 13:29:03,295 - LogUtils.py[line:112] - INFO: postgresql connect host .....   118.190.166.165
2018-01-06 13:29:03,361 - LogUtils.py[line:112] - INFO: postgresql connect.....closed!!!
2018-01-06 13:29:03,361 - LogUtils.py[line:112] - INFO:  run_update_sql.........user_label... update fs_call set cust_tag = '个人抵押贷款' where channal_uuid ='d263622e-c9b0-4098-b21c-168fb1b6deda' 
2018-01-06 13:29:11,936 - LogUtils.py[line:112] - INFO:  [x] Received '{"jsonStr": "{\\"result\\": \\"\\\\u5c31\\\\u4f60\\\\u8ddf\\\\u6211\\\\u8bf4\\\\u5427\\", \\"ret\\": 0}", "text": "\\u5c31\\u4f60\\u8ddf\\u6211\\u8bf4\\u5427", "who": "human", "create_at": "2018-01-06 13:29:08", "call_id": "25", "record_fpath": "/8a9fc0df0e56058d56e8a0323f5ed08f/human_audio/15900282168_in_5_20180106132830.wav", "mark": "insert"}'


2018-01-06 13:29:11,937 - LogUtils.py[line:112] - INFO: postgresql connect host .....   118.190.166.165
2018-01-06 13:29:11,981 - LogUtils.py[line:120] - ERROR: runsql exception error insert or update on table "fs_call_replay" violates foreign key constraint "fs_call_replay_call_id_a2c15655_fk_fs_call_id"
DETAIL:  Key (call_id)=(25) is not present in table "fs_call".
 
2018-01-06 13:29:11,981 - LogUtils.py[line:112] - INFO: ******** run_insert_sql..*********...INSERT INTO fs_call_replay(who, text, record_fpath, create_at, call_id,resp_param)VALUES ('human', '就你跟我说吧', '/8a9fc0df0e56058d56e8a0323f5ed08f/human_audio/15900282168_in_5_20180106132830.wav', '2018-01-06 13:29:08', '25','{"result": "\u5c31\u4f60\u8ddf\u6211\u8bf4\u5427", "ret": 0}') RETURNING id
2018-01-06 13:29:16,345 - LogUtils.py[line:112] - INFO:  [x] Received '{"jsonStr": "{\\"info\\": [{\\"is_flow_output\\": true, \\"output\\": \\"\\\\u90a3\\\\u597d\\\\uff0c\\\\u7a0d\\\\u540e\\\\u4f1a\\\\u6709\\\\u5de5\\\\u4f5c\\\\u4eba\\\\u5458\\\\u4e0e\\\\u60a8\\\\u8054\\\\u7cfb\\\\uff0c\\\\u795d\\\\u60a8\\\\u751f\\\\u6d3b\\\\u6109\\\\u5feb\\\\uff0c\\\\u518d\\\\u89c1\\\\u3002\\", \\"node_text\\": \\"\\\\u7ed3\\\\u675f\\\\u8bed4\\", \\"flow_id\\": \\"bfbbb0cfab4aac3dba462ac2d805fca1\\", \\"label\\": \\"\\\\u7ed3\\\\u675f\\\\u8bed4\\", \\"session_end\\": false, \\"state\\": \\"\\", \\"node_id\\": -7, \\"output_resource\\": \\"13.wav\\", \\"flow_end\\": true, \\"input\\": \\"\\\\u5c31\\\\u4f60\\\\u8ddf\\\\u6211\\\\u8bf4\\\\u5427\\", \\"similarity\\": 1, \\"flow_title\\": \\"\\\\u9080\\\\u7ea6\\", \\"output_type\\": \\"path\\", \\"user_label\\": \\"\\\\u4e2a\\\\u4eba\\\\u62b5\\\\u62bc\\\\u8d37\\\\u6b3e\\", \\"id\\": \\"bfbbb0cfab4aac3dba462ac2d805fca1_-7\\"}], \\"successful\\": true, \\"message\\": \\"ok\\"}", "text": "\\u90a3\\u597d\\uff0c\\u7a0d\\u540e\\u4f1a\\u6709\\u5de5\\u4f5c\\u4eba\\u5458\\u4e0e\\u60a8\\u8054\\u7cfb\\uff0c\\u795d\\u60a8\\u751f\\u6d3b\\u6109\\u5feb\\uff0c\\u518d\\u89c1\\u3002", "who": "bot", "create_at": "2018-01-06 13:29:11", "call_id": "25", "record_fpath": "/8a9fc0df0e56058d56e8a0323f5ed08f/bot_audio/13.wav", "mark": "insert"}'


2018-01-06 13:29:16,345 - LogUtils.py[line:112] - INFO: postgresql connect host .....   118.190.166.165
2018-01-06 13:29:16,412 - LogUtils.py[line:120] - ERROR: runsql exception error insert or update on table "fs_call_replay" violates foreign key constraint "fs_call_replay_call_id_a2c15655_fk_fs_call_id"
DETAIL:  Key (call_id)=(25) is not present in table "fs_call".
 
2018-01-06 13:29:16,412 - LogUtils.py[line:112] - INFO: ******** run_insert_sql..*********...INSERT INTO fs_call_replay(who, text, record_fpath, create_at, call_id,resp_param)VALUES ('bot', '那好，稍后会有工作人员与您联系，祝您生活愉快，再见。', '/8a9fc0df0e56058d56e8a0323f5ed08f/bot_audio/13.wav', '2018-01-06 13:29:11', '25','{"info": [{"is_flow_output": true, "output": "\u90a3\u597d\uff0c\u7a0d\u540e\u4f1a\u6709\u5de5\u4f5c\u4eba\u5458\u4e0e\u60a8\u8054\u7cfb\uff0c\u795d\u60a8\u751f\u6d3b\u6109\u5feb\uff0c\u518d\u89c1\u3002", "node_text": "\u7ed3\u675f\u8bed4", "flow_id": "bfbbb0cfab4aac3dba462ac2d805fca1", "label": "\u7ed3\u675f\u8bed4", "session_end": false, "state": "", "node_id": -7, "output_resource": "13.wav", "flow_end": true, "input": "\u5c31\u4f60\u8ddf\u6211\u8bf4\u5427", "similarity": 1, "flow_title": "\u9080\u7ea6", "output_type": "path", "user_label": "\u4e2a\u4eba\u62b5\u62bc\u8d37\u6b3e", "id": "bfbbb0cfab4aac3dba462ac2d805fca1_-7"}], "successful": true, "message": "ok"}') RETURNING id
2018-01-06 13:31:48,178 - LogUtils.py[line:112] - INFO:  [x] Received '{"record_fpath": "/8a9fc0df0e56058d56e8a0323f5ed08f/all_audio/13132229287_full_20180106133148_.wav", "channal_uuid": "3573a795-8174-4db9-b74d-d793fa0e43a4", "mark": "update"}'


2018-01-06 13:31:48,178 - LogUtils.py[line:112] - INFO: postgresql connect host .....   118.190.166.165
2018-01-06 13:31:48,221 - LogUtils.py[line:112] - INFO: postgresql connect.....closed!!!
2018-01-06 13:31:48,222 - LogUtils.py[line:112] - INFO: run_update_sql.....update fs_call set full_record_fpath ='/8a9fc0df0e56058d56e8a0323f5ed08f/all_audio/13132229287_full_20180106133148_.wav' where channal_uuid ='3573a795-8174-4db9-b74d-d793fa0e43a4'
2018-01-06 13:31:49,108 - LogUtils.py[line:112] - INFO:  [x] Received '{"jsonStr": "{\\"info\\": [{\\"is_flow_output\\": true, \\"output\\": \\"\\\\u5582\\\\uff0c\\\\u60a8\\\\u597d\\\\u3002\\", \\"node_text\\": \\"\\\\u95ee\\\\u5019\\\\u8bed\\", \\"flow_id\\": \\"505c426d2b8fbe8f8f5f18250c2f568f\\", \\"label\\": \\"\\", \\"session_end\\": false, \\"state\\": \\"\\", \\"node_id\\": -11, \\"output_resource\\": \\"t13.wav\\", \\"flow_end\\": false, \\"input\\": \\"\\\\u4f60\\\\u597d\\", \\"similarity\\": 1, \\"flow_title\\": \\"\\\\u5f00\\\\u573a\\\\u767d\\", \\"output_type\\": \\"path\\", \\"user_label\\": \\"\\\\u672a\\\\u77e5\\", \\"id\\": \\"505c426d2b8fbe8f8f5f18250c2f568f_-11\\"}], \\"successful\\": true, \\"message\\": \\"ok\\"}", "text": "\\u5582\\uff0c\\u60a8\\u597d\\u3002", "who": "bot", "create_at": "2018-01-06 13:31:48", "call_id": "22", "record_fpath": "/8a9fc0df0e56058d56e8a0323f5ed08f/bot_audio/t13.wav", "mark": "insert"}'


2018-01-06 13:31:49,108 - LogUtils.py[line:112] - INFO: postgresql connect host .....   118.190.166.165
2018-01-06 13:31:49,175 - LogUtils.py[line:120] - ERROR: runsql exception error insert or update on table "fs_call_replay" violates foreign key constraint "fs_call_replay_call_id_a2c15655_fk_fs_call_id"
DETAIL:  Key (call_id)=(22) is not present in table "fs_call".
 
2018-01-06 13:31:49,175 - LogUtils.py[line:112] - INFO: ******** run_insert_sql..*********...INSERT INTO fs_call_replay(who, text, record_fpath, create_at, call_id,resp_param)VALUES ('bot', '喂，您好。', '/8a9fc0df0e56058d56e8a0323f5ed08f/bot_audio/t13.wav', '2018-01-06 13:31:48', '22','{"info": [{"is_flow_output": true, "output": "\u5582\uff0c\u60a8\u597d\u3002", "node_text": "\u95ee\u5019\u8bed", "flow_id": "505c426d2b8fbe8f8f5f18250c2f568f", "label": "", "session_end": false, "state": "", "node_id": -11, "output_resource": "t13.wav", "flow_end": false, "input": "\u4f60\u597d", "similarity": 1, "flow_title": "\u5f00\u573a\u767d", "output_type": "path", "user_label": "\u672a\u77e5", "id": "505c426d2b8fbe8f8f5f18250c2f568f_-11"}], "successful": true, "message": "ok"}') RETURNING id
2018-01-06 13:31:51,808 - LogUtils.py[line:112] - INFO:  [x] Received '{"user_label": "\\u5f00\\u573a\\u6302\\u65ad", "channal_uuid": "3573a795-8174-4db9-b74d-d793fa0e43a4", "mark": "user_label"}'


2018-01-06 13:31:51,809 - LogUtils.py[line:112] - INFO: postgresql connect host .....   118.190.166.165
2018-01-06 13:31:51,851 - LogUtils.py[line:112] - INFO: postgresql connect.....closed!!!
2018-01-06 13:31:51,851 - LogUtils.py[line:112] - INFO:  run_update_sql.........user_label... update fs_call set cust_tag = '开场挂断' where channal_uuid ='3573a795-8174-4db9-b74d-d793fa0e43a4' 
2018-01-06 13:31:58,674 - LogUtils.py[line:112] - INFO:  [x] Received '{"jsonStr": "{\\"result\\": \\"\\\\u6492\\", \\"ret\\": 0}", "text": "\\u6492", "who": "human", "create_at": "2018-01-06 13:31:55", "call_id": "22", "record_fpath": "/8a9fc0df0e56058d56e8a0323f5ed08f/human_audio/13132229287_in_1_20180106133148.wav", "mark": "insert"}'


2018-01-06 13:31:58,674 - LogUtils.py[line:112] - INFO: postgresql connect host .....   118.190.166.165
2018-01-06 13:31:58,740 - LogUtils.py[line:120] - ERROR: runsql exception error insert or update on table "fs_call_replay" violates foreign key constraint "fs_call_replay_call_id_a2c15655_fk_fs_call_id"
DETAIL:  Key (call_id)=(22) is not present in table "fs_call".
 
2018-01-06 13:31:58,741 - LogUtils.py[line:112] - INFO: ******** run_insert_sql..*********...INSERT INTO fs_call_replay(who, text, record_fpath, create_at, call_id,resp_param)VALUES ('human', '撒', '/8a9fc0df0e56058d56e8a0323f5ed08f/human_audio/13132229287_in_1_20180106133148.wav', '2018-01-06 13:31:55', '22','{"result": "\u6492", "ret": 0}') RETURNING id
2018-01-06 13:32:04,168 - LogUtils.py[line:112] - INFO:  [x] Received '{"jsonStr": "{\\"info\\": [{\\"is_flow_output\\": true, \\"output\\": \\"\\\\u6211\\\\u4eec\\\\u662f\\\\u4e2d\\\\u5b89\\\\u4fe1\\\\u6210\\\\uff0c\\\\u4e13\\\\u4e1a\\\\u529e\\\\u7406\\\\u94f6\\\\u884c\\\\u8d37\\\\u6b3e\\\\u7684\\\\uff0c\\\\u8bf7\\\\u95ee\\\\u60a8\\\\u5927\\\\u6982\\\\u9700\\\\u8981\\\\u591a\\\\u5c11\\\\u91d1\\\\u989d\\\\u5462\\", \\"node_text\\": \\"\\\\u4f01\\\\u4e1a\\\\u4ecb\\\\u7ecd\\", \\"flow_id\\": \\"81f445b5cc3c92c5cdf3a1488a7c2eb7\\", \\"label\\": \\"\\\\u4f01\\\\u4e1a\\\\u4ecb\\\\u7ecd\\", \\"session_end\\": false, \\"state\\": \\"\\", \\"node_id\\": -11, \\"output_resource\\": \\"2.wav\\", \\"flow_end\\": false, \\"input\\": \\"\\\\u6492\\", \\"similarity\\": 1, \\"flow_title\\": \\"\\\\u516c\\\\u53f8\\\\u4ecb\\\\u7ecd\\", \\"output_type\\": \\"path\\", \\"user_label\\": \\"\\\\u5f00\\\\u573a\\\\u6302\\\\u65ad\\", \\"id\\": \\"81f445b5cc3c92c5cdf3a1488a7c2eb7_-11\\"}], \\"successful\\": true, \\"message\\": \\"ok\\"}", "text": "\\u6211\\u4eec\\u662f\\u4e2d\\u5b89\\u4fe1\\u6210\\uff0c\\u4e13\\u4e1a\\u529e\\u7406\\u94f6\\u884c\\u8d37\\u6b3e\\u7684\\uff0c\\u8bf7\\u95ee\\u60a8\\u5927\\u6982\\u9700\\u8981\\u591a\\u5c11\\u91d1\\u989d\\u5462", "who": "bot", "create_at": "2018-01-06 13:31:58", "call_id": "22", "record_fpath": "/8a9fc0df0e56058d56e8a0323f5ed08f/bot_audio/2.wav", "mark": "insert"}'


2018-01-06 13:32:04,169 - LogUtils.py[line:112] - INFO: postgresql connect host .....   118.190.166.165
2018-01-06 13:32:04,212 - LogUtils.py[line:120] - ERROR: runsql exception error insert or update on table "fs_call_replay" violates foreign key constraint "fs_call_replay_call_id_a2c15655_fk_fs_call_id"
DETAIL:  Key (call_id)=(22) is not present in table "fs_call".
 
2018-01-06 13:32:04,213 - LogUtils.py[line:112] - INFO: ******** run_insert_sql..*********...INSERT INTO fs_call_replay(who, text, record_fpath, create_at, call_id,resp_param)VALUES ('bot', '我们是中安信成，专业办理银行贷款的，请问您大概需要多少金额呢', '/8a9fc0df0e56058d56e8a0323f5ed08f/bot_audio/2.wav', '2018-01-06 13:31:58', '22','{"info": [{"is_flow_output": true, "output": "\u6211\u4eec\u662f\u4e2d\u5b89\u4fe1\u6210\uff0c\u4e13\u4e1a\u529e\u7406\u94f6\u884c\u8d37\u6b3e\u7684\uff0c\u8bf7\u95ee\u60a8\u5927\u6982\u9700\u8981\u591a\u5c11\u91d1\u989d\u5462", "node_text": "\u4f01\u4e1a\u4ecb\u7ecd", "flow_id": "81f445b5cc3c92c5cdf3a1488a7c2eb7", "label": "\u4f01\u4e1a\u4ecb\u7ecd", "session_end": false, "state": "", "node_id": -11, "output_resource": "2.wav", "flow_end": false, "input": "\u6492", "similarity": 1, "flow_title": "\u516c\u53f8\u4ecb\u7ecd", "output_type": "path", "user_label": "\u5f00\u573a\u6302\u65ad", "id": "81f445b5cc3c92c5cdf3a1488a7c2eb7_-11"}], "successful": true, "message": "ok"}') RETURNING id
2018-01-06 13:32:09,703 - LogUtils.py[line:112] - INFO:  [x] Received '{"user_label": "\\u5f00\\u573a\\u6302\\u65ad", "channal_uuid": "3573a795-8174-4db9-b74d-d793fa0e43a4", "mark": "user_label"}'


2018-01-06 13:32:09,704 - LogUtils.py[line:112] - INFO: postgresql connect host .....   118.190.166.165
2018-01-06 13:32:09,769 - LogUtils.py[line:112] - INFO: postgresql connect.....closed!!!
2018-01-06 13:32:09,769 - LogUtils.py[line:112] - INFO:  run_update_sql.........user_label... update fs_call set cust_tag = '开场挂断' where channal_uuid ='3573a795-8174-4db9-b74d-d793fa0e43a4' 
2018-01-06 13:32:13,581 - LogUtils.py[line:112] - INFO:  [x] Received '{"jsonStr": "{\\"result\\": \\"\\\\u6ca1\\\\u6709\\", \\"ret\\": 0}", "text": "\\u6ca1\\u6709", "who": "human", "create_at": "2018-01-06 13:32:11", "call_id": "22", "record_fpath": "/8a9fc0df0e56058d56e8a0323f5ed08f/human_audio/13132229287_in_3_20180106133148.wav", "mark": "insert"}'


2018-01-06 13:32:13,582 - LogUtils.py[line:112] - INFO: postgresql connect host .....   118.190.166.165
2018-01-06 13:32:13,625 - LogUtils.py[line:120] - ERROR: runsql exception error insert or update on table "fs_call_replay" violates foreign key constraint "fs_call_replay_call_id_a2c15655_fk_fs_call_id"
DETAIL:  Key (call_id)=(22) is not present in table "fs_call".
 
2018-01-06 13:32:13,626 - LogUtils.py[line:112] - INFO: ******** run_insert_sql..*********...INSERT INTO fs_call_replay(who, text, record_fpath, create_at, call_id,resp_param)VALUES ('human', '没有', '/8a9fc0df0e56058d56e8a0323f5ed08f/human_audio/13132229287_in_3_20180106133148.wav', '2018-01-06 13:32:11', '22','{"result": "\u6ca1\u6709", "ret": 0}') RETURNING id
2018-01-06 13:32:16,028 - LogUtils.py[line:112] - INFO:  [x] Received '{"jsonStr": "{\\"info\\": [{\\"is_flow_output\\": true, \\"output\\": \\"\\\\u90a3\\\\u60a8\\\\u76ee\\\\u524d\\\\u662f\\\\u81ea\\\\u5df1\\\\u5f00\\\\u516c\\\\u53f8\\\\u8fd8\\\\u662f\\\\u4e0a\\\\u73ed\\\\u7684\\\\uff1f\\", \\"node_text\\": \\"\\\\u95ee\\\\u98981\\", \\"flow_id\\": \\"ba8d69e98f71243574ab338537a7a1bd\\", \\"label\\": \\"\\\\u95ee\\\\u98981\\", \\"session_end\\": false, \\"state\\": \\"\\", \\"node_id\\": -25, \\"output_resource\\": \\"t6.wav\\", \\"flow_end\\": false, \\"input\\": \\"\\\\u6ca1\\\\u6709\\", \\"similarity\\": 0.8, \\"flow_title\\": \\"\\\\u4e86\\\\u89e3\\\\u60c5\\\\u51b5\\", \\"output_type\\": \\"path\\", \\"user_label\\": \\"\\\\u5f00\\\\u573a\\\\u6302\\\\u65ad\\", \\"id\\": \\"ba8d69e98f71243574ab338537a7a1bd_-25\\"}], \\"successful\\": true, \\"message\\": \\"ok\\"}", "text": "\\u90a3\\u60a8\\u76ee\\u524d\\u662f\\u81ea\\u5df1\\u5f00\\u516c\\u53f8\\u8fd8\\u662f\\u4e0a\\u73ed\\u7684\\uff1f", "who": "bot", "create_at": "2018-01-06 13:32:13", "call_id": "22", "record_fpath": "/8a9fc0df0e56058d56e8a0323f5ed08f/bot_audio/t6.wav", "mark": "insert"}'


2018-01-06 13:32:16,028 - LogUtils.py[line:112] - INFO: postgresql connect host .....   118.190.166.165
2018-01-06 13:32:16,094 - LogUtils.py[line:120] - ERROR: runsql exception error insert or update on table "fs_call_replay" violates foreign key constraint "fs_call_replay_call_id_a2c15655_fk_fs_call_id"
DETAIL:  Key (call_id)=(22) is not present in table "fs_call".
 
2018-01-06 13:32:16,095 - LogUtils.py[line:112] - INFO: ******** run_insert_sql..*********...INSERT INTO fs_call_replay(who, text, record_fpath, create_at, call_id,resp_param)VALUES ('bot', '那您目前是自己开公司还是上班的？', '/8a9fc0df0e56058d56e8a0323f5ed08f/bot_audio/t6.wav', '2018-01-06 13:32:13', '22','{"info": [{"is_flow_output": true, "output": "\u90a3\u60a8\u76ee\u524d\u662f\u81ea\u5df1\u5f00\u516c\u53f8\u8fd8\u662f\u4e0a\u73ed\u7684\uff1f", "node_text": "\u95ee\u98981", "flow_id": "ba8d69e98f71243574ab338537a7a1bd", "label": "\u95ee\u98981", "session_end": false, "state": "", "node_id": -25, "output_resource": "t6.wav", "flow_end": false, "input": "\u6ca1\u6709", "similarity": 0.8, "flow_title": "\u4e86\u89e3\u60c5\u51b5", "output_type": "path", "user_label": "\u5f00\u573a\u6302\u65ad", "id": "ba8d69e98f71243574ab338537a7a1bd_-25"}], "successful": true, "message": "ok"}') RETURNING id
2018-01-06 13:32:21,135 - LogUtils.py[line:112] - INFO:  [x] Received '{"user_label": "\\u5f00\\u573a\\u6302\\u65ad", "channal_uuid": "3573a795-8174-4db9-b74d-d793fa0e43a4", "mark": "user_label"}'


2018-01-06 13:32:21,135 - LogUtils.py[line:112] - INFO: postgresql connect host .....   118.190.166.165
2018-01-06 13:32:21,179 - LogUtils.py[line:112] - INFO: postgresql connect.....closed!!!
2018-01-06 13:32:21,179 - LogUtils.py[line:112] - INFO:  run_update_sql.........user_label... update fs_call set cust_tag = '开场挂断' where channal_uuid ='3573a795-8174-4db9-b74d-d793fa0e43a4' 
2018-01-06 13:32:23,316 - LogUtils.py[line:112] - INFO:  [x] Received '{"jsonStr": "{\\"result\\": \\"\\\\u5582\\", \\"ret\\": 0}", "text": "\\u5582", "who": "human", "create_at": "2018-01-06 13:32:21", "call_id": "22", "record_fpath": "/8a9fc0df0e56058d56e8a0323f5ed08f/human_audio/13132229287_in_5_20180106133148.wav", "mark": "insert"}'


2018-01-06 13:32:23,317 - LogUtils.py[line:112] - INFO: postgresql connect host .....   118.190.166.165
2018-01-06 13:32:23,383 - LogUtils.py[line:120] - ERROR: runsql exception error insert or update on table "fs_call_replay" violates foreign key constraint "fs_call_replay_call_id_a2c15655_fk_fs_call_id"
DETAIL:  Key (call_id)=(22) is not present in table "fs_call".
 
2018-01-06 13:32:23,383 - LogUtils.py[line:112] - INFO: ******** run_insert_sql..*********...INSERT INTO fs_call_replay(who, text, record_fpath, create_at, call_id,resp_param)VALUES ('human', '喂', '/8a9fc0df0e56058d56e8a0323f5ed08f/human_audio/13132229287_in_5_20180106133148.wav', '2018-01-06 13:32:21', '22','{"result": "\u5582", "ret": 0}') RETURNING id
2018-01-06 13:32:28,528 - LogUtils.py[line:112] - INFO:  [x] Received '{"jsonStr": "{\\"info\\": [{\\"is_flow_output\\": true, \\"output\\": \\"\\\\u597d\\\\u7684\\\\uff0c\\\\u6211\\\\u4eec\\\\u7ed9\\\\u60a8\\\\u505a\\\\u4e00\\\\u4e2a\\\\u9884\\\\u8bc4\\\\u4f30\\\\uff0c\\\\u7a0d\\\\u540e\\\\u4f1a\\\\u6709\\\\u4e13\\\\u4e1a\\\\u7684\\\\u878d\\\\u8d44\\\\u987e\\\\u95ee\\\\u8054\\\\u7cfb\\\\u60a8\\\\uff0c\\\\u53ef\\\\u4ee5\\\\u5417\\\\uff1f\\", \\"node_text\\": \\"\\\\u9080\\\\u7ea61\\", \\"flow_id\\": \\"bfbbb0cfab4aac3dba462ac2d805fca1\\", \\"label\\": \\"\\\\u9080\\\\u7ea61\\", \\"session_end\\": false, \\"state\\": \\"\\", \\"node_id\\": -11, \\"output_resource\\": \\"12.wav\\", \\"flow_end\\": false, \\"input\\": \\"\\\\u5582\\", \\"similarity\\": 1, \\"flow_title\\": \\"\\\\u9080\\\\u7ea6\\", \\"output_type\\": \\"path\\", \\"user_label\\": \\"\\\\u5f00\\\\u573a\\\\u6302\\\\u65ad\\", \\"id\\": \\"bfbbb0cfab4aac3dba462ac2d805fca1_-11\\"}], \\"successful\\": true, \\"message\\": \\"ok\\"}", "text": "\\u597d\\u7684\\uff0c\\u6211\\u4eec\\u7ed9\\u60a8\\u505a\\u4e00\\u4e2a\\u9884\\u8bc4\\u4f30\\uff0c\\u7a0d\\u540e\\u4f1a\\u6709\\u4e13\\u4e1a\\u7684\\u878d\\u8d44\\u987e\\u95ee\\u8054\\u7cfb\\u60a8\\uff0c\\u53ef\\u4ee5\\u5417\\uff1f", "who": "bot", "create_at": "2018-01-06 13:32:23", "call_id": "22", "record_fpath": "/8a9fc0df0e56058d56e8a0323f5ed08f/bot_audio/12.wav", "mark": "insert"}'


2018-01-06 13:32:28,529 - LogUtils.py[line:112] - INFO: postgresql connect host .....   118.190.166.165
2018-01-06 13:32:28,572 - LogUtils.py[line:120] - ERROR: runsql exception error insert or update on table "fs_call_replay" violates foreign key constraint "fs_call_replay_call_id_a2c15655_fk_fs_call_id"
DETAIL:  Key (call_id)=(22) is not present in table "fs_call".
 
2018-01-06 13:32:28,573 - LogUtils.py[line:112] - INFO: ******** run_insert_sql..*********...INSERT INTO fs_call_replay(who, text, record_fpath, create_at, call_id,resp_param)VALUES ('bot', '好的，我们给您做一个预评估，稍后会有专业的融资顾问联系您，可以吗？', '/8a9fc0df0e56058d56e8a0323f5ed08f/bot_audio/12.wav', '2018-01-06 13:32:23', '22','{"info": [{"is_flow_output": true, "output": "\u597d\u7684\uff0c\u6211\u4eec\u7ed9\u60a8\u505a\u4e00\u4e2a\u9884\u8bc4\u4f30\uff0c\u7a0d\u540e\u4f1a\u6709\u4e13\u4e1a\u7684\u878d\u8d44\u987e\u95ee\u8054\u7cfb\u60a8\uff0c\u53ef\u4ee5\u5417\uff1f", "node_text": "\u9080\u7ea61", "flow_id": "bfbbb0cfab4aac3dba462ac2d805fca1", "label": "\u9080\u7ea61", "session_end": false, "state": "", "node_id": -11, "output_resource": "12.wav", "flow_end": false, "input": "\u5582", "similarity": 1, "flow_title": "\u9080\u7ea6", "output_type": "path", "user_label": "\u5f00\u573a\u6302\u65ad", "id": "bfbbb0cfab4aac3dba462ac2d805fca1_-11"}], "successful": true, "message": "ok"}') RETURNING id
2018-01-06 13:32:30,961 - LogUtils.py[line:112] - INFO:  [x] Received '{"user_label": "\\u5f00\\u573a\\u6302\\u65ad", "channal_uuid": "3573a795-8174-4db9-b74d-d793fa0e43a4", "mark": "user_label"}'


2018-01-06 13:32:30,961 - LogUtils.py[line:112] - INFO: postgresql connect host .....   118.190.166.165
2018-01-06 13:32:31,027 - LogUtils.py[line:112] - INFO: postgresql connect.....closed!!!
2018-01-06 13:32:31,027 - LogUtils.py[line:112] - INFO:  run_update_sql.........user_label... update fs_call set cust_tag = '开场挂断' where channal_uuid ='3573a795-8174-4db9-b74d-d793fa0e43a4' 
2018-01-06 13:32:35,277 - LogUtils.py[line:112] - INFO:  [x] Received '{"user_id": "3", "task_id": "8", "number": "13132229287", "call_id": "22", "flow_id": "8a9fc0df0e56058d56e8a0323f5ed08f", "mark": "statistical"}'


2018-01-06 13:32:35,278 - LogUtils.py[line:112] - INFO: postgresql connect host .....   118.190.166.165
2018-01-06 13:32:35,322 - LogUtils.py[line:112] - INFO: postgresql connect.....closed!!!
2018-01-06 13:33:05,703 - LogUtils.py[line:112] - INFO:  [x] Received '{"user_label": "\\u672a\\u77e5", "channal_uuid": "4616d76e-5628-49a9-9797-828de5514661", "mark": "user_label"}'


2018-01-06 13:33:05,704 - LogUtils.py[line:112] - INFO: postgresql connect host .....   118.190.166.165
2018-01-06 13:33:05,769 - LogUtils.py[line:112] - INFO: postgresql connect.....closed!!!
2018-01-06 13:33:05,769 - LogUtils.py[line:112] - INFO:  run_update_sql.........user_label... update fs_call set cust_tag = '未知' where channal_uuid ='4616d76e-5628-49a9-9797-828de5514661' 
2018-01-06 13:33:11,494 - LogUtils.py[line:112] - INFO:  [x] Received '{"jsonStr": "{\\"result\\": \\"\\\\u5582\\\\u4f60\\\\u597d\\", \\"ret\\": 0}", "text": "\\u5582\\u4f60\\u597d", "who": "human", "create_at": "2018-01-06 13:33:06", "call_id": "23", "record_fpath": "/8a9fc0df0e56058d56e8a0323f5ed08f/human_audio/13512239772_in_0_20180106133305.wav", "mark": "insert"}'


2018-01-06 13:33:11,495 - LogUtils.py[line:112] - INFO: postgresql connect host .....   118.190.166.165
2018-01-06 13:33:11,538 - LogUtils.py[line:120] - ERROR: runsql exception error insert or update on table "fs_call_replay" violates foreign key constraint "fs_call_replay_call_id_a2c15655_fk_fs_call_id"
DETAIL:  Key (call_id)=(23) is not present in table "fs_call".
 
2018-01-06 13:33:11,538 - LogUtils.py[line:112] - INFO: ******** run_insert_sql..*********...INSERT INTO fs_call_replay(who, text, record_fpath, create_at, call_id,resp_param)VALUES ('human', '喂你好', '/8a9fc0df0e56058d56e8a0323f5ed08f/human_audio/13512239772_in_0_20180106133305.wav', '2018-01-06 13:33:06', '23','{"result": "\u5582\u4f60\u597d", "ret": 0}') RETURNING id
2018-01-06 13:33:15,557 - LogUtils.py[line:112] - INFO:  [x] Received '{"jsonStr": "{\\"info\\": [{\\"is_flow_output\\": true, \\"output\\": \\"\\\\u60a8\\\\u597d\\\\uff0c\\\\u6211\\\\u4eec\\\\u662f\\\\u529e\\\\u7406\\\\u8d37\\\\u6b3e\\\\u7684\\\\uff0c\\\\u8bf7\\\\u95ee\\\\u60a8\\\\u6709\\\\u8d44\\\\u91d1\\\\u4e0a\\\\u7684\\\\u9700\\\\u6c42\\\\u5417\\\\uff1f\\", \\"node_text\\": \\"\\\\u8bed\\\\u6599\\\\u8282\\\\u70b9\\", \\"flow_id\\": \\"505c426d2b8fbe8f8f5f18250c2f568f\\", \\"label\\": \\"\\\\u5f00\\\\u573a\\\\u767d\\", \\"session_end\\": false, \\"state\\": \\"\\", \\"node_id\\": -3, \\"output_resource\\": \\"7.wav\\", \\"flow_end\\": false, \\"input\\": \\"\\\\u5582\\\\u4f60\\\\u597d\\", \\"similarity\\": 1, \\"flow_title\\": \\"\\\\u5f00\\\\u573a\\\\u767d\\", \\"output_type\\": \\"path\\", \\"user_label\\": \\"\\\\u5f00\\\\u573a\\\\u6302\\\\u65ad\\", \\"id\\": \\"505c426d2b8fbe8f8f5f18250c2f568f_-3\\"}], \\"successful\\": true, \\"message\\": \\"ok\\"}", "text": "\\u60a8\\u597d\\uff0c\\u6211\\u4eec\\u662f\\u529e\\u7406\\u8d37\\u6b3e\\u7684\\uff0c\\u8bf7\\u95ee\\u60a8\\u6709\\u8d44\\u91d1\\u4e0a\\u7684\\u9700\\u6c42\\u5417\\uff1f", "who": "bot", "create_at": "2018-01-06 13:33:11", "call_id": "23", "record_fpath": "/8a9fc0df0e56058d56e8a0323f5ed08f/bot_audio/7.wav", "mark": "insert"}'


2018-01-06 13:33:15,557 - LogUtils.py[line:112] - INFO: postgresql connect host .....   118.190.166.165
2018-01-06 13:33:15,624 - LogUtils.py[line:120] - ERROR: runsql exception error insert or update on table "fs_call_replay" violates foreign key constraint "fs_call_replay_call_id_a2c15655_fk_fs_call_id"
DETAIL:  Key (call_id)=(23) is not present in table "fs_call".
 
2018-01-06 13:33:15,624 - LogUtils.py[line:112] - INFO: ******** run_insert_sql..*********...INSERT INTO fs_call_replay(who, text, record_fpath, create_at, call_id,resp_param)VALUES ('bot', '您好，我们是办理贷款的，请问您有资金上的需求吗？', '/8a9fc0df0e56058d56e8a0323f5ed08f/bot_audio/7.wav', '2018-01-06 13:33:11', '23','{"info": [{"is_flow_output": true, "output": "\u60a8\u597d\uff0c\u6211\u4eec\u662f\u529e\u7406\u8d37\u6b3e\u7684\uff0c\u8bf7\u95ee\u60a8\u6709\u8d44\u91d1\u4e0a\u7684\u9700\u6c42\u5417\uff1f", "node_text": "\u8bed\u6599\u8282\u70b9", "flow_id": "505c426d2b8fbe8f8f5f18250c2f568f", "label": "\u5f00\u573a\u767d", "session_end": false, "state": "", "node_id": -3, "output_resource": "7.wav", "flow_end": false, "input": "\u5582\u4f60\u597d", "similarity": 1, "flow_title": "\u5f00\u573a\u767d", "output_type": "path", "user_label": "\u5f00\u573a\u6302\u65ad", "id": "505c426d2b8fbe8f8f5f18250c2f568f_-3"}], "successful": true, "message": "ok"}') RETURNING id
2018-01-06 13:33:18,478 - LogUtils.py[line:112] - INFO:  [x] Received '{"user_label": "\\u5f00\\u573a\\u6302\\u65ad", "channal_uuid": "4616d76e-5628-49a9-9797-828de5514661", "mark": "user_label"}'


2018-01-06 13:33:18,479 - LogUtils.py[line:112] - INFO: postgresql connect host .....   118.190.166.165
2018-01-06 13:33:18,522 - LogUtils.py[line:112] - INFO: postgresql connect.....closed!!!
2018-01-06 13:33:18,522 - LogUtils.py[line:112] - INFO:  run_update_sql.........user_label... update fs_call set cust_tag = '开场挂断' where channal_uuid ='4616d76e-5628-49a9-9797-828de5514661' 
2018-01-06 13:33:24,663 - LogUtils.py[line:112] - INFO:  [x] Received '{"jsonStr": "{\\"result\\": \\"\\\\u55ef\\", \\"ret\\": 0}", "text": "\\u55ef", "who": "human", "create_at": "2018-01-06 13:33:23", "call_id": "23", "record_fpath": "/8a9fc0df0e56058d56e8a0323f5ed08f/human_audio/13512239772_in_2_20180106133305.wav", "mark": "insert"}'


2018-01-06 13:33:24,663 - LogUtils.py[line:112] - INFO: postgresql connect host .....   118.190.166.165
2018-01-06 13:33:24,730 - LogUtils.py[line:120] - ERROR: runsql exception error insert or update on table "fs_call_replay" violates foreign key constraint "fs_call_replay_call_id_a2c15655_fk_fs_call_id"
DETAIL:  Key (call_id)=(23) is not present in table "fs_call".
 
2018-01-06 13:33:24,731 - LogUtils.py[line:112] - INFO: ******** run_insert_sql..*********...INSERT INTO fs_call_replay(who, text, record_fpath, create_at, call_id,resp_param)VALUES ('human', '嗯', '/8a9fc0df0e56058d56e8a0323f5ed08f/human_audio/13512239772_in_2_20180106133305.wav', '2018-01-06 13:33:23', '23','{"result": "\u55ef", "ret": 0}') RETURNING id
2018-01-06 13:33:26,480 - LogUtils.py[line:112] - INFO:  [x] Received '{"jsonStr": "{\\"info\\": [{\\"is_flow_output\\": true, \\"output\\": \\"\\\\u8bf7\\\\u95ee\\\\u60a8\\\\u5728\\\\u5317\\\\u4eac\\\\u6709\\\\u623f\\\\u5417\\\\uff1f\\", \\"node_text\\": \\"\\\\u95ee\\\\u98987\\", \\"flow_id\\": \\"ba8d69e98f71243574ab338537a7a1bd\\", \\"label\\": \\"\\\\u95ee\\\\u98987\\", \\"session_end\\": false, \\"state\\": \\"\\", \\"node_id\\": -23, \\"output_resource\\": \\"3.wav\\", \\"flow_end\\": false, \\"input\\": \\"\\\\u55ef\\", \\"similarity\\": 1, \\"flow_title\\": \\"\\\\u4e86\\\\u89e3\\\\u60c5\\\\u51b5\\", \\"output_type\\": \\"path\\", \\"user_label\\": \\"\\\\u5f00\\\\u573a\\\\u6302\\\\u65ad\\", \\"id\\": \\"ba8d69e98f71243574ab338537a7a1bd_-23\\"}], \\"successful\\": true, \\"message\\": \\"ok\\"}", "text": "\\u8bf7\\u95ee\\u60a8\\u5728\\u5317\\u4eac\\u6709\\u623f\\u5417\\uff1f", "who": "bot", "create_at": "2018-01-06 13:33:24", "call_id": "23", "record_fpath": "/8a9fc0df0e56058d56e8a0323f5ed08f/bot_audio/3.wav", "mark": "insert"}'


2018-01-06 13:33:26,480 - LogUtils.py[line:112] - INFO: postgresql connect host .....   118.190.166.165
2018-01-06 13:33:26,524 - LogUtils.py[line:120] - ERROR: runsql exception error insert or update on table "fs_call_replay" violates foreign key constraint "fs_call_replay_call_id_a2c15655_fk_fs_call_id"
DETAIL:  Key (call_id)=(23) is not present in table "fs_call".
 
2018-01-06 13:33:26,524 - LogUtils.py[line:112] - INFO: ******** run_insert_sql..*********...INSERT INTO fs_call_replay(who, text, record_fpath, create_at, call_id,resp_param)VALUES ('bot', '请问您在北京有房吗？', '/8a9fc0df0e56058d56e8a0323f5ed08f/bot_audio/3.wav', '2018-01-06 13:33:24', '23','{"info": [{"is_flow_output": true, "output": "\u8bf7\u95ee\u60a8\u5728\u5317\u4eac\u6709\u623f\u5417\uff1f", "node_text": "\u95ee\u98987", "flow_id": "ba8d69e98f71243574ab338537a7a1bd", "label": "\u95ee\u98987", "session_end": false, "state": "", "node_id": -23, "output_resource": "3.wav", "flow_end": false, "input": "\u55ef", "similarity": 1, "flow_title": "\u4e86\u89e3\u60c5\u51b5", "output_type": "path", "user_label": "\u5f00\u573a\u6302\u65ad", "id": "ba8d69e98f71243574ab338537a7a1bd_-23"}], "successful": true, "message": "ok"}') RETURNING id
2018-01-06 13:33:29,364 - LogUtils.py[line:112] - INFO:  [x] Received '{"user_label": "\\u4e2a\\u4eba\\u62b5\\u62bc\\u8d37\\u6b3e", "channal_uuid": "4616d76e-5628-49a9-9797-828de5514661", "mark": "user_label"}'


2018-01-06 13:33:29,364 - LogUtils.py[line:112] - INFO: postgresql connect host .....   118.190.166.165
2018-01-06 13:33:29,428 - LogUtils.py[line:112] - INFO: postgresql connect.....closed!!!
2018-01-06 13:33:29,428 - LogUtils.py[line:112] - INFO:  run_update_sql.........user_label... update fs_call set cust_tag = '个人抵押贷款' where channal_uuid ='4616d76e-5628-49a9-9797-828de5514661' 
2018-01-06 13:33:35,461 - LogUtils.py[line:112] - INFO:  [x] Received '{"jsonStr": "{\\"result\\": \\"\\\\u6211\\\\u6ca1\\\\u6709\\\\u53d1\\\\u6211\\\\u6ca1\\\\u6709\\\\u65b9\\", \\"ret\\": 0}", "text": "\\u6211\\u6ca1\\u6709\\u53d1\\u6211\\u6ca1\\u6709\\u65b9", "who": "human", "create_at": "2018-01-06 13:33:32", "call_id": "23", "record_fpath": "/8a9fc0df0e56058d56e8a0323f5ed08f/human_audio/13512239772_in_4_20180106133305.wav", "mark": "insert"}'


2018-01-06 13:33:35,461 - LogUtils.py[line:112] - INFO: postgresql connect host .....   118.190.166.165
2018-01-06 13:33:35,505 - LogUtils.py[line:120] - ERROR: runsql exception error insert or update on table "fs_call_replay" violates foreign key constraint "fs_call_replay_call_id_a2c15655_fk_fs_call_id"
DETAIL:  Key (call_id)=(23) is not present in table "fs_call".
 
2018-01-06 13:33:35,505 - LogUtils.py[line:112] - INFO: ******** run_insert_sql..*********...INSERT INTO fs_call_replay(who, text, record_fpath, create_at, call_id,resp_param)VALUES ('human', '我没有发我没有方', '/8a9fc0df0e56058d56e8a0323f5ed08f/human_audio/13512239772_in_4_20180106133305.wav', '2018-01-06 13:33:32', '23','{"result": "\u6211\u6ca1\u6709\u53d1\u6211\u6ca1\u6709\u65b9", "ret": 0}') RETURNING id
2018-01-06 13:33:40,658 - LogUtils.py[line:112] - INFO:  [x] Received '{"jsonStr": "{\\"info\\": [{\\"is_flow_output\\": true, \\"output\\": \\"\\\\u597d\\\\u7684\\\\uff0c\\\\u6211\\\\u4eec\\\\u7ed9\\\\u60a8\\\\u505a\\\\u4e00\\\\u4e2a\\\\u9884\\\\u8bc4\\\\u4f30\\\\uff0c\\\\u7a0d\\\\u540e\\\\u4f1a\\\\u6709\\\\u4e13\\\\u4e1a\\\\u7684\\\\u878d\\\\u8d44\\\\u987e\\\\u95ee\\\\u8054\\\\u7cfb\\\\u60a8\\\\uff0c\\\\u53ef\\\\u4ee5\\\\u5417\\\\uff1f\\", \\"node_text\\": \\"\\\\u9080\\\\u7ea61\\", \\"flow_id\\": \\"bfbbb0cfab4aac3dba462ac2d805fca1\\", \\"label\\": \\"\\\\u9080\\\\u7ea61\\", \\"session_end\\": false, \\"state\\": \\"\\", \\"node_id\\": -11, \\"output_resource\\": \\"12.wav\\", \\"flow_end\\": false, \\"input\\": \\"\\\\u6211\\\\u6ca1\\\\u6709\\\\u53d1\\\\u6211\\\\u6ca1\\\\u6709\\\\u65b9\\", \\"similarity\\": 1, \\"flow_title\\": \\"\\\\u9080\\\\u7ea6\\", \\"output_type\\": \\"path\\", \\"user_label\\": \\"\\\\u4e2a\\\\u4eba\\\\u62b5\\\\u62bc\\\\u8d37\\\\u6b3e\\", \\"id\\": \\"bfbbb0cfab4aac3dba462ac2d805fca1_-11\\"}], \\"successful\\": true, \\"message\\": \\"ok\\"}", "text": "\\u597d\\u7684\\uff0c\\u6211\\u4eec\\u7ed9\\u60a8\\u505a\\u4e00\\u4e2a\\u9884\\u8bc4\\u4f30\\uff0c\\u7a0d\\u540e\\u4f1a\\u6709\\u4e13\\u4e1a\\u7684\\u878d\\u8d44\\u987e\\u95ee\\u8054\\u7cfb\\u60a8\\uff0c\\u53ef\\u4ee5\\u5417\\uff1f", "who": "bot", "create_at": "2018-01-06 13:33:35", "call_id": "23", "record_fpath": "/8a9fc0df0e56058d56e8a0323f5ed08f/bot_audio/12.wav", "mark": "insert"}'


2018-01-06 13:33:40,658 - LogUtils.py[line:112] - INFO: postgresql connect host .....   118.190.166.165
2018-01-06 13:33:40,724 - LogUtils.py[line:120] - ERROR: runsql exception error insert or update on table "fs_call_replay" violates foreign key constraint "fs_call_replay_call_id_a2c15655_fk_fs_call_id"
DETAIL:  Key (call_id)=(23) is not present in table "fs_call".
 
2018-01-06 13:33:40,725 - LogUtils.py[line:112] - INFO: ******** run_insert_sql..*********...INSERT INTO fs_call_replay(who, text, record_fpath, create_at, call_id,resp_param)VALUES ('bot', '好的，我们给您做一个预评估，稍后会有专业的融资顾问联系您，可以吗？', '/8a9fc0df0e56058d56e8a0323f5ed08f/bot_audio/12.wav', '2018-01-06 13:33:35', '23','{"info": [{"is_flow_output": true, "output": "\u597d\u7684\uff0c\u6211\u4eec\u7ed9\u60a8\u505a\u4e00\u4e2a\u9884\u8bc4\u4f30\uff0c\u7a0d\u540e\u4f1a\u6709\u4e13\u4e1a\u7684\u878d\u8d44\u987e\u95ee\u8054\u7cfb\u60a8\uff0c\u53ef\u4ee5\u5417\uff1f", "node_text": "\u9080\u7ea61", "flow_id": "bfbbb0cfab4aac3dba462ac2d805fca1", "label": "\u9080\u7ea61", "session_end": false, "state": "", "node_id": -11, "output_resource": "12.wav", "flow_end": false, "input": "\u6211\u6ca1\u6709\u53d1\u6211\u6ca1\u6709\u65b9", "similarity": 1, "flow_title": "\u9080\u7ea6", "output_type": "path", "user_label": "\u4e2a\u4eba\u62b5\u62bc\u8d37\u6b3e", "id": "bfbbb0cfab4aac3dba462ac2d805fca1_-11"}], "successful": true, "message": "ok"}') RETURNING id
2018-01-06 13:33:43,383 - LogUtils.py[line:112] - INFO:  [x] Received '{"user_label": "\\u4e2a\\u4eba\\u62b5\\u62bc\\u8d37\\u6b3e", "channal_uuid": "4616d76e-5628-49a9-9797-828de5514661", "mark": "user_label"}'


2018-01-06 13:33:43,383 - LogUtils.py[line:112] - INFO: postgresql connect host .....   118.190.166.165
2018-01-06 13:33:43,426 - LogUtils.py[line:112] - INFO: postgresql connect.....closed!!!
2018-01-06 13:33:43,427 - LogUtils.py[line:112] - INFO:  run_update_sql.........user_label... update fs_call set cust_tag = '个人抵押贷款' where channal_uuid ='4616d76e-5628-49a9-9797-828de5514661' 
2018-01-06 13:33:47,685 - LogUtils.py[line:112] - INFO:  [x] Received '{"user_id": "3", "task_id": "8", "number": "13512239772", "call_id": "23", "flow_id": "8a9fc0df0e56058d56e8a0323f5ed08f", "mark": "statistical"}'


2018-01-06 13:33:47,686 - LogUtils.py[line:112] - INFO: postgresql connect host .....   118.190.166.165
2018-01-06 13:33:47,750 - LogUtils.py[line:112] - INFO: postgresql connect.....closed!!!
2018-01-06 13:34:09,546 - LogUtils.py[line:112] - INFO:  [x] Received '{"user_label": "\\u672a\\u77e5", "channal_uuid": "d3af5c17-2643-44e3-8588-0603b8140ac1", "mark": "user_label"}'


2018-01-06 13:34:09,546 - LogUtils.py[line:112] - INFO: postgresql connect host .....   118.190.166.165
2018-01-06 13:34:09,589 - LogUtils.py[line:112] - INFO: postgresql connect.....closed!!!
2018-01-06 13:34:09,589 - LogUtils.py[line:112] - INFO:  run_update_sql.........user_label... update fs_call set cust_tag = '未知' where channal_uuid ='d3af5c17-2643-44e3-8588-0603b8140ac1' 
2018-01-06 13:34:12,886 - LogUtils.py[line:112] - INFO:  [x] Received '{"jsonStr": "{\\"result\\": \\"\\\\u54ce\\\\u4f60\\\\u597d\\", \\"ret\\": 0}", "text": "\\u54ce\\u4f60\\u597d", "who": "human", "create_at": "2018-01-06 13:34:10", "call_id": "24", "record_fpath": "/8a9fc0df0e56058d56e8a0323f5ed08f/human_audio/15900282168_in_0_20180106133409.wav", "mark": "insert"}'


2018-01-06 13:34:12,886 - LogUtils.py[line:112] - INFO: postgresql connect host .....   118.190.166.165
2018-01-06 13:34:12,952 - LogUtils.py[line:120] - ERROR: runsql exception error insert or update on table "fs_call_replay" violates foreign key constraint "fs_call_replay_call_id_a2c15655_fk_fs_call_id"
DETAIL:  Key (call_id)=(24) is not present in table "fs_call".
 
2018-01-06 13:34:12,952 - LogUtils.py[line:112] - INFO: ******** run_insert_sql..*********...INSERT INTO fs_call_replay(who, text, record_fpath, create_at, call_id,resp_param)VALUES ('human', '哎你好', '/8a9fc0df0e56058d56e8a0323f5ed08f/human_audio/15900282168_in_0_20180106133409.wav', '2018-01-06 13:34:10', '24','{"result": "\u54ce\u4f60\u597d", "ret": 0}') RETURNING id
2018-01-06 13:34:16,941 - LogUtils.py[line:112] - INFO:  [x] Received '{"jsonStr": "{\\"info\\": [{\\"is_flow_output\\": true, \\"output\\": \\"\\\\u60a8\\\\u597d\\\\uff0c\\\\u6211\\\\u4eec\\\\u662f\\\\u529e\\\\u7406\\\\u8d37\\\\u6b3e\\\\u7684\\\\uff0c\\\\u8bf7\\\\u95ee\\\\u60a8\\\\u6709\\\\u8d44\\\\u91d1\\\\u4e0a\\\\u7684\\\\u9700\\\\u6c42\\\\u5417\\\\uff1f\\", \\"node_text\\": \\"\\\\u8bed\\\\u6599\\\\u8282\\\\u70b9\\", \\"flow_id\\": \\"505c426d2b8fbe8f8f5f18250c2f568f\\", \\"label\\": \\"\\\\u5f00\\\\u573a\\\\u767d\\", \\"session_end\\": false, \\"state\\": \\"\\", \\"node_id\\": -3, \\"output_resource\\": \\"7.wav\\", \\"flow_end\\": false, \\"input\\": \\"\\\\u54ce\\\\u4f60\\\\u597d\\", \\"similarity\\": 1, \\"flow_title\\": \\"\\\\u5f00\\\\u573a\\\\u767d\\", \\"output_type\\": \\"path\\", \\"user_label\\": \\"\\\\u5f00\\\\u573a\\\\u6302\\\\u65ad\\", \\"id\\": \\"505c426d2b8fbe8f8f5f18250c2f568f_-3\\"}], \\"successful\\": true, \\"message\\": \\"ok\\"}", "text": "\\u60a8\\u597d\\uff0c\\u6211\\u4eec\\u662f\\u529e\\u7406\\u8d37\\u6b3e\\u7684\\uff0c\\u8bf7\\u95ee\\u60a8\\u6709\\u8d44\\u91d1\\u4e0a\\u7684\\u9700\\u6c42\\u5417\\uff1f", "who": "bot", "create_at": "2018-01-06 13:34:12", "call_id": "24", "record_fpath": "/8a9fc0df0e56058d56e8a0323f5ed08f/bot_audio/7.wav", "mark": "insert"}'


2018-01-06 13:34:16,941 - LogUtils.py[line:112] - INFO: postgresql connect host .....   118.190.166.165
2018-01-06 13:34:16,986 - LogUtils.py[line:120] - ERROR: runsql exception error insert or update on table "fs_call_replay" violates foreign key constraint "fs_call_replay_call_id_a2c15655_fk_fs_call_id"
DETAIL:  Key (call_id)=(24) is not present in table "fs_call".
 
2018-01-06 13:34:16,986 - LogUtils.py[line:112] - INFO: ******** run_insert_sql..*********...INSERT INTO fs_call_replay(who, text, record_fpath, create_at, call_id,resp_param)VALUES ('bot', '您好，我们是办理贷款的，请问您有资金上的需求吗？', '/8a9fc0df0e56058d56e8a0323f5ed08f/bot_audio/7.wav', '2018-01-06 13:34:12', '24','{"info": [{"is_flow_output": true, "output": "\u60a8\u597d\uff0c\u6211\u4eec\u662f\u529e\u7406\u8d37\u6b3e\u7684\uff0c\u8bf7\u95ee\u60a8\u6709\u8d44\u91d1\u4e0a\u7684\u9700\u6c42\u5417\uff1f", "node_text": "\u8bed\u6599\u8282\u70b9", "flow_id": "505c426d2b8fbe8f8f5f18250c2f568f", "label": "\u5f00\u573a\u767d", "session_end": false, "state": "", "node_id": -3, "output_resource": "7.wav", "flow_end": false, "input": "\u54ce\u4f60\u597d", "similarity": 1, "flow_title": "\u5f00\u573a\u767d", "output_type": "path", "user_label": "\u5f00\u573a\u6302\u65ad", "id": "505c426d2b8fbe8f8f5f18250c2f568f_-3"}], "successful": true, "message": "ok"}') RETURNING id
2018-01-06 13:34:19,922 - LogUtils.py[line:112] - INFO:  [x] Received '{"user_label": "\\u5f00\\u573a\\u6302\\u65ad", "channal_uuid": "d3af5c17-2643-44e3-8588-0603b8140ac1", "mark": "user_label"}'


2018-01-06 13:34:19,923 - LogUtils.py[line:112] - INFO: postgresql connect host .....   118.190.166.165
2018-01-06 13:34:19,988 - LogUtils.py[line:112] - INFO: postgresql connect.....closed!!!
2018-01-06 13:34:19,988 - LogUtils.py[line:112] - INFO:  run_update_sql.........user_label... update fs_call set cust_tag = '开场挂断' where channal_uuid ='d3af5c17-2643-44e3-8588-0603b8140ac1' 
2018-01-06 13:34:28,092 - LogUtils.py[line:112] - INFO:  [x] Received '{"jsonStr": "{\\"result\\": \\"\\\\u8bb2\\\\u4e70\\\\u623f\\", \\"ret\\": 0}", "text": "\\u8bb2\\u4e70\\u623f", "who": "human", "create_at": "2018-01-06 13:34:25", "call_id": "24", "record_fpath": "/8a9fc0df0e56058d56e8a0323f5ed08f/human_audio/15900282168_in_2_20180106133409.wav", "mark": "insert"}'


2018-01-06 13:34:28,092 - LogUtils.py[line:112] - INFO: postgresql connect host .....   118.190.166.165
2018-01-06 13:34:28,135 - LogUtils.py[line:120] - ERROR: runsql exception error insert or update on table "fs_call_replay" violates foreign key constraint "fs_call_replay_call_id_a2c15655_fk_fs_call_id"
DETAIL:  Key (call_id)=(24) is not present in table "fs_call".
 
2018-01-06 13:34:28,136 - LogUtils.py[line:112] - INFO: ******** run_insert_sql..*********...INSERT INTO fs_call_replay(who, text, record_fpath, create_at, call_id,resp_param)VALUES ('human', '讲买房', '/8a9fc0df0e56058d56e8a0323f5ed08f/human_audio/15900282168_in_2_20180106133409.wav', '2018-01-06 13:34:25', '24','{"result": "\u8bb2\u4e70\u623f", "ret": 0}') RETURNING id
2018-01-06 13:34:29,920 - LogUtils.py[line:112] - INFO:  [x] Received '{"jsonStr": "{\\"info\\": [{\\"is_flow_output\\": true, \\"output\\": \\"\\\\u8bf7\\\\u95ee\\\\u60a8\\\\u5728\\\\u5317\\\\u4eac\\\\u6709\\\\u623f\\\\u5417\\\\uff1f\\", \\"node_text\\": \\"\\\\u95ee\\\\u98987\\", \\"flow_id\\": \\"ba8d69e98f71243574ab338537a7a1bd\\", \\"label\\": \\"\\\\u95ee\\\\u98987\\", \\"session_end\\": false, \\"state\\": \\"\\", \\"node_id\\": -23, \\"output_resource\\": \\"3.wav\\", \\"flow_end\\": false, \\"input\\": \\"\\\\u8bb2\\\\u4e70\\\\u623f\\", \\"similarity\\": 1, \\"flow_title\\": \\"\\\\u4e86\\\\u89e3\\\\u60c5\\\\u51b5\\", \\"output_type\\": \\"path\\", \\"user_label\\": \\"\\\\u5f00\\\\u573a\\\\u6302\\\\u65ad\\", \\"id\\": \\"ba8d69e98f71243574ab338537a7a1bd_-23\\"}], \\"successful\\": true, \\"message\\": \\"ok\\"}", "text": "\\u8bf7\\u95ee\\u60a8\\u5728\\u5317\\u4eac\\u6709\\u623f\\u5417\\uff1f", "who": "bot", "create_at": "2018-01-06 13:34:28", "call_id": "24", "record_fpath": "/8a9fc0df0e56058d56e8a0323f5ed08f/bot_audio/3.wav", "mark": "insert"}'


2018-01-06 13:34:29,920 - LogUtils.py[line:112] - INFO: postgresql connect host .....   118.190.166.165
2018-01-06 13:34:29,987 - LogUtils.py[line:120] - ERROR: runsql exception error insert or update on table "fs_call_replay" violates foreign key constraint "fs_call_replay_call_id_a2c15655_fk_fs_call_id"
DETAIL:  Key (call_id)=(24) is not present in table "fs_call".
 
2018-01-06 13:34:29,987 - LogUtils.py[line:112] - INFO: ******** run_insert_sql..*********...INSERT INTO fs_call_replay(who, text, record_fpath, create_at, call_id,resp_param)VALUES ('bot', '请问您在北京有房吗？', '/8a9fc0df0e56058d56e8a0323f5ed08f/bot_audio/3.wav', '2018-01-06 13:34:28', '24','{"info": [{"is_flow_output": true, "output": "\u8bf7\u95ee\u60a8\u5728\u5317\u4eac\u6709\u623f\u5417\uff1f", "node_text": "\u95ee\u98987", "flow_id": "ba8d69e98f71243574ab338537a7a1bd", "label": "\u95ee\u98987", "session_end": false, "state": "", "node_id": -23, "output_resource": "3.wav", "flow_end": false, "input": "\u8bb2\u4e70\u623f", "similarity": 1, "flow_title": "\u4e86\u89e3\u60c5\u51b5", "output_type": "path", "user_label": "\u5f00\u573a\u6302\u65ad", "id": "ba8d69e98f71243574ab338537a7a1bd_-23"}], "successful": true, "message": "ok"}') RETURNING id
2018-01-06 13:34:33,029 - LogUtils.py[line:112] - INFO:  [x] Received '{"user_label": "\\u4e2a\\u4eba\\u62b5\\u62bc\\u8d37\\u6b3e", "channal_uuid": "d3af5c17-2643-44e3-8588-0603b8140ac1", "mark": "user_label"}'


2018-01-06 13:34:33,030 - LogUtils.py[line:112] - INFO: postgresql connect host .....   118.190.166.165
2018-01-06 13:34:33,073 - LogUtils.py[line:112] - INFO: postgresql connect.....closed!!!
2018-01-06 13:34:33,073 - LogUtils.py[line:112] - INFO:  run_update_sql.........user_label... update fs_call set cust_tag = '个人抵押贷款' where channal_uuid ='d3af5c17-2643-44e3-8588-0603b8140ac1' 
2018-01-06 13:34:37,485 - LogUtils.py[line:112] - INFO:  [x] Received '{"jsonStr": "{\\"result\\": \\"\\\\u554a\\", \\"ret\\": 0}", "text": "\\u554a", "who": "human", "create_at": "2018-01-06 13:34:36", "call_id": "24", "record_fpath": "/8a9fc0df0e56058d56e8a0323f5ed08f/human_audio/15900282168_in_4_20180106133409.wav", "mark": "insert"}'


2018-01-06 13:34:37,485 - LogUtils.py[line:112] - INFO: postgresql connect host .....   118.190.166.165
2018-01-06 13:34:37,551 - LogUtils.py[line:120] - ERROR: runsql exception error insert or update on table "fs_call_replay" violates foreign key constraint "fs_call_replay_call_id_a2c15655_fk_fs_call_id"
DETAIL:  Key (call_id)=(24) is not present in table "fs_call".
 
2018-01-06 13:34:37,552 - LogUtils.py[line:112] - INFO: ******** run_insert_sql..*********...INSERT INTO fs_call_replay(who, text, record_fpath, create_at, call_id,resp_param)VALUES ('human', '啊', '/8a9fc0df0e56058d56e8a0323f5ed08f/human_audio/15900282168_in_4_20180106133409.wav', '2018-01-06 13:34:36', '24','{"result": "\u554a", "ret": 0}') RETURNING id
2018-01-06 13:34:42,678 - LogUtils.py[line:112] - INFO:  [x] Received '{"jsonStr": "{\\"info\\": [{\\"is_flow_output\\": true, \\"output\\": \\"\\\\u597d\\\\u7684\\\\uff0c\\\\u6211\\\\u4eec\\\\u7ed9\\\\u60a8\\\\u505a\\\\u4e00\\\\u4e2a\\\\u9884\\\\u8bc4\\\\u4f30\\\\uff0c\\\\u7a0d\\\\u540e\\\\u4f1a\\\\u6709\\\\u4e13\\\\u4e1a\\\\u7684\\\\u878d\\\\u8d44\\\\u987e\\\\u95ee\\\\u8054\\\\u7cfb\\\\u60a8\\\\uff0c\\\\u53ef\\\\u4ee5\\\\u5417\\\\uff1f\\", \\"node_text\\": \\"\\\\u9080\\\\u7ea61\\", \\"flow_id\\": \\"bfbbb0cfab4aac3dba462ac2d805fca1\\", \\"label\\": \\"\\\\u9080\\\\u7ea61\\", \\"session_end\\": false, \\"state\\": \\"\\", \\"node_id\\": -11, \\"output_resource\\": \\"12.wav\\", \\"flow_end\\": false, \\"input\\": \\"\\\\u554a\\", \\"similarity\\": 1, \\"flow_title\\": \\"\\\\u9080\\\\u7ea6\\", \\"output_type\\": \\"path\\", \\"user_label\\": \\"\\\\u4e2a\\\\u4eba\\\\u62b5\\\\u62bc\\\\u8d37\\\\u6b3e\\", \\"id\\": \\"bfbbb0cfab4aac3dba462ac2d805fca1_-11\\"}], \\"successful\\": true, \\"message\\": \\"ok\\"}", "text": "\\u597d\\u7684\\uff0c\\u6211\\u4eec\\u7ed9\\u60a8\\u505a\\u4e00\\u4e2a\\u9884\\u8bc4\\u4f30\\uff0c\\u7a0d\\u540e\\u4f1a\\u6709\\u4e13\\u4e1a\\u7684\\u878d\\u8d44\\u987e\\u95ee\\u8054\\u7cfb\\u60a8\\uff0c\\u53ef\\u4ee5\\u5417\\uff1f", "who": "bot", "create_at": "2018-01-06 13:34:37", "call_id": "24", "record_fpath": "/8a9fc0df0e56058d56e8a0323f5ed08f/bot_audio/12.wav", "mark": "insert"}'


2018-01-06 13:34:42,679 - LogUtils.py[line:112] - INFO: postgresql connect host .....   118.190.166.165
2018-01-06 13:34:42,723 - LogUtils.py[line:120] - ERROR: runsql exception error insert or update on table "fs_call_replay" violates foreign key constraint "fs_call_replay_call_id_a2c15655_fk_fs_call_id"
DETAIL:  Key (call_id)=(24) is not present in table "fs_call".
 
2018-01-06 13:34:42,724 - LogUtils.py[line:112] - INFO: ******** run_insert_sql..*********...INSERT INTO fs_call_replay(who, text, record_fpath, create_at, call_id,resp_param)VALUES ('bot', '好的，我们给您做一个预评估，稍后会有专业的融资顾问联系您，可以吗？', '/8a9fc0df0e56058d56e8a0323f5ed08f/bot_audio/12.wav', '2018-01-06 13:34:37', '24','{"info": [{"is_flow_output": true, "output": "\u597d\u7684\uff0c\u6211\u4eec\u7ed9\u60a8\u505a\u4e00\u4e2a\u9884\u8bc4\u4f30\uff0c\u7a0d\u540e\u4f1a\u6709\u4e13\u4e1a\u7684\u878d\u8d44\u987e\u95ee\u8054\u7cfb\u60a8\uff0c\u53ef\u4ee5\u5417\uff1f", "node_text": "\u9080\u7ea61", "flow_id": "bfbbb0cfab4aac3dba462ac2d805fca1", "label": "\u9080\u7ea61", "session_end": false, "state": "", "node_id": -11, "output_resource": "12.wav", "flow_end": false, "input": "\u554a", "similarity": 1, "flow_title": "\u9080\u7ea6", "output_type": "path", "user_label": "\u4e2a\u4eba\u62b5\u62bc\u8d37\u6b3e", "id": "bfbbb0cfab4aac3dba462ac2d805fca1_-11"}], "successful": true, "message": "ok"}') RETURNING id
2018-01-06 13:34:47,784 - LogUtils.py[line:112] - INFO:  [x] Received '{"user_label": "\\u4e2a\\u4eba\\u62b5\\u62bc\\u8d37\\u6b3e", "channal_uuid": "d3af5c17-2643-44e3-8588-0603b8140ac1", "mark": "user_label"}'


2018-01-06 13:34:47,785 - LogUtils.py[line:112] - INFO: postgresql connect host .....   118.190.166.165
2018-01-06 13:34:47,850 - LogUtils.py[line:112] - INFO: postgresql connect.....closed!!!
2018-01-06 13:34:47,850 - LogUtils.py[line:112] - INFO:  run_update_sql.........user_label... update fs_call set cust_tag = '个人抵押贷款' where channal_uuid ='d3af5c17-2643-44e3-8588-0603b8140ac1' 
2018-01-06 13:34:53,196 - LogUtils.py[line:112] - INFO:  [x] Received '{"jsonStr": "vad \\u6ca1\\u6709\\u68c0\\u6d4b\\u5230\\u58f0\\u97f3", "text": "", "who": "human", "create_at": "2018-01-06 13:34:48", "call_id": "24", "record_fpath": "", "mark": "insert"}'


2018-01-06 13:34:53,197 - LogUtils.py[line:112] - INFO: postgresql connect host .....   118.190.166.165
2018-01-06 13:34:53,241 - LogUtils.py[line:120] - ERROR: runsql exception error insert or update on table "fs_call_replay" violates foreign key constraint "fs_call_replay_call_id_a2c15655_fk_fs_call_id"
DETAIL:  Key (call_id)=(24) is not present in table "fs_call".
 
2018-01-06 13:34:53,241 - LogUtils.py[line:112] - INFO: ******** run_insert_sql..*********...INSERT INTO fs_call_replay(who, text, record_fpath, create_at, call_id,resp_param)VALUES ('human', '', '', '2018-01-06 13:34:48', '24','vad 没有检测到声音') RETURNING id
2018-01-06 13:34:54,359 - LogUtils.py[line:112] - INFO:  [x] Received '{"jsonStr": "{\\"info\\": [{\\"is_flow_output\\": true, \\"output\\": \\"\\\\u5582\\\\uff0c\\\\u5728\\\\u542c\\\\u5417\\\\uff1f\\", \\"node_text\\": \\"\\\\u8bed\\\\u6599\\\\u8282\\\\u70b9\\", \\"flow_id\\": \\"8a9fc0df0e56058d56e8a0323f5ed08f\\", \\"label\\": \\"\\", \\"session_end\\": false, \\"state\\": \\"\\", \\"node_id\\": -13, \\"output_resource\\": \\"t1.wav\\", \\"flow_end\\": false, \\"input\\": \\"\\", \\"similarity\\": 1, \\"flow_title\\": \\"\\\\u91d1\\\\u878d\\\\u884c\\\\u4e1a\\\\uff08\\\\u8d37\\\\u6b3e\\\\uff09\\", \\"output_type\\": \\"path\\", \\"user_label\\": \\"\\\\u4e2a\\\\u4eba\\\\u62b5\\\\u62bc\\\\u8d37\\\\u6b3e\\", \\"id\\": \\"8a9fc0df0e56058d56e8a0323f5ed08f_-13\\"}], \\"successful\\": true, \\"message\\": \\"ok\\"}", "text": "\\u5582\\uff0c\\u5728\\u542c\\u5417\\uff1f", "who": "bot", "create_at": "2018-01-06 13:34:53", "call_id": "24", "record_fpath": "/8a9fc0df0e56058d56e8a0323f5ed08f/bot_audio/t1.wav", "mark": "insert"}'


2018-01-06 13:34:54,360 - LogUtils.py[line:112] - INFO: postgresql connect host .....   118.190.166.165
2018-01-06 13:34:54,426 - LogUtils.py[line:120] - ERROR: runsql exception error insert or update on table "fs_call_replay" violates foreign key constraint "fs_call_replay_call_id_a2c15655_fk_fs_call_id"
DETAIL:  Key (call_id)=(24) is not present in table "fs_call".
 
2018-01-06 13:34:54,427 - LogUtils.py[line:112] - INFO: ******** run_insert_sql..*********...INSERT INTO fs_call_replay(who, text, record_fpath, create_at, call_id,resp_param)VALUES ('bot', '喂，在听吗？', '/8a9fc0df0e56058d56e8a0323f5ed08f/bot_audio/t1.wav', '2018-01-06 13:34:53', '24','{"info": [{"is_flow_output": true, "output": "\u5582\uff0c\u5728\u542c\u5417\uff1f", "node_text": "\u8bed\u6599\u8282\u70b9", "flow_id": "8a9fc0df0e56058d56e8a0323f5ed08f", "label": "", "session_end": false, "state": "", "node_id": -13, "output_resource": "t1.wav", "flow_end": false, "input": "", "similarity": 1, "flow_title": "\u91d1\u878d\u884c\u4e1a\uff08\u8d37\u6b3e\uff09", "output_type": "path", "user_label": "\u4e2a\u4eba\u62b5\u62bc\u8d37\u6b3e", "id": "8a9fc0df0e56058d56e8a0323f5ed08f_-13"}], "successful": true, "message": "ok"}') RETURNING id
2018-01-06 13:34:59,454 - LogUtils.py[line:112] - INFO:  [x] Received '{"user_label": "\\u4e2a\\u4eba\\u62b5\\u62bc\\u8d37\\u6b3e", "channal_uuid": "d3af5c17-2643-44e3-8588-0603b8140ac1", "mark": "user_label"}'


2018-01-06 13:34:59,454 - LogUtils.py[line:112] - INFO: postgresql connect host .....   118.190.166.165
2018-01-06 13:34:59,497 - LogUtils.py[line:112] - INFO: postgresql connect.....closed!!!
2018-01-06 13:34:59,497 - LogUtils.py[line:112] - INFO:  run_update_sql.........user_label... update fs_call set cust_tag = '个人抵押贷款' where channal_uuid ='d3af5c17-2643-44e3-8588-0603b8140ac1' 
2018-01-06 13:35:05,207 - LogUtils.py[line:112] - INFO:  [x] Received '{"user_id": "3", "task_id": "8", "number": "15900282168", "call_id": "24", "flow_id": "8a9fc0df0e56058d56e8a0323f5ed08f", "mark": "statistical"}'


2018-01-06 13:35:05,208 - LogUtils.py[line:112] - INFO: postgresql connect host .....   118.190.166.165
2018-01-06 13:35:05,273 - LogUtils.py[line:112] - INFO: postgresql connect.....closed!!!
2018-01-06 14:06:54,637 - LogUtils.py[line:112] - INFO: postgresql connect host .....   118.190.166.165
2018-01-06 14:06:54,948 - LogUtils.py[line:112] - INFO: postgresql connect.....closed!!!
2018-01-06 14:07:15,416 - LogUtils.py[line:112] - INFO: postgresql connect host .....   118.190.166.165
2018-01-06 14:07:15,644 - LogUtils.py[line:112] - INFO: postgresql connect.....closed!!!
2018-01-06 14:07:37,061 - LogUtils.py[line:112] - INFO: postgresql connect host .....   121.42.36.138
2018-01-06 14:07:37,432 - LogUtils.py[line:112] - INFO: postgresql connect.....closed!!!
2018-01-06 14:07:45,955 - LogUtils.py[line:112] - INFO: postgresql connect host .....   121.42.36.138
2018-01-06 14:07:46,229 - LogUtils.py[line:112] - INFO: postgresql connect.....closed!!!
2018-01-06 14:07:57,930 - LogUtils.py[line:112] - INFO: postgresql connect host .....   121.42.36.138
2018-01-06 14:07:58,228 - LogUtils.py[line:112] - INFO: postgresql connect.....closed!!!
2018-01-06 14:08:07,532 - LogUtils.py[line:112] - INFO: postgresql connect host .....   121.42.36.138
2018-01-06 14:08:07,787 - LogUtils.py[line:112] - INFO: postgresql connect.....closed!!!
2018-01-06 14:08:22,585 - LogUtils.py[line:112] - INFO: postgresql connect host .....   121.42.36.138
2018-01-06 14:08:22,886 - LogUtils.py[line:112] - INFO: postgresql connect.....closed!!!
2018-01-06 14:08:50,530 - LogUtils.py[line:112] - INFO: [sql__get_one]....select * from fs_customer where id = 14
2018-01-06 14:08:50,530 - LogUtils.py[line:112] - INFO: postgresql connect host .....   121.42.36.138
2018-01-06 14:08:50,778 - LogUtils.py[line:112] - INFO: postgresql connect.....closed!!!
2018-01-06 14:09:02,196 - LogUtils.py[line:112] - INFO: [sql__get_one]....select * from fs_customer where id = 14
2018-01-06 14:09:02,197 - LogUtils.py[line:112] - INFO: postgresql connect host .....   121.42.36.138
2018-01-06 14:09:02,438 - LogUtils.py[line:112] - INFO: postgresql connect.....closed!!!
2018-01-06 15:09:45,287 - LogUtils.py[line:112] - INFO: postgresql connect host .....   121.42.36.138
2018-01-06 15:09:45,590 - LogUtils.py[line:112] - INFO: postgresql connect.....closed!!!
2018-01-06 15:11:47,010 - LogUtils.py[line:112] - INFO: postgresql connect host .....   121.42.36.138
2018-01-06 15:11:47,321 - LogUtils.py[line:112] - INFO: postgresql connect.....closed!!!
2018-01-06 15:12:19,460 - LogUtils.py[line:112] - INFO: [sql__get_one]....select * from fs_customer where number = '15166636562' and user_id = 8
2018-01-06 15:12:19,463 - LogUtils.py[line:112] - INFO: postgresql connect host .....   121.42.36.138
2018-01-06 15:12:19,531 - LogUtils.py[line:112] - INFO: postgresql connect.....closed!!!
2018-01-06 15:12:26,155 - LogUtils.py[line:112] - INFO: .......httpClient exception error  : info() takes exactly 2 arguments (3 given)
2018-01-06 15:12:44,729 - LogUtils.py[line:112] - INFO: postgresql connect host .....   121.42.36.138
2018-01-06 15:12:45,015 - LogUtils.py[line:112] - INFO: postgresql connect.....closed!!!
2018-01-06 15:12:52,289 - LogUtils.py[line:112] - INFO: [sql__get_one]....select * from fs_customer where number = '15166636562' and user_id = 8
2018-01-06 15:12:52,290 - LogUtils.py[line:112] - INFO: postgresql connect host .....   121.42.36.138
2018-01-06 15:12:52,359 - LogUtils.py[line:112] - INFO: postgresql connect.....closed!!!
2018-01-06 15:13:02,375 - LogUtils.py[line:112] - INFO: .......httpClient exception error  : info() takes exactly 2 arguments (3 given)
2018-01-06 15:13:57,967 - LogUtils.py[line:112] - INFO: postgresql connect host .....   121.42.36.138
2018-01-06 15:13:58,265 - LogUtils.py[line:112] - INFO: postgresql connect.....closed!!!
2018-01-06 15:14:03,404 - LogUtils.py[line:112] - INFO: [sql__get_one]....select * from fs_customer where number = '15166636562' and user_id = 8
2018-01-06 15:14:03,405 - LogUtils.py[line:112] - INFO: postgresql connect host .....   121.42.36.138
2018-01-06 15:14:03,471 - LogUtils.py[line:112] - INFO: postgresql connect.....closed!!!
2018-01-06 15:14:07,364 - LogUtils.py[line:112] - INFO: .......httpClient exception error  : info() takes exactly 2 arguments (3 given)
2018-01-06 15:14:25,052 - LogUtils.py[line:112] - INFO: postgresql connect host .....   121.42.36.138
2018-01-06 15:14:25,346 - LogUtils.py[line:112] - INFO: postgresql connect.....closed!!!
2018-01-06 15:14:25,383 - LogUtils.py[line:112] - INFO: [sql__get_one]....select * from fs_customer where number = '15166636562' and user_id = 8
2018-01-06 15:14:25,383 - LogUtils.py[line:112] - INFO: postgresql connect host .....   121.42.36.138
2018-01-06 15:14:25,452 - LogUtils.py[line:112] - INFO: postgresql connect.....closed!!!
2018-01-06 15:14:25,452 - LogUtils.py[line:112] - INFO: exception ****'int' object has no attribute 'label'
2018-01-06 15:14:45,320 - LogUtils.py[line:112] - INFO: postgresql connect host .....   121.42.36.138
2018-01-06 15:14:45,602 - LogUtils.py[line:112] - INFO: postgresql connect.....closed!!!
2018-01-06 15:14:50,869 - LogUtils.py[line:112] - INFO: [sql__get_one]....select * from fs_customer where number = '15900282168' and user_id = 8
2018-01-06 15:14:50,870 - LogUtils.py[line:112] - INFO: postgresql connect host .....   121.42.36.138
2018-01-06 15:14:50,935 - LogUtils.py[line:112] - INFO: postgresql connect.....closed!!!
2018-01-06 15:15:03,434 - LogUtils.py[line:112] - INFO: exception ****'int' object has no attribute 'label'
2018-01-06 15:15:33,284 - LogUtils.py[line:112] - INFO: postgresql connect host .....   121.42.36.138
2018-01-06 15:15:33,592 - LogUtils.py[line:112] - INFO: postgresql connect.....closed!!!
2018-01-06 15:15:37,824 - LogUtils.py[line:112] - INFO: [sql__get_one]....select * from fs_customer where number = '15900282168' and user_id = 8
2018-01-06 15:15:37,826 - LogUtils.py[line:112] - INFO: postgresql connect host .....   121.42.36.138
2018-01-06 15:15:37,875 - LogUtils.py[line:112] - INFO: postgresql connect.....closed!!!
2018-01-06 15:16:01,488 - LogUtils.py[line:112] - INFO: postgresql connect host .....   121.42.36.138
2018-01-06 15:16:01,558 - LogUtils.py[line:112] - INFO: postgresql connect.....closed!!!
2018-01-06 15:16:06,320 - LogUtils.py[line:112] - INFO: postgresql connect host .....   121.42.36.138
2018-01-06 15:16:06,368 - LogUtils.py[line:112] - INFO: postgresql connect.....closed!!!
2018-01-06 15:16:09,398 - LogUtils.py[line:112] - INFO: postgresql connect host .....   121.42.36.138
2018-01-06 15:16:09,467 - LogUtils.py[line:112] - INFO: postgresql connect.....closed!!!
2018-01-06 15:16:10,209 - LogUtils.py[line:112] - INFO: postgresql connect host .....   121.42.36.138
2018-01-06 15:16:10,257 - LogUtils.py[line:112] - INFO: postgresql connect.....closed!!!
2018-01-06 15:16:25,834 - LogUtils.py[line:112] - INFO: postgresql connect host .....   121.42.36.138
2018-01-06 15:16:26,098 - LogUtils.py[line:112] - INFO: postgresql connect.....closed!!!
2018-01-06 15:16:32,891 - LogUtils.py[line:112] - INFO: [sql__get_one]....select * from fs_customer where number = '15900282168' and user_id = 8
2018-01-06 15:16:32,894 - LogUtils.py[line:112] - INFO: postgresql connect host .....   121.42.36.138
2018-01-06 15:16:32,951 - LogUtils.py[line:112] - INFO: postgresql connect.....closed!!!
2018-01-06 15:17:48,769 - LogUtils.py[line:112] - INFO: postgresql connect host .....   121.42.36.138
2018-01-06 15:17:49,076 - LogUtils.py[line:112] - INFO: postgresql connect.....closed!!!
2018-01-06 15:17:54,138 - LogUtils.py[line:112] - INFO: [sql__get_one]....select * from fs_customer where number = '15900282168' and user_id = 8
2018-01-06 15:17:54,139 - LogUtils.py[line:112] - INFO: postgresql connect host .....   121.42.36.138
2018-01-06 15:17:54,188 - LogUtils.py[line:112] - INFO: postgresql connect.....closed!!!
2018-01-06 15:18:33,678 - LogUtils.py[line:112] - INFO: postgresql connect host .....   121.42.36.138
2018-01-06 15:18:33,979 - LogUtils.py[line:112] - INFO: postgresql connect.....closed!!!
2018-01-06 15:18:42,732 - LogUtils.py[line:112] - INFO: [sql__get_one]....select * from fs_customer where number = '15900282168' and user_id = 8
2018-01-06 15:18:42,734 - LogUtils.py[line:112] - INFO: postgresql connect host .....   121.42.36.138
2018-01-06 15:18:42,805 - LogUtils.py[line:112] - INFO: postgresql connect.....closed!!!
2018-01-06 15:18:45,281 - LogUtils.py[line:112] - INFO: postgresql connect host .....   121.42.36.138
2018-01-06 15:18:45,337 - LogUtils.py[line:112] - INFO: postgresql connect.....closed!!!
2018-01-06 15:18:56,722 - LogUtils.py[line:112] - INFO: postgresql connect host .....   121.42.36.138
2018-01-06 15:18:56,792 - LogUtils.py[line:112] - INFO: postgresql connect.....closed!!!
2018-01-06 15:19:08,702 - LogUtils.py[line:112] - INFO: postgresql connect host .....   121.42.36.138
2018-01-06 15:19:09,005 - LogUtils.py[line:112] - INFO: postgresql connect.....closed!!!
