2018-01-06 13:18:39,760 - LogUtils.py[line:120] - ERROR: runsql exception error insert or update on table "fs_call_replay" violates foreign key constraint "fs_call_replay_call_id_a2c15655_fk_fs_call_id"
DETAIL:  Key (call_id)=(16) is not present in table "fs_call".
 
2018-01-06 13:18:40,848 - LogUtils.py[line:120] - ERROR: runsql exception error insert or update on table "fs_call_replay" violates foreign key constraint "fs_call_replay_call_id_a2c15655_fk_fs_call_id"
DETAIL:  Key (call_id)=(19) is not present in table "fs_call".
 
2018-01-06 13:18:41,306 - LogUtils.py[line:120] - ERROR: runsql exception error insert or update on table "fs_call_replay" violates foreign key constraint "fs_call_replay_call_id_a2c15655_fk_fs_call_id"
DETAIL:  Key (call_id)=(19) is not present in table "fs_call".
 
2018-01-06 13:18:46,996 - LogUtils.py[line:120] - ERROR: runsql exception error insert or update on table "fs_call_replay" violates foreign key constraint "fs_call_replay_call_id_a2c15655_fk_fs_call_id"
DETAIL:  Key (call_id)=(16) is not present in table "fs_call".
 
2018-01-06 13:18:47,668 - LogUtils.py[line:120] - ERROR: runsql exception error insert or update on table "fs_call_replay" violates foreign key constraint "fs_call_replay_call_id_a2c15655_fk_fs_call_id"
DETAIL:  Key (call_id)=(19) is not present in table "fs_call".
 
2018-01-06 13:18:56,628 - LogUtils.py[line:120] - ERROR: runsql exception error insert or update on table "fs_call_replay" violates foreign key constraint "fs_call_replay_call_id_a2c15655_fk_fs_call_id"
DETAIL:  Key (call_id)=(19) is not present in table "fs_call".
 
2018-01-06 13:19:02,451 - LogUtils.py[line:120] - ERROR: runsql exception error insert or update on table "fs_call_replay" violates foreign key constraint "fs_call_replay_call_id_a2c15655_fk_fs_call_id"
DETAIL:  Key (call_id)=(19) is not present in table "fs_call".
 
2018-01-06 13:19:03,184 - LogUtils.py[line:120] - ERROR: runsql exception error insert or update on table "fs_call_replay" violates foreign key constraint "fs_call_replay_call_id_a2c15655_fk_fs_call_id"
DETAIL:  Key (call_id)=(16) is not present in table "fs_call".
 
2018-01-06 13:19:06,216 - LogUtils.py[line:120] - ERROR: runsql exception error insert or update on table "fs_call_replay" violates foreign key constraint "fs_call_replay_call_id_a2c15655_fk_fs_call_id"
DETAIL:  Key (call_id)=(16) is not present in table "fs_call".
 
2018-01-06 13:19:07,064 - LogUtils.py[line:120] - ERROR: runsql exception error insert or update on table "fs_call_replay" violates foreign key constraint "fs_call_replay_call_id_a2c15655_fk_fs_call_id"
DETAIL:  Key (call_id)=(19) is not present in table "fs_call".
 
2018-01-06 13:19:11,785 - LogUtils.py[line:120] - ERROR: runsql exception error insert or update on table "fs_call_replay" violates foreign key constraint "fs_call_replay_call_id_a2c15655_fk_fs_call_id"
DETAIL:  Key (call_id)=(19) is not present in table "fs_call".
 
2018-01-06 13:19:13,823 - LogUtils.py[line:120] - ERROR: runsql exception error insert or update on table "fs_call_replay" violates foreign key constraint "fs_call_replay_call_id_a2c15655_fk_fs_call_id"
DETAIL:  Key (call_id)=(19) is not present in table "fs_call".
 
2018-01-06 13:19:15,468 - LogUtils.py[line:120] - ERROR: runsql exception error insert or update on table "fs_call_replay" violates foreign key constraint "fs_call_replay_call_id_a2c15655_fk_fs_call_id"
DETAIL:  Key (call_id)=(16) is not present in table "fs_call".
 
2018-01-06 13:19:17,323 - LogUtils.py[line:120] - ERROR: runsql exception error insert or update on table "fs_call_replay" violates foreign key constraint "fs_call_replay_call_id_a2c15655_fk_fs_call_id"
DETAIL:  Key (call_id)=(16) is not present in table "fs_call".
 
2018-01-06 13:19:20,525 - LogUtils.py[line:120] - ERROR: runsql exception error insert or update on table "fs_call_replay" violates foreign key constraint "fs_call_replay_call_id_a2c15655_fk_fs_call_id"
DETAIL:  Key (call_id)=(16) is not present in table "fs_call".
 
2018-01-06 13:19:23,414 - LogUtils.py[line:120] - ERROR: runsql exception error insert or update on table "fs_call_replay" violates foreign key constraint "fs_call_replay_call_id_a2c15655_fk_fs_call_id"
DETAIL:  Key (call_id)=(19) is not present in table "fs_call".
 
2018-01-06 13:19:24,121 - LogUtils.py[line:120] - ERROR: runsql exception error insert or update on table "fs_call_replay" violates foreign key constraint "fs_call_replay_call_id_a2c15655_fk_fs_call_id"
DETAIL:  Key (call_id)=(16) is not present in table "fs_call".
 
2018-01-06 13:19:37,475 - LogUtils.py[line:120] - ERROR: runsql exception error insert or update on table "fs_call_replay" violates foreign key constraint "fs_call_replay_call_id_a2c15655_fk_fs_call_id"
DETAIL:  Key (call_id)=(16) is not present in table "fs_call".
 
2018-01-06 13:19:41,822 - LogUtils.py[line:120] - ERROR: runsql exception error insert or update on table "fs_call_replay" violates foreign key constraint "fs_call_replay_call_id_a2c15655_fk_fs_call_id"
DETAIL:  Key (call_id)=(16) is not present in table "fs_call".
 
2018-01-06 13:20:10,574 - LogUtils.py[line:120] - ERROR: runsql exception error insert or update on table "fs_call_replay" violates foreign key constraint "fs_call_replay_call_id_a2c15655_fk_fs_call_id"
DETAIL:  Key (call_id)=(17) is not present in table "fs_call".
 
2018-01-06 13:20:15,754 - LogUtils.py[line:120] - ERROR: runsql exception error insert or update on table "fs_call_replay" violates foreign key constraint "fs_call_replay_call_id_a2c15655_fk_fs_call_id"
DETAIL:  Key (call_id)=(20) is not present in table "fs_call".
 
2018-01-06 13:20:16,345 - LogUtils.py[line:120] - ERROR: runsql exception error insert or update on table "fs_call_replay" violates foreign key constraint "fs_call_replay_call_id_a2c15655_fk_fs_call_id"
DETAIL:  Key (call_id)=(17) is not present in table "fs_call".
 
2018-01-06 13:20:19,807 - LogUtils.py[line:120] - ERROR: runsql exception error insert or update on table "fs_call_replay" violates foreign key constraint "fs_call_replay_call_id_a2c15655_fk_fs_call_id"
DETAIL:  Key (call_id)=(20) is not present in table "fs_call".
 
2018-01-06 13:20:25,805 - LogUtils.py[line:120] - ERROR: runsql exception error insert or update on table "fs_call_replay" violates foreign key constraint "fs_call_replay_call_id_a2c15655_fk_fs_call_id"
DETAIL:  Key (call_id)=(20) is not present in table "fs_call".
 
2018-01-06 13:20:30,738 - LogUtils.py[line:120] - ERROR: runsql exception error insert or update on table "fs_call_replay" violates foreign key constraint "fs_call_replay_call_id_a2c15655_fk_fs_call_id"
DETAIL:  Key (call_id)=(17) is not present in table "fs_call".
 
2018-01-06 13:20:32,615 - LogUtils.py[line:120] - ERROR: runsql exception error insert or update on table "fs_call_replay" violates foreign key constraint "fs_call_replay_call_id_a2c15655_fk_fs_call_id"
DETAIL:  Key (call_id)=(17) is not present in table "fs_call".
 
2018-01-06 13:20:38,500 - LogUtils.py[line:120] - ERROR: runsql exception error insert or update on table "fs_call_replay" violates foreign key constraint "fs_call_replay_call_id_a2c15655_fk_fs_call_id"
DETAIL:  Key (call_id)=(20) is not present in table "fs_call".
 
2018-01-06 13:20:40,709 - LogUtils.py[line:120] - ERROR: runsql exception error insert or update on table "fs_call_replay" violates foreign key constraint "fs_call_replay_call_id_a2c15655_fk_fs_call_id"
DETAIL:  Key (call_id)=(20) is not present in table "fs_call".
 
2018-01-06 13:20:50,117 - LogUtils.py[line:120] - ERROR: runsql exception error insert or update on table "fs_call_replay" violates foreign key constraint "fs_call_replay_call_id_a2c15655_fk_fs_call_id"
DETAIL:  Key (call_id)=(18) is not present in table "fs_call".
 
2018-01-06 13:20:59,189 - LogUtils.py[line:120] - ERROR: runsql exception error insert or update on table "fs_call_replay" violates foreign key constraint "fs_call_replay_call_id_a2c15655_fk_fs_call_id"
DETAIL:  Key (call_id)=(18) is not present in table "fs_call".
 
2018-01-06 13:21:08,619 - LogUtils.py[line:120] - ERROR: runsql exception error insert or update on table "fs_call_replay" violates foreign key constraint "fs_call_replay_call_id_a2c15655_fk_fs_call_id"
DETAIL:  Key (call_id)=(18) is not present in table "fs_call".
 
2018-01-06 13:21:12,967 - LogUtils.py[line:120] - ERROR: runsql exception error insert or update on table "fs_call_replay" violates foreign key constraint "fs_call_replay_call_id_a2c15655_fk_fs_call_id"
DETAIL:  Key (call_id)=(20) is not present in table "fs_call".
 
2018-01-06 13:21:14,359 - LogUtils.py[line:120] - ERROR: runsql exception error insert or update on table "fs_call_replay" violates foreign key constraint "fs_call_replay_call_id_a2c15655_fk_fs_call_id"
DETAIL:  Key (call_id)=(18) is not present in table "fs_call".
 
2018-01-06 13:21:18,962 - LogUtils.py[line:120] - ERROR: runsql exception error insert or update on table "fs_call_replay" violates foreign key constraint "fs_call_replay_call_id_a2c15655_fk_fs_call_id"
DETAIL:  Key (call_id)=(20) is not present in table "fs_call".
 
2018-01-06 13:21:23,382 - LogUtils.py[line:120] - ERROR: runsql exception error insert or update on table "fs_call_replay" violates foreign key constraint "fs_call_replay_call_id_a2c15655_fk_fs_call_id"
DETAIL:  Key (call_id)=(18) is not present in table "fs_call".
 
2018-01-06 13:21:28,107 - LogUtils.py[line:120] - ERROR: runsql exception error insert or update on table "fs_call_replay" violates foreign key constraint "fs_call_replay_call_id_a2c15655_fk_fs_call_id"
DETAIL:  Key (call_id)=(18) is not present in table "fs_call".
 
2018-01-06 13:21:53,400 - LogUtils.py[line:120] - ERROR: runsql exception error insert or update on table "fs_call_replay" violates foreign key constraint "fs_call_replay_call_id_a2c15655_fk_fs_call_id"
DETAIL:  Key (call_id)=(21) is not present in table "fs_call".
 
2018-01-06 13:21:57,470 - LogUtils.py[line:120] - ERROR: runsql exception error insert or update on table "fs_call_replay" violates foreign key constraint "fs_call_replay_call_id_a2c15655_fk_fs_call_id"
DETAIL:  Key (call_id)=(21) is not present in table "fs_call".
 
2018-01-06 13:22:14,009 - LogUtils.py[line:120] - ERROR: runsql exception error insert or update on table "fs_call_replay" violates foreign key constraint "fs_call_replay_call_id_a2c15655_fk_fs_call_id"
DETAIL:  Key (call_id)=(21) is not present in table "fs_call".
 
2018-01-06 13:22:14,465 - LogUtils.py[line:120] - ERROR: runsql exception error insert or update on table "fs_call_replay" violates foreign key constraint "fs_call_replay_call_id_a2c15655_fk_fs_call_id"
DETAIL:  Key (call_id)=(21) is not present in table "fs_call".
 
2018-01-06 13:28:31,508 - LogUtils.py[line:120] - ERROR: runsql exception error insert or update on table "fs_call_replay" violates foreign key constraint "fs_call_replay_call_id_a2c15655_fk_fs_call_id"
DETAIL:  Key (call_id)=(25) is not present in table "fs_call".
 
2018-01-06 13:28:42,381 - LogUtils.py[line:120] - ERROR: runsql exception error insert or update on table "fs_call_replay" violates foreign key constraint "fs_call_replay_call_id_a2c15655_fk_fs_call_id"
DETAIL:  Key (call_id)=(25) is not present in table "fs_call".
 
2018-01-06 13:28:47,871 - LogUtils.py[line:120] - ERROR: runsql exception error insert or update on table "fs_call_replay" violates foreign key constraint "fs_call_replay_call_id_a2c15655_fk_fs_call_id"
DETAIL:  Key (call_id)=(25) is not present in table "fs_call".
 
2018-01-06 13:28:55,921 - LogUtils.py[line:120] - ERROR: runsql exception error insert or update on table "fs_call_replay" violates foreign key constraint "fs_call_replay_call_id_a2c15655_fk_fs_call_id"
DETAIL:  Key (call_id)=(25) is not present in table "fs_call".
 
2018-01-06 13:28:59,489 - LogUtils.py[line:120] - ERROR: runsql exception error insert or update on table "fs_call_replay" violates foreign key constraint "fs_call_replay_call_id_a2c15655_fk_fs_call_id"
DETAIL:  Key (call_id)=(25) is not present in table "fs_call".
 
2018-01-06 13:29:11,981 - LogUtils.py[line:120] - ERROR: runsql exception error insert or update on table "fs_call_replay" violates foreign key constraint "fs_call_replay_call_id_a2c15655_fk_fs_call_id"
DETAIL:  Key (call_id)=(25) is not present in table "fs_call".
 
2018-01-06 13:29:16,412 - LogUtils.py[line:120] - ERROR: runsql exception error insert or update on table "fs_call_replay" violates foreign key constraint "fs_call_replay_call_id_a2c15655_fk_fs_call_id"
DETAIL:  Key (call_id)=(25) is not present in table "fs_call".
 
2018-01-06 13:31:49,175 - LogUtils.py[line:120] - ERROR: runsql exception error insert or update on table "fs_call_replay" violates foreign key constraint "fs_call_replay_call_id_a2c15655_fk_fs_call_id"
DETAIL:  Key (call_id)=(22) is not present in table "fs_call".
 
2018-01-06 13:31:58,740 - LogUtils.py[line:120] - ERROR: runsql exception error insert or update on table "fs_call_replay" violates foreign key constraint "fs_call_replay_call_id_a2c15655_fk_fs_call_id"
DETAIL:  Key (call_id)=(22) is not present in table "fs_call".
 
2018-01-06 13:32:04,212 - LogUtils.py[line:120] - ERROR: runsql exception error insert or update on table "fs_call_replay" violates foreign key constraint "fs_call_replay_call_id_a2c15655_fk_fs_call_id"
DETAIL:  Key (call_id)=(22) is not present in table "fs_call".
 
2018-01-06 13:32:13,625 - LogUtils.py[line:120] - ERROR: runsql exception error insert or update on table "fs_call_replay" violates foreign key constraint "fs_call_replay_call_id_a2c15655_fk_fs_call_id"
DETAIL:  Key (call_id)=(22) is not present in table "fs_call".
 
2018-01-06 13:32:16,094 - LogUtils.py[line:120] - ERROR: runsql exception error insert or update on table "fs_call_replay" violates foreign key constraint "fs_call_replay_call_id_a2c15655_fk_fs_call_id"
DETAIL:  Key (call_id)=(22) is not present in table "fs_call".
 
2018-01-06 13:32:23,383 - LogUtils.py[line:120] - ERROR: runsql exception error insert or update on table "fs_call_replay" violates foreign key constraint "fs_call_replay_call_id_a2c15655_fk_fs_call_id"
DETAIL:  Key (call_id)=(22) is not present in table "fs_call".
 
2018-01-06 13:32:28,572 - LogUtils.py[line:120] - ERROR: runsql exception error insert or update on table "fs_call_replay" violates foreign key constraint "fs_call_replay_call_id_a2c15655_fk_fs_call_id"
DETAIL:  Key (call_id)=(22) is not present in table "fs_call".
 
2018-01-06 13:33:11,538 - LogUtils.py[line:120] - ERROR: runsql exception error insert or update on table "fs_call_replay" violates foreign key constraint "fs_call_replay_call_id_a2c15655_fk_fs_call_id"
DETAIL:  Key (call_id)=(23) is not present in table "fs_call".
 
2018-01-06 13:33:15,624 - LogUtils.py[line:120] - ERROR: runsql exception error insert or update on table "fs_call_replay" violates foreign key constraint "fs_call_replay_call_id_a2c15655_fk_fs_call_id"
DETAIL:  Key (call_id)=(23) is not present in table "fs_call".
 
2018-01-06 13:33:24,730 - LogUtils.py[line:120] - ERROR: runsql exception error insert or update on table "fs_call_replay" violates foreign key constraint "fs_call_replay_call_id_a2c15655_fk_fs_call_id"
DETAIL:  Key (call_id)=(23) is not present in table "fs_call".
 
2018-01-06 13:33:26,524 - LogUtils.py[line:120] - ERROR: runsql exception error insert or update on table "fs_call_replay" violates foreign key constraint "fs_call_replay_call_id_a2c15655_fk_fs_call_id"
DETAIL:  Key (call_id)=(23) is not present in table "fs_call".
 
2018-01-06 13:33:35,505 - LogUtils.py[line:120] - ERROR: runsql exception error insert or update on table "fs_call_replay" violates foreign key constraint "fs_call_replay_call_id_a2c15655_fk_fs_call_id"
DETAIL:  Key (call_id)=(23) is not present in table "fs_call".
 
2018-01-06 13:33:40,724 - LogUtils.py[line:120] - ERROR: runsql exception error insert or update on table "fs_call_replay" violates foreign key constraint "fs_call_replay_call_id_a2c15655_fk_fs_call_id"
DETAIL:  Key (call_id)=(23) is not present in table "fs_call".
 
2018-01-06 13:34:12,952 - LogUtils.py[line:120] - ERROR: runsql exception error insert or update on table "fs_call_replay" violates foreign key constraint "fs_call_replay_call_id_a2c15655_fk_fs_call_id"
DETAIL:  Key (call_id)=(24) is not present in table "fs_call".
 
2018-01-06 13:34:16,986 - LogUtils.py[line:120] - ERROR: runsql exception error insert or update on table "fs_call_replay" violates foreign key constraint "fs_call_replay_call_id_a2c15655_fk_fs_call_id"
DETAIL:  Key (call_id)=(24) is not present in table "fs_call".
 
2018-01-06 13:34:28,135 - LogUtils.py[line:120] - ERROR: runsql exception error insert or update on table "fs_call_replay" violates foreign key constraint "fs_call_replay_call_id_a2c15655_fk_fs_call_id"
DETAIL:  Key (call_id)=(24) is not present in table "fs_call".
 
2018-01-06 13:34:29,987 - LogUtils.py[line:120] - ERROR: runsql exception error insert or update on table "fs_call_replay" violates foreign key constraint "fs_call_replay_call_id_a2c15655_fk_fs_call_id"
DETAIL:  Key (call_id)=(24) is not present in table "fs_call".
 
2018-01-06 13:34:37,551 - LogUtils.py[line:120] - ERROR: runsql exception error insert or update on table "fs_call_replay" violates foreign key constraint "fs_call_replay_call_id_a2c15655_fk_fs_call_id"
DETAIL:  Key (call_id)=(24) is not present in table "fs_call".
 
2018-01-06 13:34:42,723 - LogUtils.py[line:120] - ERROR: runsql exception error insert or update on table "fs_call_replay" violates foreign key constraint "fs_call_replay_call_id_a2c15655_fk_fs_call_id"
DETAIL:  Key (call_id)=(24) is not present in table "fs_call".
 
2018-01-06 13:34:53,241 - LogUtils.py[line:120] - ERROR: runsql exception error insert or update on table "fs_call_replay" violates foreign key constraint "fs_call_replay_call_id_a2c15655_fk_fs_call_id"
DETAIL:  Key (call_id)=(24) is not present in table "fs_call".
 
2018-01-06 13:34:54,426 - LogUtils.py[line:120] - ERROR: runsql exception error insert or update on table "fs_call_replay" violates foreign key constraint "fs_call_replay_call_id_a2c15655_fk_fs_call_id"
DETAIL:  Key (call_id)=(24) is not present in table "fs_call".
 
